File: Original_Data/Stress_Strain/SR_HIP_HT/18-065_RT_SR+HIP+HT.csv
Eng_Strain, Eng_Stress (MPa)
-0.000002, 0.034606
0.000039, 8.216110
0.000127, 26.335052
0.000231, 48.507958
0.000317, 67.011165
0.000408, 85.684911
0.000497, 104.047330
0.000591, 123.936977
0.000684, 143.093857
0.000774, 161.839709
0.000863, 181.066804
0.000949, 199.689805
0.001035, 217.567019
0.001127, 236.921292
0.001213, 254.963932
0.001292, 272.232449
0.001379, 289.045384
0.001463, 305.606433
0.001553, 320.803856
0.001676, 336.874305
0.001821, 349.163819
0.002034, 360.100558
0.002310, 367.583164
0.002674, 372.838505
0.003071, 376.170562
0.003490, 379.150511
0.003911, 382.630193
0.004321, 384.873297
0.004724, 387.865298
0.005166, 391.240199
0.005561, 392.841527
0.005961, 395.626948
0.006342, 397.286232
0.006771, 401.469909
0.007157, 403.182960
0.007531, 405.426857
0.007894, 407.013206
0.008299, 410.588952
0.008664, 412.704977
0.009037, 414.506660
0.009411, 416.942837
0.009781, 419.020979
0.010151, 421.233030
0.010525, 423.364147
0.010904, 425.562540
0.011231, 426.002792
0.011559, 428.445610
0.011961, 431.412708
0.012317, 433.406105
0.012684, 435.638531
0.013045, 437.305852
0.013417, 439.796400
0.013751, 440.327472
0.014151, 442.945817
0.014504, 444.872618
0.014862, 446.665547
0.015219, 448.362638
0.015575, 449.812738
0.015929, 451.616685
0.016281, 453.692714
0.016634, 455.648379
0.016988, 457.130853
0.017343, 458.290722
0.017698, 461.078067
0.018065, 461.703203
0.018422, 463.799042
0.018771, 464.816889
0.019126, 466.903030
0.019476, 468.148549
0.019837, 469.781383
0.020196, 471.555069
0.020522, 472.255518
0.020911, 474.452553
0.021253, 475.833566
0.021607, 477.546051
0.021960, 479.153643
0.022314, 480.406897
0.022668, 481.653737
0.023016, 482.691280
0.023360, 485.422820
0.023720, 485.371581
0.024064, 487.106441
0.024407, 488.877825
0.024759, 490.050636
0.025110, 491.334377
0.025456, 492.753500
0.025800, 494.002528
0.026122, 495.430895
0.026509, 496.642229
0.026843, 497.473267
0.027158, 498.476135
0.027546, 500.220881
0.027882, 501.899936
0.028230, 502.859223
0.028577, 504.076142
0.028921, 505.428329
0.029276, 506.590763
0.029629, 508.304532
0.029958, 508.410293
0.030338, 510.161906
0.030676, 511.287250
0.031019, 512.332906
0.031363, 513.571445
0.031704, 514.683545
0.032049, 515.618609
0.032367, 516.895068
0.032752, 518.014904
0.033093, 519.237860
0.033442, 520.623137
0.033798, 521.702449
0.034142, 522.730936
0.034476, 523.262197
0.034857, 524.789496
0.035201, 526.064974
0.035544, 527.120364
0.035894, 528.175867
0.036237, 529.120100
0.036576, 529.959816
0.036920, 531.176810
0.037255, 533.153568
0.037622, 532.837679
0.037966, 534.033468
0.038309, 535.223937
0.038658, 536.226729
0.039003, 537.405199
0.039345, 538.055465
0.039690, 540.432442
0.040047, 539.950157
0.040401, 541.081123
0.040747, 542.359393
0.041087, 543.261744
0.041420, 544.338452
0.041760, 545.051202
0.042102, 545.826812
0.042457, 546.669320
0.042828, 548.777270
0.043180, 548.912123
0.043527, 549.997397
0.043874, 550.767309
0.044215, 551.569898
0.044567, 552.293174
0.044909, 554.608497
0.045264, 554.474248
0.045605, 555.243029
0.045954, 556.403766
0.046298, 557.202392
0.046633, 557.358827
0.047008, 559.475569
0.047350, 559.924612
0.047694, 560.793571
0.048036, 561.684979
0.048386, 562.719918
0.048740, 563.538618
0.049090, 564.369769
0.049445, 565.162585
0.049775, 565.573671
0.050152, 566.965098
0.050500, 567.883070
0.050850, 568.437535
0.051199, 569.620911
0.051544, 570.037052
0.051889, 571.100328
0.052230, 572.068558
0.052564, 572.299664
0.052938, 573.449081
0.053277, 574.016715
0.053626, 575.038675
0.053967, 576.049240
0.054307, 576.837566
0.054658, 577.741048
0.055012, 578.959967
0.055352, 578.310116
0.055728, 579.999094
0.056074, 581.140437
0.056415, 581.648191
0.056741, 582.063465
0.057114, 583.790741
0.057461, 584.183564
0.057816, 585.014753
0.058166, 585.856318
0.058516, 586.570237
0.058871, 587.276006
0.059198, 587.399691
0.059580, 589.152096
0.059911, 589.731087
0.060251, 590.304494
0.060609, 591.503943
0.060962, 591.861525
0.061312, 592.932725
0.061662, 593.444101
0.062015, 594.485719
0.062350, 594.225522
0.062723, 595.854847
0.063066, 596.403275
0.063408, 597.190582
0.063741, 597.757160
0.064132, 598.931479
0.064474, 599.606346
0.064817, 599.939441
0.065162, 600.928046
0.065512, 601.842773
0.065861, 602.640871
0.066191, 602.656341
0.066569, 603.865449
0.066915, 604.709693
0.067257, 605.448930
0.067602, 606.126061
0.067928, 605.961627
0.068303, 608.050334
0.068648, 608.085160
0.068994, 609.047806
0.069345, 609.951213
0.069690, 610.484360
0.070043, 611.327925
0.070392, 611.644984
0.070739, 612.338377
0.071066, 612.390597
0.071444, 614.186168
0.071797, 614.885522
0.072147, 615.203449
0.072496, 616.010263
0.072839, 616.710448
0.073160, 616.836471
0.073553, 618.069124
0.073903, 619.232011
0.074252, 619.472928
0.074595, 620.106818
0.074951, 620.819228
0.075234, 620.957854
0.075570, 621.975361
0.075895, 622.313398
0.076287, 623.362148
0.076625, 623.627438
0.076968, 624.744444
0.077313, 625.284609
0.077644, 625.355281
0.078024, 626.561936
0.078370, 627.252462
0.078722, 628.073803
0.079070, 628.710221
0.079420, 629.464853
0.079775, 630.375203
0.080126, 630.769083
0.080465, 631.044938
0.080819, 631.794702
0.081156, 633.649172
0.081525, 633.173226
0.081872, 633.609742
0.082213, 634.350413
0.082558, 634.809984
0.082909, 635.982191
0.083253, 636.589405
0.083596, 636.811984
0.083942, 637.434630
0.084276, 638.836811
0.084641, 638.711882
0.084993, 639.765574
0.085333, 639.735200
0.085682, 640.866506
0.086021, 641.116855
0.086368, 641.912312
0.086715, 642.612006
0.087033, 642.840622
0.087427, 643.805569
0.087774, 644.358865
0.088117, 644.926914
0.088473, 645.788175
0.088824, 646.410520
0.089169, 646.707958
0.089508, 648.429461
0.089869, 647.698562
0.090213, 648.543410
0.090557, 649.426631
0.090910, 649.752934
0.091258, 650.594159
0.091603, 650.859110
0.091951, 651.402068
0.092285, 652.235332
0.092632, 653.719466
0.093000, 653.236690
0.093351, 653.889484
0.093694, 654.728219
0.094031, 655.023809
0.094367, 655.450251
0.094710, 657.237143
0.095070, 656.728333
0.095420, 657.557710
0.095777, 658.337999
0.096128, 658.776855
0.096468, 659.058937
0.096817, 660.621477
0.097170, 660.344753
0.097520, 661.215259
0.097865, 661.642757
0.098208, 662.087349
0.098552, 662.503566
0.098890, 663.371090
0.099234, 663.864770
0.099583, 664.423612
0.099931, 666.052032
0.100294, 665.201751
0.100639, 665.864468
0.100980, 666.642305
0.101327, 667.446025
0.101676, 667.793005
0.102027, 668.545033
0.102371, 668.843716
0.102708, 669.033845
0.103068, 670.582123
0.103416, 670.343395
0.103765, 671.204694
0.104112, 671.602686
0.104458, 672.385353
0.104797, 672.742256
0.105145, 672.899445
0.105488, 674.942610
0.105836, 673.960495
0.106184, 674.935668
0.106532, 675.663774
0.106874, 676.127533
0.107217, 676.574426
0.107559, 677.285854
0.107913, 677.892729
0.108247, 677.674150
0.108613, 679.172811
0.108969, 679.496698
0.109314, 679.769460
0.109657, 680.277931
0.110000, 680.970758
0.110358, 681.526695
0.110705, 682.103498
0.111040, 681.740256
0.111411, 683.518205
0.111753, 683.492133
0.112087, 683.861035
0.112431, 684.955250
0.112784, 685.375391
0.113122, 685.949025
0.113449, 685.332943
0.113814, 687.550466
0.114158, 687.312380
0.114508, 688.131796
0.114859, 688.557748
0.115198, 688.598951
0.115543, 689.311701
0.115886, 689.800966
0.116240, 690.487341
0.116577, 691.164472
0.116902, 691.369996
0.117285, 692.214014
0.117632, 692.582349
0.117980, 693.158171
0.118319, 693.536241
0.118662, 694.363016
0.118988, 693.603215
0.119361, 695.735049
0.119712, 695.801004
0.120062, 696.548806
0.120411, 696.605026
0.120749, 696.834283
0.121087, 698.501566
0.121447, 698.228502
0.121793, 698.763763
0.122145, 699.491190
0.122485, 699.601139
0.122825, 699.995548
0.123180, 700.891107
0.123506, 701.284836
0.123882, 701.759159
0.124227, 702.341697
0.124571, 702.772139
0.124913, 703.279025
0.125255, 703.828284
0.125600, 704.391654
0.125947, 704.682149
0.126267, 705.089688
0.126652, 705.999811
0.126991, 706.115006
0.127338, 706.673245
0.127681, 707.327359
0.128025, 707.825756
0.128354, 707.556239
0.128728, 709.285854
0.129071, 709.219296
0.129409, 710.013093
0.129746, 710.058899
0.130094, 710.363355
0.130443, 711.119534
0.130793, 711.727352
0.131141, 712.098555
0.131478, 713.661397
0.131846, 713.226314
0.132183, 713.441271
0.132533, 714.102102
0.132876, 714.760103
0.133223, 715.272120
0.133574, 715.508924
0.133918, 716.845678
0.134272, 716.424405
0.134624, 717.184507
0.134963, 717.680904
0.135308, 718.382636
0.135657, 718.293703
0.135999, 718.621099
0.136325, 719.101687
0.136700, 719.953666
0.137046, 720.513866
0.137379, 720.725088
0.137724, 721.304682
0.138045, 721.097687
0.138411, 722.127948
0.138756, 722.850432
0.139105, 723.196582
0.139452, 723.393767
0.139797, 723.835302
0.140140, 724.203524
0.140492, 725.362450
0.140821, 725.796966
0.141191, 725.634607
0.141534, 726.142361
0.141874, 726.679546
0.142192, 727.347696
0.142565, 727.485983
0.142904, 728.172056
0.143257, 728.335585
0.143601, 728.895974
0.143942, 729.461495
0.144283, 729.818322
0.144630, 730.585179
0.144969, 730.539712
0.145296, 730.756518
0.145692, 731.879108
0.146034, 731.912500
0.146380, 732.651360
0.146728, 733.228012
0.147076, 733.516545
0.147420, 733.660906
0.147765, 735.455005
0.148125, 734.488133
0.148471, 735.340037
0.148817, 735.458024
0.149162, 736.231521
0.149502, 736.718409
0.149852, 737.178470
0.150197, 737.114063
0.150533, 738.594386
0.150880, 737.810059
0.151229, 738.699996
0.151583, 739.175376
0.151930, 739.632004
0.152267, 739.765234
0.152618, 740.314568
0.152958, 741.781081
0.153319, 741.191752
0.153661, 741.607214
0.154006, 742.088971
0.154338, 742.357129
0.154672, 743.990001
0.155046, 743.236917
0.155383, 743.736709
0.155729, 744.303286
0.156074, 744.539750
0.156408, 744.998151
0.156760, 745.886956
0.157103, 746.175263
0.157451, 746.413010
0.157799, 746.984417
0.158138, 748.206807
0.158496, 747.576689
0.158842, 748.168019
0.159192, 748.715051
0.159521, 748.192431
0.159874, 749.855262
0.160228, 749.830887
0.160567, 750.293514
0.160913, 750.594499
0.161257, 751.212731
0.161603, 751.134324
0.161958, 751.963438
0.162305, 752.366562
0.162662, 752.882127
0.163010, 753.056031
0.163352, 753.141908
0.163704, 754.860959
0.164061, 754.251292
0.164405, 754.860318
0.164751, 755.146587
0.165084, 756.791156
0.165447, 755.869977
0.165797, 756.477455
0.166145, 756.906350
0.166495, 757.303701
0.166841, 757.528619
0.167180, 757.724371
0.167520, 758.282383
0.167869, 758.773535
0.168215, 760.534128
0.168567, 759.582651
0.168912, 760.093499
0.169258, 760.074633
0.169602, 760.621892
0.169943, 762.437422
0.170316, 761.803418
0.170654, 761.988530
0.171002, 762.307512
0.171339, 762.654379
0.171687, 763.381164
0.172033, 763.553296
0.172393, 765.483794
0.172737, 764.203788
0.173092, 764.936045
0.173437, 765.596046
0.173782, 765.764064
0.174129, 766.175942
0.174461, 765.688450
0.174829, 767.368185
0.175170, 767.079274
0.175509, 767.180847
0.175869, 768.900653
0.176217, 768.478889
0.176569, 768.823794
0.176920, 769.411123
0.177274, 769.755726
0.177616, 770.280949
0.177974, 770.445723
0.178297, 769.835528
0.178676, 771.667057
0.179024, 771.575897
0.179377, 772.231710
0.179719, 772.311436
0.180075, 772.908237
0.180400, 772.235483
0.180757, 774.169302
0.181113, 774.068898
0.181467, 774.471947
0.181817, 775.210504
0.182164, 775.141154
0.182514, 775.599857
0.182851, 775.395351
0.183214, 777.144474
0.183564, 776.865977
0.183905, 777.045202
0.184254, 777.106101
0.184603, 777.917972
0.184952, 778.118590
0.185296, 778.584915
0.185649, 778.733464
0.185999, 779.250236
0.186339, 780.282232
0.186719, 779.995585
0.187066, 780.394257
0.187405, 780.538618
0.187755, 780.981587
0.188105, 781.753915
0.188438, 781.168585
0.188812, 782.971211
0.189164, 782.790062
0.189516, 783.142022
0.189868, 783.650832
0.190222, 783.832245
0.190572, 784.198279
0.190910, 784.333962
0.191247, 785.604762
0.191618, 785.093537
0.191972, 785.553900
0.192326, 786.249821
0.192664, 785.563332
0.193033, 787.299664
0.193387, 786.950043
0.193738, 787.370486
0.194081, 787.673358
0.194428, 788.380447
0.194780, 788.658152
0.195136, 788.937441
0.195460, 788.781874
0.195847, 789.930913
0.196187, 789.911331
0.196537, 790.341395
0.196888, 790.690337
0.197237, 790.642003
0.197594, 791.560163
0.197942, 791.937856
0.198285, 791.172962
0.198652, 793.033392
0.199000, 792.696223
0.199359, 793.346149
0.199716, 793.352111
0.200070, 794.137833
0.200416, 794.367619
0.200736, 793.541863
0.201131, 795.028601
0.201479, 795.290571
0.201832, 795.655360
0.202182, 795.783232
0.202530, 796.227823
0.202877, 796.639173
0.203224, 796.521790
0.203579, 798.159944
0.203947, 797.544504
0.204302, 798.257443
0.204657, 798.056107
0.205005, 799.294759
0.205374, 798.820247
0.205731, 799.519828
0.206082, 800.044750
0.206436, 800.064144
0.206790, 800.346753
0.207141, 800.792099
0.207503, 801.308682
0.207830, 801.359469
0.208212, 801.445836
0.208557, 802.044372
0.208907, 802.377919
0.209258, 802.791420
0.209607, 803.154058
0.209962, 803.532355
0.210310, 804.468022
0.210678, 804.170245
0.211035, 804.365619
0.211385, 804.809078
0.211734, 805.456363
0.212088, 805.416255
0.212450, 805.766743
0.212771, 805.550089
0.213169, 806.853375
0.213524, 806.749047
0.213862, 806.571784
0.214220, 807.532015
0.214560, 808.758971
0.214939, 808.055050
0.215293, 808.202958
0.215641, 808.856092
0.215992, 809.064521
0.216350, 809.331510
0.216710, 809.989511
0.217068, 810.105158
0.217427, 810.347961
0.217785, 811.628419
0.218155, 810.929442
0.218513, 811.380863
0.218873, 812.016187
0.219235, 812.220918
0.219596, 812.245331
0.219948, 813.564163
0.220324, 812.786892
0.220672, 813.301815
0.221023, 813.589065
0.221378, 813.916689
0.221734, 814.074256
0.222081, 814.020186
0.222447, 815.934762
0.222816, 815.140022
0.223171, 815.597442
0.223523, 815.485379
0.223883, 816.212731
0.224250, 816.622684
0.224608, 816.960155
0.224963, 817.114893
0.225313, 816.526167
0.225677, 818.294684
0.226037, 817.924952
0.226374, 817.331396
0.226759, 819.339282
0.227117, 819.017847
0.227472, 818.909142
0.227826, 819.629287
0.228182, 820.005547
0.228538, 820.543297
0.228891, 820.385390
0.229254, 820.909633
0.229563, 820.119873
0.229906, 821.588009
0.230261, 821.545712
0.230629, 822.969173
0.230996, 822.122590
0.231356, 822.872430
0.231720, 823.237143
0.232083, 823.335887
0.232428, 822.555484
0.232809, 824.672414
0.233175, 824.024790
0.233536, 824.286986
0.233895, 824.759612
0.234255, 824.928499
0.234610, 825.635324
0.234976, 825.841641
0.235341, 825.933630
0.235685, 825.577142
0.236072, 827.223182
0.236429, 827.004490
0.236786, 826.754933
0.237140, 827.493378
0.237500, 827.817115
0.237862, 827.808248
0.238216, 829.520620
0.238587, 828.385881
0.238946, 829.258273
0.239308, 829.558880
0.239664, 829.149266
0.240051, 830.785383
0.240423, 830.115195
0.240783, 830.376071
0.241156, 830.787156
0.241509, 831.118779
0.241868, 831.250689
0.242233, 831.936913
0.242596, 831.859978
0.242963, 832.329208
0.243312, 831.566917
0.243697, 833.826359
0.244062, 833.378523
0.244410, 833.073878
0.244776, 833.917972
0.245152, 834.096555
0.245523, 834.465457
0.245889, 834.960080
0.246256, 834.758971
0.246613, 836.138965
0.246992, 835.622533
0.247352, 835.726522
0.247713, 836.354300
0.248057, 835.756858
0.248440, 837.039807
0.248799, 836.718070
0.249162, 837.285138
0.249533, 837.661057
0.249891, 837.877146
0.250257, 838.365053
0.250621, 838.139871
0.250982, 838.241708
0.251356, 840.267290
0.251733, 839.231068
0.252097, 839.036147
0.252463, 839.544467
0.252818, 840.056635
0.253159, 839.805343
0.253556, 840.703241
0.253923, 840.957854
0.254283, 841.030072
0.254655, 841.482059
0.255023, 841.984190
0.255390, 841.640267
0.255762, 842.414859
0.256103, 842.862506
0.256506, 842.639852
0.256875, 842.996265
0.257235, 843.402030
0.257604, 843.811833
0.257968, 843.533336
0.258348, 843.998491
0.258699, 844.822624
0.259101, 844.862921
0.259468, 844.785496
0.259840, 845.159265
0.260205, 845.393616
0.260571, 845.797608
0.260951, 845.993925
0.261329, 846.423839
0.261701, 846.667924
0.262044, 845.392937
0.262437, 847.514696
0.262804, 847.018941
0.263181, 847.558767
0.263550, 848.064521
0.263914, 847.748745
0.264257, 848.455382
0.264662, 848.418783
0.265033, 848.741463
0.265404, 849.426329
0.265761, 849.005735
0.266140, 849.194544
0.266490, 850.129231
0.266891, 850.056258
0.267264, 850.469230
0.267638, 850.569030
0.268005, 850.826812
0.268381, 851.234577
0.268755, 851.337886
0.269127, 851.594989
0.269481, 850.958269
0.269875, 852.585519
0.270250, 852.435649
0.270615, 852.726144
0.270993, 852.911180
0.271372, 853.362185
0.271755, 853.484889
0.272122, 853.335811
0.272494, 853.775384
0.272853, 854.783383
0.273255, 854.657963
0.273622, 854.298495
0.273990, 854.580651
0.274371, 855.209637
0.274729, 856.055277
0.275128, 855.459080
0.275508, 856.150058
0.275889, 856.270837
0.276264, 856.552202
0.276642, 856.730861
0.277000, 857.368600
0.277388, 856.939931
0.277769, 857.479002
0.278142, 857.646568
0.278503, 856.988190
0.278886, 859.217372
0.279265, 858.352413
0.279637, 858.560767
0.280024, 858.833868
0.280405, 859.369468
0.280779, 859.191073
0.281156, 859.692035
0.281532, 859.815681
0.281899, 859.161001
0.282298, 860.759952
0.282683, 860.577708
0.283058, 860.633626
0.283436, 860.928197
0.283818, 861.200619
0.284201, 861.537637
0.284573, 861.921669
0.284933, 861.165642
0.285351, 862.722145
0.285732, 862.340452
0.286114, 862.575708
0.286494, 862.535751
0.286878, 863.014979
0.287254, 863.583708
0.287629, 863.655850
0.288002, 863.141758
0.288407, 864.989926
0.288795, 864.429197
0.289161, 864.318643
0.289533, 864.218994
0.289919, 864.865110
0.290304, 864.905935
0.290683, 866.512697
0.291072, 865.553032
0.291447, 865.730559
0.291826, 866.097725
0.292210, 866.378108
0.292603, 866.622986
0.292991, 867.083160
0.293378, 867.018828
0.293764, 866.603328
0.294161, 868.421235
0.294553, 867.718749
0.294929, 867.630268
0.295311, 868.221296
0.295692, 868.244802
0.296079, 868.584689
0.296466, 869.174395
0.296855, 869.174509
0.297207, 868.766404
0.297625, 869.539222
0.298008, 869.474550
0.298394, 869.917217
0.298784, 870.308833
0.299176, 870.377580
0.299568, 870.635588
0.299946, 870.428291
0.300337, 872.127004
0.300744, 871.334566
0.301121, 871.432291
0.301505, 871.934385
0.301885, 871.405124
0.302281, 872.310229
0.302641, 871.491039
0.303060, 872.880014
0.303448, 872.961250
0.303833, 873.080029
0.304211, 872.945327
0.304602, 873.318945
0.304991, 873.724484
0.305350, 873.258009
0.305775, 873.846470
0.306171, 874.158624
0.306559, 874.330114
0.306950, 874.794702
0.307337, 874.862355
0.307733, 874.946044
0.308120, 875.321586
0.308517, 875.486020
0.308908, 875.831113
0.309300, 876.015357
0.309677, 875.255443
0.310085, 876.579482
0.310487, 876.499679
0.310884, 877.240086
0.311277, 876.996227
0.311590, 848.460853
0.311702, 863.291778
0.311854, 875.502886
0.312060, 880.933894
0.312342, 883.105950
0.312658, 881.321737
0.312973, 880.994906
0.313293, 880.946119
0.313614, 880.466438
0.313939, 880.599592
0.314266, 880.158095
0.314583, 879.972758
0.314898, 881.545750
0.315249, 880.377618
0.315572, 880.423688
0.315897, 880.383692
0.316227, 880.763800
0.316561, 881.283553
0.316886, 881.045617
0.317199, 880.445195
0.317539, 881.851677
0.317861, 881.382976
0.318179, 881.458288
0.318497, 883.050296
0.318841, 881.721164
0.319155, 881.910274
0.319482, 882.409086
0.319808, 882.831679
0.320141, 883.232200
0.320467, 882.856507
0.320792, 883.254084
0.321108, 882.286685
0.321460, 884.146738
0.321785, 883.748255
0.322113, 883.873260
0.322447, 883.910161
0.322774, 884.170169
0.323103, 884.764668
0.323413, 885.452515
0.323757, 884.934611
0.324080, 885.119873
0.324408, 885.212278
0.324731, 885.528657
0.325065, 885.705543
0.325396, 885.898464
0.325729, 886.277176
0.326060, 885.334830
0.326398, 886.886541
0.326727, 886.619477
0.327051, 886.646682
0.327372, 887.014715
0.327689, 886.809606
0.327999, 886.110478
0.328343, 888.130438
0.328675, 887.792250
0.329005, 887.993963
0.329327, 888.177225
0.329649, 887.898728
0.329975, 888.350187
0.330302, 888.850206
0.330626, 888.635853
0.330956, 889.050447
0.331279, 887.998151
0.331626, 890.002943
0.331949, 889.516772
0.332287, 889.650757
0.332614, 890.120251
0.332949, 889.791005
0.333284, 889.988869
0.333614, 890.361167
0.333950, 890.599442
0.334270, 890.038335
0.334633, 890.958458
0.334966, 890.916462
0.335298, 891.190695
0.335626, 891.313889
0.335962, 891.299891
0.336293, 891.373656
0.336630, 891.802475
0.336949, 892.465306
0.337315, 892.141644
0.337641, 892.217523
0.337969, 892.438705
0.338300, 892.659171
0.338647, 892.973626
0.338984, 892.738030
0.339302, 891.780440
0.339662, 894.079576
0.339989, 893.056182
0.340331, 893.482889
0.340665, 893.667773
0.341002, 893.938309
0.341344, 894.112516
0.341676, 893.811493
0.341990, 894.024601
0.342356, 894.737954
0.342693, 894.684149
0.343032, 894.845414
0.343356, 894.182394
0.343726, 895.398483
0.344079, 895.284760
0.344422, 895.440214
0.344763, 895.602045
0.345103, 895.864808
0.345441, 896.795004
0.345801, 895.977663
0.346142, 896.111421
0.346480, 896.384673
0.346816, 896.727918
0.347156, 896.174999
0.347503, 896.703769
0.347851, 896.964193
0.348163, 896.863148
0.348533, 897.140399
0.348870, 897.108629
0.349216, 897.704034
0.349570, 897.707543
0.349920, 897.885749
0.350264, 898.081500
0.350613, 897.727012
0.350940, 898.070143
0.351328, 898.560276
0.351675, 898.264989
0.352019, 898.681206
0.352359, 898.720484
0.352699, 898.832132
0.353032, 899.370901
0.353408, 899.551975
0.353749, 899.144248
0.354095, 899.416821
0.354443, 899.634607
0.354800, 900.135117
0.355148, 900.158058
0.355490, 899.985436
0.355839, 900.147870
0.356196, 900.524658
0.356535, 899.520432
0.356911, 901.366260
0.357259, 900.789533
0.357609, 900.899181
0.357958, 901.136400
0.358290, 900.539109
0.358683, 901.525752
0.359037, 901.270535
0.359394, 901.628608
0.359754, 901.909972
0.360111, 901.890880
0.360467, 901.980078
0.360818, 902.015508
0.361168, 902.120892
0.361525, 902.704034
0.361869, 901.859639
0.362234, 903.451081
0.362584, 902.150511
0.362952, 903.656831
0.363311, 903.085122
0.363673, 902.968456
0.364034, 903.344904
0.364394, 903.411802
0.364753, 903.441195
0.365115, 903.672528
0.365471, 903.482474
0.365838, 904.084632
0.366205, 904.067464
0.366547, 903.333547
0.366946, 904.508961
0.367309, 904.411010
0.367668, 904.232917
0.368030, 904.675018
0.368395, 904.757990
0.368749, 904.371015
0.369108, 905.923820
0.369481, 905.030298
0.369846, 905.121647
0.370212, 905.191676
0.370583, 905.435762
0.370962, 905.724031
0.371321, 905.508697
0.371693, 905.865185
0.372053, 905.463608
0.372417, 906.986718
0.372793, 906.114176
0.373159, 905.914161
0.373526, 906.360752
0.373890, 906.574463
0.374250, 905.904162
0.374637, 907.512319
0.375010, 906.823114
0.375384, 906.739916
0.375760, 907.012942
0.376125, 907.141418
0.376492, 907.171679
0.376848, 906.870807
0.377252, 908.315511
0.377623, 907.541335
0.377999, 907.799494
0.378367, 907.562125
0.378742, 908.009659
0.379121, 908.200770
0.379494, 908.019620
0.379841, 907.406331
0.380253, 909.209938
0.380634, 908.771611
0.381010, 908.346980
0.381395, 908.740935
0.381779, 908.794438
0.382145, 908.037090
0.382536, 909.735464
0.382927, 909.138814
0.383305, 909.031166
0.383685, 909.401087
0.384063, 909.604271
0.384451, 909.401917
0.384839, 909.773497
0.385214, 909.483417
0.385592, 909.742520
0.385976, 909.861035
0.386351, 911.224729
0.386752, 910.268121
0.387132, 910.014904
0.387521, 910.515791
0.387913, 910.524884
0.388299, 910.643965
0.388668, 909.503830
0.389076, 910.944648
0.389467, 910.949138
0.389860, 911.060031
0.390249, 911.223786
0.390639, 911.356526
0.391024, 910.963061
0.391427, 911.315096
0.391797, 911.598461
0.392223, 911.504999
0.392611, 911.661548
0.393004, 911.517602
0.393363, 911.169981
0.393794, 912.143720
0.394191, 912.109799
0.394582, 912.290156
0.394980, 912.363091
0.395375, 911.977248
0.395773, 912.125231
0.396178, 912.471381
0.396577, 912.823982
0.396946, 912.351319
0.397378, 912.664868
0.397788, 912.641286
0.398166, 912.626344
0.398600, 912.964608
0.398998, 913.119345
0.399406, 913.194582
0.399814, 913.184356
0.400214, 912.827755
0.400620, 913.307437
0.401019, 913.487001
0.401422, 913.557824
0.401809, 912.590612
0.402235, 914.508056
0.402658, 913.736973
0.403064, 913.721013
0.403467, 914.131193
0.403870, 913.887334
0.404270, 913.015508
0.404705, 914.754782
0.405114, 914.144512
0.405520, 914.052636
0.405920, 913.749538
0.406328, 914.306946
0.406741, 914.740935
0.407163, 914.422631
0.407583, 914.395087
0.407982, 915.457533
0.408418, 914.400672
0.408839, 914.504283
0.409246, 914.702902
0.409669, 915.140588
0.410100, 914.978380
0.410520, 915.036901
0.410919, 913.971211
0.411361, 915.882843
0.411794, 915.061729
0.412222, 915.184206
0.412647, 915.023243
0.413046, 915.787609
0.413506, 915.466023
0.413934, 915.502056
0.414354, 915.519790
0.414786, 915.507490
0.415220, 915.507942
0.415655, 915.893672
0.416084, 915.926008
0.416518, 915.835754
0.416924, 915.698449
0.417391, 915.989963
0.417825, 915.789911
0.418261, 916.039656
0.418690, 916.086896
0.419121, 916.235143
0.419553, 916.101045
0.419989, 916.311814
0.420419, 917.292608
0.420878, 916.200732
0.421316, 916.297815
0.421756, 916.274082
0.422200, 916.307739
0.422643, 916.549598
0.423059, 916.662755
0.423536, 916.952005
0.423982, 916.619100
0.424430, 916.615138
0.424883, 916.803569
0.425333, 916.590084
0.425790, 917.012263
0.426219, 916.226540
0.426695, 917.691280
0.427165, 916.968947
0.427621, 916.759423
0.428081, 917.102932
0.428545, 917.084406
0.429001, 916.907558
0.429461, 917.277365
0.429898, 918.012150
0.430391, 916.969249
0.430863, 917.591367
0.431312, 916.891182
0.431778, 917.123684
0.432236, 917.124892
0.432668, 917.186205
0.433182, 917.613025
0.433653, 917.349206
0.434119, 917.530996
0.434590, 917.440290
0.435064, 917.544353
0.435534, 917.599630
0.436004, 917.196808
0.436484, 917.581859
0.436936, 916.585141
0.437420, 918.314606
0.437907, 917.732936
0.438382, 917.513829
0.438862, 917.420103
0.439347, 917.527186
0.439826, 917.730861
0.440300, 916.960910
0.440795, 918.689130
0.441296, 917.816662
0.441789, 917.990341
0.442287, 917.604913
0.442784, 917.980115
0.443282, 918.175452
0.443737, 916.722296
0.444262, 917.899785
0.444758, 917.782364
0.445255, 918.331623
0.445759, 917.963438
0.446255, 917.943327
0.446760, 918.026223
0.447278, 917.862393
0.447782, 917.880165
0.448267, 916.922801
0.448792, 918.670679
0.449316, 917.939629
0.449809, 917.058710
0.450332, 918.722711
0.450857, 918.464476
0.451368, 918.114440
0.451886, 917.978116
0.452407, 918.164547
0.452914, 917.833453
0.453445, 918.053428
0.453958, 917.745236
0.454456, 918.844772
0.455012, 918.045391
0.455537, 917.885862
0.456051, 918.023960
0.456575, 917.893144
0.457103, 917.749953
0.457620, 917.824171
0.458139, 917.025469
0.458705, 919.027884
0.459247, 918.000377
0.459783, 918.075463
0.460314, 917.683470
0.460858, 917.782817
0.461405, 917.956533
0.461937, 918.108554
0.462456, 916.938196
0.463039, 918.568766
0.463592, 917.850470
0.464146, 917.782591
0.464704, 917.974720
0.465235, 916.791420
0.465823, 917.949892
0.466384, 917.465193
0.466953, 917.533298
0.467515, 917.770366
0.468068, 917.185073
0.468634, 917.723428
0.469163, 916.957665
0.469768, 917.604045
0.470349, 917.360827
0.470926, 917.216240
0.471499, 917.222013
0.472069, 916.984040
0.472641, 917.085009
0.473222, 917.057578
0.473758, 916.585217
0.474380, 917.226352
0.474972, 916.995019
0.475570, 916.887560
0.476126, 915.906124
0.476755, 917.391654
0.477356, 916.582840
0.477941, 916.245633
0.478536, 916.299287
0.479134, 916.656416
0.479735, 916.859073
0.480336, 916.371430
0.480910, 915.616572
0.481563, 916.584462
0.482186, 916.165302
0.482800, 915.980417
0.483416, 915.980908
0.484044, 915.917896
0.484655, 915.378825
0.485282, 915.571256
0.485889, 916.467230
0.486546, 915.396974
0.487160, 915.145644
0.487772, 915.215447
0.488360, 914.452854
0.489042, 915.108290
0.489670, 914.695846
0.490296, 914.898993
0.490932, 914.574388
0.491580, 914.456552
0.492219, 914.419915
0.492874, 914.424254
0.493523, 914.127118
0.494182, 914.098479
0.494831, 913.136173
0.495478, 914.794816
0.496162, 913.356865
0.496833, 913.396597
0.497504, 913.131721
0.498141, 912.036109
0.498817, 913.276610
0.499490, 912.587443
0.500149, 912.273705
0.500821, 912.530921
0.501499, 912.178659
0.502175, 911.950496
0.502852, 912.174244
0.503533, 911.659623
0.504214, 911.325624
0.504849, 910.583670
0.505592, 911.332868
0.506269, 910.411236
0.506937, 910.695770
0.507614, 910.505716
0.508297, 910.233181
0.508999, 909.962721
0.509691, 909.917179
0.510343, 910.157869
0.511076, 909.321360
0.511773, 908.809040
0.512457, 908.322228
0.513167, 908.531864
0.513874, 908.201298
0.514583, 908.305550
0.515284, 907.622043
0.515930, 906.869034
0.516684, 907.076256
0.517397, 906.801381
0.518095, 906.634381
0.518814, 906.364374
0.519521, 905.253217
0.520232, 905.627287
0.520940, 905.187639
0.521651, 904.643022
0.522362, 905.698600
0.523128, 903.842018
0.523838, 903.145116
0.524553, 904.353092
0.525280, 903.035505
0.525990, 902.755613
0.526701, 902.326076
0.527423, 901.882127
0.528108, 900.942761
0.528886, 901.580123
0.529603, 900.637211
0.530303, 900.853790
0.531025, 899.949402
0.531759, 899.737841
0.532509, 899.193035
0.533246, 899.064483
0.533947, 897.566577
0.534689, 898.385768
0.535429, 897.550881
0.536157, 897.037467
0.536890, 896.472588
0.537617, 896.015696
0.538340, 895.463495
0.539040, 894.369845
0.539805, 895.041505
0.540534, 893.993586
0.541244, 893.383617
0.541975, 892.885296
0.542714, 892.354979
0.543464, 891.976342
0.544212, 891.605818
0.544952, 890.779006
0.545682, 890.158963
0.546389, 890.515187
0.547172, 889.157454
0.547893, 888.573180
0.548585, 887.587254
0.549385, 887.847300
0.550121, 886.898728
0.550872, 886.284685
0.551631, 885.566691
0.552374, 885.075501
0.553102, 884.236351
0.553832, 883.319737
0.554589, 883.129080
0.555335, 882.038260
0.556075, 881.799721
0.556780, 880.285892
0.557553, 881.033732
0.558302, 879.319511
0.559066, 879.171716
0.559815, 878.448968
0.560568, 877.586236
0.561296, 875.682942
0.562081, 876.320832
0.562820, 874.770818
0.563557, 874.365204
0.564319, 873.793344
0.565080, 872.802664
0.565839, 871.961514
0.566562, 870.943101
0.567298, 870.578916
0.568052, 869.608724
0.568782, 868.222994
0.569577, 867.766517
0.570316, 866.733766
0.571026, 865.490020
0.571835, 864.922047
0.572584, 863.892012
0.573326, 863.252651
0.574072, 862.184470
0.574823, 861.264461
0.575586, 860.226314
0.576329, 858.507037
0.577115, 858.820511
0.577874, 856.896125
0.578633, 855.793533
0.579407, 855.075161
0.580174, 853.877448
0.580926, 853.029997
0.581677, 851.377467
0.582416, 849.933253
0.583223, 849.349734
0.584003, 847.981247
0.584793, 846.559069
0.585580, 844.948044
0.586393, 842.240954
0.587159, 833.637852