File: Original_Data/Stress_Strain/SR_HIP_HT/18-064_RT_SR+HIP+HT.csv
Eng_Strain, Eng_Stress (MPa)
0.000000, -0.011592
-0.000010, -0.021139
-0.000015, 0.145380
0.000052, 11.520762
0.000094, 18.112287
0.000160, 28.153652
0.000208, 38.972115
0.000227, 47.369516
0.000251, 55.801341
0.000296, 64.575176
0.000337, 72.613583
0.000396, 81.083700
0.000447, 89.388189
0.000486, 97.991714
0.000506, 106.056971
0.000527, 114.734694
0.000575, 124.062495
0.000622, 132.029657
0.000680, 140.994385
0.000728, 149.387660
0.000770, 157.705305
0.000785, 166.058944
0.000817, 174.893981
0.000853, 183.200503
0.000905, 192.178652
0.000961, 200.997344
0.001009, 209.294121
0.001052, 217.534149
0.001065, 225.424726
0.001104, 235.086447
0.001139, 243.340437
0.001180, 249.649055
0.001240, 259.676940
0.001298, 268.991752
0.001331, 275.100824
0.001347, 283.636224
0.001375, 291.259193
0.001416, 299.873026
0.001467, 307.568979
0.001518, 315.777016
0.001583, 323.583575
0.001628, 330.221586
0.001668, 337.732736
0.001713, 343.850586
0.001786, 350.492141
0.001887, 356.382585
0.001999, 360.542587
0.002140, 364.675765
0.002280, 368.335015
0.002428, 371.042201
0.002598, 373.790645
0.002789, 375.246928
0.002997, 376.879143
0.003213, 378.257425
0.003428, 379.800159
0.003634, 381.403650
0.003819, 382.245825
0.003998, 383.713595
0.004201, 384.932290
0.004400, 386.483866
0.004612, 387.345500
0.004822, 388.878372
0.005022, 389.691151
0.005194, 391.322565
0.005369, 392.307262
0.005567, 393.842477
0.005773, 394.662737
0.005973, 396.079498
0.006188, 397.816708
0.006375, 398.635872
0.006542, 399.257576
0.006719, 401.225232
0.006901, 402.014887
0.007101, 402.879770
0.007293, 404.191907
0.007499, 405.359253
0.007681, 406.798496
0.007855, 407.809945
0.008016, 408.798156
0.008199, 409.649890
0.008387, 411.135192
0.008586, 411.963954
0.008780, 412.996751
0.008957, 414.088340
0.009116, 415.156352
0.009284, 416.444344
0.009459, 417.069485
0.009636, 417.968186
0.009829, 419.566274
0.010010, 419.871004
0.010180, 420.709968
0.010350, 422.551462
0.010506, 422.747109
0.010668, 423.815235
0.010865, 425.624877
0.011070, 426.580367
0.011240, 426.921786
0.011421, 429.123064
0.011603, 429.567785
0.011753, 429.656389
0.011913, 430.067067
0.012092, 431.862389
0.012278, 432.745938
0.012460, 433.366168
0.012630, 434.709136
0.012775, 435.018477
0.012929, 436.145092
0.013093, 437.355966
0.013279, 438.399947
0.013464, 439.219111
0.013653, 439.624462
0.013828, 441.453223
0.013976, 441.597408
0.014135, 442.694249
0.014307, 443.658430
0.014490, 444.155558
0.014672, 444.913134
0.014853, 446.450880
0.015030, 446.997922
0.015178, 447.637459
0.015338, 448.892995
0.015512, 449.831822
0.015686, 450.178947
0.015875, 451.080594
0.016057, 451.876785
0.016228, 452.668216
0.016379, 453.357024
0.016532, 454.416005
0.016706, 455.315386
0.016881, 455.819693
0.017069, 457.136175
0.017249, 457.539107
0.017415, 458.384909
0.017560, 458.876105
0.017715, 460.073528
0.017885, 460.573302
0.018058, 461.301519
0.018237, 462.199879
0.018423, 463.014131
0.018594, 463.503892
0.018741, 464.362994
0.018892, 465.254931
0.019054, 465.701504
0.019235, 467.079800
0.019412, 467.606098
0.019594, 468.153744
0.019762, 468.823774
0.019916, 469.657296
0.020072, 470.650117
0.020242, 471.022217
0.020421, 472.146868
0.020585, 472.109915
0.020776, 473.836167
0.020968, 474.639122
0.021098, 473.770876
0.021261, 476.307867
0.021453, 476.617396
0.021618, 476.351356
0.021788, 477.398133
0.021965, 478.350110
0.022138, 479.333749
0.022291, 479.497809
0.022439, 480.201768
0.022616, 481.645130
0.022793, 481.957266
0.022976, 482.562231
0.023154, 483.333711
0.023326, 484.202600
0.023474, 484.279982
0.023628, 484.826872
0.023797, 486.201579
0.023966, 486.225232
0.024141, 486.908033
0.024316, 487.719867
0.024484, 488.530227
0.024631, 488.544283
0.024785, 489.783269
0.024958, 490.461498
0.025137, 490.853170
0.025311, 491.394960
0.025484, 492.418877
0.025644, 492.274541
0.025796, 493.729918
0.025950, 494.021650
0.026116, 494.654198
0.026292, 494.879317
0.026475, 496.354190
0.026658, 496.763395
0.026819, 497.433084
0.026968, 498.241215
0.027121, 498.522973
0.027297, 498.867868
0.027474, 499.343384
0.027663, 500.629374
0.027837, 500.637837
0.028004, 501.554485
0.028143, 502.038276
0.028298, 502.846633
0.028473, 503.043150
0.028649, 503.632170
0.028840, 504.856344
0.029009, 504.638291
0.029170, 505.674261
0.029308, 506.248394
0.029460, 506.688430
0.029629, 507.106590
0.029822, 508.191038
0.030005, 508.511184
0.030187, 508.982128
0.030344, 509.544094
0.030487, 510.136137
0.030633, 510.675810
0.030808, 511.514471
0.030988, 511.800385
0.031155, 512.087357
0.031327, 513.410527
0.031510, 514.226026
0.031650, 513.205320
0.031802, 514.981372
0.032005, 516.222323
0.032183, 515.634437
0.032355, 515.700597
0.032525, 516.912869
0.032695, 517.688544
0.032848, 517.721152
0.033002, 518.457379
0.033177, 519.250019
0.033349, 519.609612
0.033519, 519.671881
0.033695, 520.958626
0.033859, 521.034081
0.034009, 521.699917
0.034158, 522.011978
0.034327, 522.478501
0.034511, 523.153027
0.034686, 523.672183
0.034875, 524.734943
0.035037, 524.708834
0.035184, 525.343648
0.035333, 525.789239
0.035502, 526.358082
0.035677, 526.903423
0.035859, 527.626653
0.036043, 527.908033
0.036202, 528.307753
0.036351, 528.793811
0.036499, 529.313383
0.036673, 529.733620
0.036845, 530.387781
0.037034, 531.124008
0.037219, 531.339568
0.037376, 531.611010
0.037522, 532.595745
0.037676, 533.049346
0.037842, 533.302275
0.038005, 533.828232
0.038192, 534.233092
0.038372, 534.421295
0.038533, 535.056299
0.038683, 536.050102
0.038834, 535.920577
0.038994, 536.377768
0.039168, 537.288257
0.039354, 537.757236
0.039538, 538.309038
0.039704, 538.729011
0.039857, 539.505517
0.040008, 539.054901
0.040175, 540.231089
0.040352, 540.499282
0.040528, 540.795813
0.040703, 541.243936
0.040866, 541.726139
0.040999, 542.268118
0.041168, 543.090456
0.041346, 543.556374
0.041500, 542.848220
0.041694, 544.882264
0.041897, 545.354190
0.042060, 544.616980
0.042198, 545.406068
0.042341, 546.396471
0.042508, 546.513640
0.042680, 546.903499
0.042858, 547.154425
0.043041, 548.136212
0.043215, 548.527280
0.043360, 548.503930
0.043510, 549.427416
0.043679, 549.489043
0.043854, 550.109461
0.044034, 550.921560
0.044223, 551.001549
0.044391, 551.434217
0.044533, 551.824832
0.044681, 552.132056
0.044851, 552.736908
0.045023, 553.044472
0.045204, 554.278584
0.045389, 554.147926
0.045554, 554.406144
0.045702, 554.842855
0.045854, 555.351810
0.046023, 555.864770
0.046198, 556.503325
0.046378, 556.735850
0.046559, 557.256896
0.046728, 557.797514
0.046886, 558.232185
0.047033, 558.513527
0.047201, 558.877125
0.047378, 559.708343
0.047553, 559.848900
0.047733, 560.040467
0.047904, 561.062986
0.048055, 561.383095
0.048210, 561.934520
0.048376, 561.769062
0.048548, 562.484055
0.048725, 562.536953
0.048910, 562.981939
0.049079, 564.020026
0.049232, 564.120192
0.049387, 564.260901
0.049550, 564.495504
0.049725, 565.648001
0.049899, 565.422051
0.050078, 566.590342
0.050235, 566.302275
0.050378, 567.104511
0.050545, 567.615696
0.050714, 567.430099
0.050871, 567.843686
0.051075, 569.469697
0.051269, 568.827023
0.051419, 569.204489
0.051558, 569.581047
0.051711, 570.230069
0.051872, 570.550858
0.052040, 570.360840
0.052225, 571.639538
0.052406, 571.698557
0.052566, 572.229011
0.052719, 572.486813
0.052871, 573.411093
0.053030, 573.497317
0.053206, 573.792753
0.053393, 574.061135
0.053570, 574.359480
0.053730, 574.653858
0.053882, 575.435540
0.054041, 575.992708
0.054201, 576.092685
0.054376, 576.335940
0.054562, 576.786632
0.054742, 577.278622
0.054912, 577.742915
0.055055, 578.427190
0.055210, 578.043225
0.055375, 578.928663
0.055547, 579.071601
0.055727, 579.798269
0.055905, 579.761014
0.056070, 580.193569
0.056224, 580.773370
0.056374, 580.923865
0.056538, 581.266984
0.056716, 581.881206
0.056900, 582.378486
0.057075, 582.249452
0.057242, 583.266417
0.057395, 583.606967
0.057542, 583.382831
0.057707, 584.379921
0.057871, 584.236492
0.058051, 584.822187
0.058229, 584.836885
0.058392, 586.047533
0.058536, 585.814970
0.058688, 586.044548
0.058855, 586.362956
0.059030, 587.102547
0.059214, 587.545341
0.059394, 587.832691
0.059564, 588.647359
0.059715, 589.112522
0.059876, 589.263130
0.060044, 589.409544
0.060218, 589.701504
0.060379, 588.765284
0.060573, 591.366395
0.060754, 591.476914
0.060895, 590.291053
0.061023, 591.647888
0.061223, 592.810436
0.061399, 591.528754
0.061569, 592.377465
0.061744, 593.104058
0.061911, 593.160583
0.062060, 593.472077
0.062213, 594.114600
0.062384, 594.639953
0.062556, 594.247336
0.062732, 594.971359
0.062915, 595.484093
0.063075, 595.269213
0.063228, 596.593592
0.063380, 596.582672
0.063537, 596.635003
0.063700, 596.636817
0.063885, 597.550178
0.064070, 597.974949
0.064231, 598.063251
0.064378, 598.814252
0.064529, 599.024938
0.064686, 598.646565
0.064862, 599.892239
0.065041, 600.138139
0.065217, 600.418688
0.065382, 600.853359
0.065541, 601.720396
0.065690, 601.534308
0.065852, 601.263961
0.066027, 602.373158
0.066199, 602.329139
0.066378, 602.817237
0.066545, 603.362503
0.066697, 603.743860
0.066844, 603.449105
0.066983, 602.448727
0.067141, 603.999433
0.067317, 604.688053
0.067497, 604.969244
0.067659, 605.563213
0.067808, 605.729615
0.067959, 605.978463
0.068127, 606.711517
0.068300, 607.140709
0.068476, 606.863410
0.068658, 607.716051
0.068813, 607.466032
0.068965, 607.882151
0.069113, 608.661075
0.069279, 608.780700
0.069451, 609.176717
0.069627, 609.173090
0.069809, 610.008086
0.069976, 610.132056
0.070120, 610.424582
0.070268, 610.647812
0.070429, 611.162586
0.070599, 610.705925
0.070759, 610.998866
0.070940, 612.459835
0.071121, 612.941888
0.071248, 611.363259
0.071391, 613.599788
0.071585, 613.956397
0.071761, 613.252513
0.071933, 614.081199
0.072113, 614.590909
0.072282, 614.647888
0.072440, 615.490365
0.072587, 615.636590
0.072753, 616.063515
0.072926, 616.113051
0.073105, 616.664135
0.073279, 616.418915
0.073448, 616.926396
0.073597, 617.232903
0.073747, 617.392655
0.073912, 617.682309
0.074087, 618.437014
0.074264, 618.508615
0.074435, 618.787992
0.074597, 619.411547
0.074749, 619.743482
0.074900, 619.580896
0.075064, 619.915288
0.075241, 620.724099
0.075416, 620.605494
0.075589, 620.601829
0.075753, 621.290486
0.075901, 621.713368
0.076050, 621.698065
0.076212, 622.550895
0.076387, 623.107081
0.076568, 623.229086
0.076748, 623.110859
0.076920, 624.459231
0.077063, 624.250283
0.077219, 624.221303
0.077384, 624.991347
0.077553, 624.761997
0.077731, 625.382944
0.077911, 625.513489
0.078071, 625.965994
0.078213, 625.896055
0.078371, 627.069561
0.078537, 626.969886
0.078712, 627.205282
0.078892, 627.287652
0.079069, 628.027091
0.079237, 627.962518
0.079376, 628.367075
0.079535, 628.914003
0.079696, 628.922051
0.079869, 629.217222
0.080035, 629.297438
0.080225, 630.228104
0.080367, 629.171390
0.080523, 631.151969
0.080705, 632.286027
0.080862, 630.367868
0.081005, 630.899531
0.081216, 633.039560
0.081401, 631.952543
0.081560, 631.855551
0.081704, 632.702826
0.081852, 632.958324
0.082010, 633.121854
0.082173, 633.277790
0.082352, 634.058490
0.082517, 633.743369
0.082682, 634.176642
0.082831, 634.890048
0.082980, 635.159714
0.083146, 635.284856
0.083319, 635.666251
0.083499, 635.748621
0.083677, 636.225043
0.083836, 636.476385
0.083987, 636.995277
0.084137, 636.731240
0.084300, 637.222776
0.084467, 637.535895
0.084644, 637.836469
0.084821, 638.233092
0.084978, 638.436598
0.085129, 638.974382
0.085274, 639.171919
0.085443, 639.884380
0.085613, 639.625708
0.085794, 639.853661
0.085975, 640.662284
0.086139, 640.691038
0.086281, 640.741366
0.086433, 641.116565
0.086597, 641.588491
0.086767, 641.859405
0.086941, 641.969130
0.087123, 642.677737
0.087288, 642.946951
0.087430, 643.102018
0.087576, 643.344215
0.087748, 643.714388
0.087912, 643.740875
0.088084, 643.824114
0.088268, 644.587773
0.088424, 644.619814
0.088572, 644.912189
0.088728, 645.336394
0.088892, 645.583390
0.089060, 645.542205
0.089245, 646.688997
0.089421, 647.010051
0.089580, 646.761770
0.089726, 647.274163
0.089876, 647.449709
0.090035, 647.576816
0.090203, 647.575380
0.090388, 648.457417
0.090566, 648.562722
0.090725, 648.756442
0.090877, 649.322792
0.091025, 649.125595
0.091190, 649.674035
0.091362, 649.622535
0.091540, 650.230031
0.091718, 650.376030
0.091868, 650.149248
0.092029, 652.149437
0.092188, 651.397302
0.092336, 650.116905
0.092522, 652.953185
0.092725, 652.644563
0.092888, 651.720660
0.093041, 652.572244
0.093185, 652.901572
0.093336, 653.520215
0.093494, 653.479937
0.093674, 654.005894
0.093854, 654.280511
0.094024, 653.676680
0.094191, 654.913323
0.094332, 654.821280
0.094488, 655.202600
0.094650, 655.706869
0.094822, 655.773936
0.094998, 655.717713
0.095176, 656.573226
0.095336, 656.836394
0.095477, 656.756631
0.095622, 656.717864
0.095780, 657.319844
0.095949, 657.571639
0.096120, 657.641313
0.096301, 658.310058
0.096463, 658.915628
0.096603, 658.468639
0.096756, 659.403574
0.096923, 659.517607
0.097091, 659.404255
0.097264, 659.753231
0.097443, 660.488551
0.097604, 660.482355
0.097747, 660.379846
0.097898, 661.443588
0.098060, 661.165646
0.098229, 661.486889
0.098409, 662.046853
0.098586, 662.154765
0.098749, 662.296002
0.098891, 662.766304
0.099044, 663.158316
0.099207, 662.919746
0.099381, 663.244616
0.099555, 663.657069
0.099732, 663.930704
0.099884, 663.882642
0.100035, 664.820978
0.100188, 665.154122
0.100343, 664.694287
0.100517, 665.572924
0.100691, 665.551500
0.100869, 665.574851
0.101026, 665.900438
0.101176, 666.294227
0.101312, 665.682952
0.101481, 667.612446
0.101676, 667.600733
0.101853, 666.779566
0.102007, 667.353057
0.102197, 669.099713
0.102351, 668.136704
0.102488, 667.926018
0.102643, 668.593516
0.102808, 668.955037
0.102991, 669.356231
0.103162, 669.030341
0.103324, 670.147019
0.103469, 669.938336
0.103612, 669.896924
0.103778, 670.660206
0.103952, 671.170672
0.104122, 670.799101
0.104301, 671.681138
0.104466, 671.688733
0.104611, 671.829328
0.104756, 671.896773
0.104921, 672.673354
0.105093, 672.270196
0.105274, 672.832011
0.105454, 673.544737
0.105613, 673.400249
0.105759, 673.514698
0.105911, 673.844517
0.106069, 674.413398
0.106239, 674.312250
0.106416, 674.562835
0.106591, 675.299932
0.106746, 675.140822
0.106889, 675.053389
0.107036, 675.637270
0.107197, 675.990025
0.107368, 676.246694
0.107545, 676.633039
0.107723, 676.744842
0.107893, 677.203846
0.108036, 677.521461
0.108186, 677.801670
0.108350, 677.493501
0.108518, 677.888385
0.108697, 678.327855
0.108876, 678.735434
0.109036, 678.882453
0.109178, 679.112031
0.109327, 679.364354
0.109488, 679.522331
0.109660, 679.988362
0.109828, 679.920464
0.110005, 680.144449
0.110166, 680.010806
0.110309, 680.889821
0.110457, 680.887365
0.110620, 681.236946
0.110793, 681.847200
0.110970, 681.780171
0.111151, 682.053087
0.111314, 682.324001
0.111456, 682.653140
0.111601, 682.795851
0.111761, 683.032872
0.111932, 683.322111
0.112107, 683.487418
0.112275, 683.421938
0.112443, 684.133492
0.112571, 683.555392
0.112718, 684.919671
0.112906, 685.979105
0.113071, 684.305675
0.113220, 684.475176
0.113428, 686.910942
0.113598, 685.705320
0.113730, 685.429608
0.113878, 685.997317
0.114037, 686.656578
0.114208, 686.386231
0.114382, 686.582030
0.114562, 687.691793
0.114718, 687.606779
0.114860, 687.561702
0.115019, 688.553994
0.115182, 688.199955
0.115359, 688.688355
0.115531, 688.410300
0.115709, 688.919406
0.115863, 689.222058
0.116009, 689.555203
0.116156, 689.708683
0.116317, 689.677322
0.116482, 689.739326
0.116661, 690.719565
0.116830, 690.415892
0.116995, 691.320940
0.117138, 691.202260
0.117287, 691.603453
0.117454, 691.740271
0.117619, 691.678871
0.117796, 692.369380
0.117972, 692.661679
0.118130, 692.705396
0.118271, 692.552029
0.118422, 693.258407
0.118585, 693.392579
0.118758, 693.729766
0.118932, 694.044888
0.119103, 694.138177
0.119265, 694.227084
0.119405, 694.638442
0.119551, 694.644261
0.119715, 695.076929
0.119894, 695.500302
0.120071, 695.724212
0.120250, 695.667762
0.120407, 696.108932
0.120558, 696.325512
0.120703, 696.282627
0.120865, 697.069334
0.121041, 697.165835
0.121217, 697.380526
0.121390, 696.874707
0.121551, 697.739855
0.121699, 697.870626
0.121844, 698.053767
0.122005, 698.511260
0.122178, 698.817955
0.122354, 698.779869
0.122528, 699.089738
0.122683, 699.508199
0.122827, 699.379241
0.122978, 699.933689
0.123144, 700.017079
0.123312, 700.270649
0.123472, 699.542356
0.123654, 701.717827
0.123831, 701.745485
0.123963, 700.187561
0.124094, 701.296229
0.124278, 702.386005
0.124456, 701.578780
0.124618, 701.719754
0.124790, 702.649588
0.124947, 702.256404
0.125092, 702.602811
0.125229, 702.759843
0.125395, 703.472455
0.125564, 703.458928
0.125738, 703.988891
0.125912, 704.014849
0.126075, 703.870060
0.126223, 704.751719
0.126366, 704.900438
0.126526, 704.906333
0.126700, 705.121817
0.126876, 705.316708
0.127046, 705.569674
0.127203, 705.570581
0.127344, 706.073302
0.127494, 706.458588
0.127652, 706.504988
0.127822, 706.883964
0.128005, 706.935993
0.128183, 707.267400
0.128344, 707.200748
0.128493, 708.036235
0.128636, 707.632396
0.128799, 707.995504
0.128970, 708.527054
0.129143, 708.354304
0.129314, 708.703129
0.129475, 709.331142
0.129610, 709.107836
0.129757, 709.167914
0.129925, 710.157674
0.130091, 710.091325
0.130267, 710.148001
0.130449, 710.528678
0.130612, 711.051084
0.130753, 710.982733
0.130892, 710.477292
0.131060, 711.724401
0.131233, 711.510542
0.131406, 711.677322
0.131576, 712.067634
0.131735, 712.243784
0.131879, 712.403348
0.132016, 712.349241
0.132189, 713.303673
0.132358, 712.908335
0.132532, 713.150079
0.132709, 713.952656
0.132876, 713.967619
0.133018, 713.886156
0.133157, 713.582256
0.133318, 715.307716
0.133510, 715.079309
0.133685, 714.452996
0.133839, 714.972606
0.134024, 715.936409
0.134169, 715.142182
0.134311, 715.650419
0.134459, 715.850487
0.134637, 716.460213
0.134813, 716.655180
0.134997, 716.897604
0.135156, 717.101678
0.135303, 717.280171
0.135455, 717.619285
0.135612, 717.443399
0.135783, 717.589813
0.135964, 718.221303
0.136130, 717.930326
0.136285, 718.174072
0.136431, 718.550744
0.136577, 719.005403
0.136736, 719.190584
0.136910, 719.485604
0.137084, 719.865374
0.137255, 719.773332
0.137414, 720.045530
0.137557, 720.225270
0.137703, 720.493614
0.137859, 720.245938
0.138036, 720.953979
0.138217, 721.074548
0.138393, 721.312023
0.138556, 721.701239
0.138698, 721.704715
0.138850, 722.399154
0.139011, 722.103869
0.139185, 722.629449
0.139357, 722.498489
0.139530, 722.462442
0.139694, 723.183670
0.139839, 723.283534
0.139984, 723.583655
0.140146, 724.012658
0.140320, 724.166893
0.140488, 723.901421
0.140665, 724.407466
0.140817, 724.398549
0.140962, 724.444722
0.141108, 724.768344
0.141268, 725.159450
0.141434, 725.163077
0.141612, 725.710950
0.141787, 725.996108
0.141938, 725.785121
0.142081, 725.890728
0.142226, 726.740422
0.142388, 726.544208
0.142557, 726.953034
0.142733, 727.130356
0.142912, 727.584221
0.143071, 727.285347
0.143206, 727.218922
0.143348, 728.047835
0.143505, 728.905426
0.143693, 728.584410
0.143861, 727.667989
0.144021, 729.154651
0.144203, 729.661717
0.144349, 729.090947
0.144489, 729.155974
0.144646, 729.546059
0.144813, 729.565707
0.144994, 730.499736
0.145170, 730.236303
0.145327, 730.453336
0.145476, 731.091967
0.145619, 730.862541
0.145781, 730.928210
0.145946, 731.183859
0.146127, 731.523313
0.146299, 731.588264
0.146458, 731.967052
0.146604, 732.022784
0.146745, 732.426585
0.146910, 732.422164
0.147085, 733.192020
0.147261, 733.145885
0.147433, 733.179702
0.147592, 733.403914
0.147738, 733.550593
0.147885, 733.746543
0.148047, 733.816935
0.148227, 734.657334
0.148395, 734.005705
0.148570, 734.392201
0.148736, 735.140633
0.148877, 734.639424
0.149027, 735.258936
0.149186, 735.596426
0.149356, 735.714502
0.149529, 735.762412
0.149701, 736.031550
0.149855, 736.380979
0.149998, 736.122535
0.150149, 736.545832
0.150314, 737.329177
0.150482, 736.980881
0.150660, 737.230522
0.150835, 737.593101
0.150999, 738.090116
0.151135, 737.751681
0.151284, 738.526978
0.151449, 738.647208
0.151613, 738.608403
0.151790, 739.012431
0.151962, 739.173392
0.152117, 739.009635
0.152255, 738.936787
0.152404, 739.934255
0.152563, 739.722210
0.152731, 739.942946
0.152901, 740.171805
0.153076, 740.329139
0.153237, 740.699577
0.153377, 740.671843
0.153510, 740.578629
0.153675, 741.627673
0.153866, 741.914910
0.154033, 740.430817
0.154188, 741.970830
0.154378, 742.847314
0.154525, 742.189413
0.154660, 741.702297
0.154812, 742.391975
0.154985, 742.953752
0.155168, 743.278319
0.155342, 742.887969
0.155508, 743.559246
0.155653, 743.738495
0.155799, 743.726782
0.155960, 743.707512
0.156131, 744.379732
0.156305, 744.456926
0.156487, 744.762941
0.156645, 745.071526
0.156785, 745.024862
0.156932, 745.309340
0.157093, 745.438789
0.157259, 745.931762
0.157429, 745.620872
0.157602, 745.992632
0.157766, 746.383700
0.157910, 746.675433
0.158056, 746.751304
0.158222, 747.231429
0.158386, 746.840135
0.158561, 747.074813
0.158732, 747.250397
0.158890, 747.497733
0.159028, 747.692851
0.159181, 748.229729
0.159338, 748.403310
0.159508, 748.567067
0.159675, 747.911320
0.159860, 749.123593
0.160024, 749.196063
0.160164, 748.891635
0.160319, 749.605909
0.160485, 749.727008
0.160656, 749.746656
0.160834, 750.095141
0.161006, 750.024144
0.161166, 750.327666
0.161307, 750.314101
0.161455, 751.000038
0.161617, 750.922240
0.161785, 751.183556
0.161964, 751.476007
0.162137, 751.570279
0.162293, 751.547382
0.162437, 751.830311
0.162586, 752.389783
0.162742, 752.138064
0.162915, 752.144109
0.163091, 752.656200
0.163266, 752.884531
0.163418, 752.752286
0.163561, 753.261279
0.163701, 753.188657
0.163853, 753.200068
0.164024, 753.935918
0.164200, 754.128693
0.164378, 754.256404
0.164536, 754.458702
0.164682, 754.780095
0.164814, 754.311267
0.164978, 755.085317
0.165162, 755.688166
0.165328, 754.311192
0.165483, 755.112824
0.165670, 756.801708
0.165818, 755.856495
0.165958, 755.932139
0.166116, 756.263697
0.166289, 756.910036
0.166464, 756.767891
0.166631, 756.738230
0.166799, 757.450956
0.166945, 757.172448
0.167083, 757.320638
0.167251, 757.951032
0.167419, 757.940603
0.167588, 757.586602
0.167760, 758.399720
0.167922, 758.442454
0.168065, 758.623101
0.168210, 758.922844
0.168379, 759.205282
0.168554, 759.412491
0.168724, 758.989723
0.168895, 759.806582
0.169047, 759.657523
0.169190, 759.548893
0.169332, 760.112975
0.168998, 760.554598
0.169165, 760.365752
0.169344, 760.834429
0.169528, 761.286519
0.169683, 760.851999
0.169824, 760.846104
0.169972, 761.717260
0.170127, 761.475062
0.170299, 761.799403
0.170476, 762.069523
0.170645, 762.002872
0.170811, 762.592156
0.170951, 762.439810
0.171103, 763.074624
0.171260, 762.498413
0.171426, 763.028716
0.171610, 763.515114
0.171783, 763.545530
0.171942, 763.373876
0.172086, 763.966183
0.172231, 764.029132
0.172386, 763.824341
0.172559, 764.442454
0.172737, 764.609234
0.172913, 764.673732
0.173067, 764.835449
0.173220, 765.744691
0.173366, 765.367906
0.173528, 765.298950
0.173701, 766.051122
0.173873, 766.101640
0.174044, 766.065783
0.174200, 766.079385
0.174348, 766.466221
0.174494, 766.563780
0.174657, 767.018288
0.174825, 767.005517
0.174992, 766.773067
0.175177, 768.137270
0.175368, 768.610633
0.175486, 766.304957
0.175641, 768.842364
0.175829, 769.126464
0.175994, 767.728293
0.176163, 768.041638
0.176328, 768.494899
0.176489, 768.809303
0.176628, 768.587811
0.176772, 769.019232
0.176936, 769.744805
0.177105, 769.280624
0.177284, 769.829328
0.177460, 770.024069
0.177621, 770.167914
0.177765, 770.336885
0.177914, 770.492594
0.178072, 770.317766
0.178241, 770.636364
0.178420, 771.445099
0.178598, 771.303295
0.178748, 770.822943
0.178888, 771.353737
0.179041, 772.002645
0.179205, 772.043301
0.179372, 771.854681
0.179548, 772.574889
0.179721, 772.481750
0.179879, 772.610292
0.180024, 772.840928
0.180170, 773.166062
0.180334, 773.076853
0.180503, 773.051840
0.180683, 773.794302
0.180857, 773.843913
0.181019, 773.809000
0.181166, 774.242198
0.181311, 774.155936
0.181467, 774.023011
0.181640, 774.661415
0.181816, 774.700899
0.181992, 774.897567
0.182148, 775.065102
0.182292, 775.491423
0.182437, 775.381773
0.182600, 775.677171
0.182771, 775.979899
0.182943, 775.917970
0.183123, 776.495012
0.183282, 776.335298
0.183429, 776.434406
0.183574, 776.479143
0.183737, 777.257840
0.183907, 777.164211
0.184079, 777.045001
0.184259, 777.315499
0.184418, 777.577760
0.184565, 778.107194
0.184718, 777.962631
0.184883, 778.368511
0.185056, 778.462367
0.185234, 778.333371
0.185407, 778.484282
0.185564, 778.718658
0.185710, 778.865223
0.185853, 778.632623
0.186007, 779.133870
0.186181, 780.112635
0.186376, 780.269100
0.186537, 778.525315
0.186693, 780.260523
0.186855, 780.722512
0.187011, 780.442303
0.187164, 780.585090
0.187330, 780.254780
0.187506, 781.188015
0.187687, 781.291468
0.187845, 781.098995
0.187989, 781.366243
0.188137, 781.671768
0.188302, 782.239326
0.188467, 781.576702
0.188649, 782.604096
0.188825, 782.259238
0.188980, 782.236908
0.189132, 783.015378
0.189281, 782.853624
0.189440, 782.895111
0.189600, 782.739515
0.189788, 784.007217
0.189960, 783.392428
0.190124, 783.717789
0.190265, 783.956737
0.190411, 784.099259
0.190563, 783.621099
0.190735, 784.371496
0.190917, 784.459609
0.191088, 784.517456
0.191251, 784.861445
0.191397, 785.293886
0.191548, 784.980390
0.191708, 785.139802
0.191880, 785.304957
0.192055, 785.696138
0.192232, 785.842704
0.192389, 785.783156
0.192536, 786.409771
0.192684, 786.206302
0.192847, 786.902441
0.193025, 787.126804
0.193204, 786.637233
0.193381, 786.972909
0.193541, 787.193494
0.193681, 787.421975
0.193822, 787.047004
0.193986, 787.864090
0.194154, 787.815159
0.194323, 787.661452
0.194501, 788.628353
0.194665, 788.224174
0.194806, 788.507481
0.194950, 788.121137
0.195117, 789.136288
0.195288, 789.132623
0.195469, 789.165873
0.195645, 789.655105
0.195807, 789.609990
0.195949, 789.607194
0.196091, 789.794642
0.196245, 789.764075
0.196420, 790.810096
0.196618, 791.329101
0.196781, 789.653896
0.196936, 790.941245
0.197106, 791.175622
0.197259, 790.935464
0.197410, 790.692473
0.197579, 790.859631
0.197758, 791.673959
0.197934, 791.677586
0.198094, 791.864354
0.198243, 792.134852
0.198390, 792.141616
0.198557, 792.541827
0.198729, 792.404708
0.198905, 792.788181
0.199085, 792.677851
0.199248, 793.021386
0.199391, 793.208381
0.199536, 793.227915
0.199699, 793.364090
0.199870, 793.492859
0.200051, 794.090456
0.200216, 793.760070
0.200380, 793.995201
0.200529, 794.497242
0.200674, 794.313497
0.200839, 794.315990
0.201013, 795.040996
0.201192, 795.214350
0.201360, 794.856646
0.201524, 795.291166
0.201666, 795.455792
0.201806, 795.371911
0.201970, 795.829819
0.202139, 795.970755
0.202313, 795.904632
0.202488, 795.925527
0.202657, 796.459609
0.202802, 796.444457
0.202943, 796.224552
0.203118, 797.250926
0.203284, 796.913738
0.203454, 796.972795
0.203630, 797.638971
0.203786, 797.312628
0.203932, 797.685219
0.204074, 797.663908
0.204239, 798.346067
0.204413, 798.230938
0.204590, 798.240988
0.204771, 798.755346
0.204937, 798.848712
0.205088, 799.051802
0.205234, 798.936825
0.205402, 799.537558
0.205571, 799.142069
0.205750, 799.491347
0.205930, 800.086828
0.206095, 799.822980
0.206239, 799.804013
0.206389, 800.014434
0.206550, 800.134852
0.206719, 800.159223
0.206899, 800.690924
0.207083, 801.041223
0.207238, 800.646112
0.207389, 801.092080
0.207529, 800.912907
0.207691, 801.055694
0.207853, 801.123064
0.208019, 801.030605
0.208185, 801.841570
0.208359, 802.606174
0.208514, 801.799214
0.208634, 801.530227
0.208822, 803.436107
0.209015, 803.334580
0.209184, 802.285990
0.209351, 802.548628
0.209512, 803.208910
0.209653, 803.052067
0.209804, 803.657712
0.209966, 803.208910
0.210142, 804.216240
0.210317, 803.690509
0.210487, 803.704942
0.210658, 804.558263
0.210802, 804.124197
0.210947, 804.397567
0.211106, 804.332691
0.211283, 804.791204
0.211406, 805.225988