File: Original_Data/Stress_Strain/SR_HIP_HT/18-069_RT_SR+HIP+HT.csv
Eng_Strain, Eng_Stress (MPa)
0.000042, 8.452587
0.000123, 25.726969
0.000227, 47.998174
0.000315, 66.010757
0.000403, 85.037177
0.000495, 105.251946
0.000585, 123.579760
0.000676, 142.678221
0.000759, 161.234452
0.000853, 180.135282
0.000942, 198.937525
0.001028, 216.892339
0.001122, 236.875903
0.001204, 254.261641
0.001279, 270.030853
0.001359, 286.487872
0.001435, 301.010006
0.001526, 316.134255
0.001631, 331.075406
0.001772, 344.283738
0.001941, 354.942674
0.002174, 363.582916
0.002479, 368.680855
0.002881, 374.767525
0.003267, 377.441424
0.003671, 380.450044
0.004084, 383.436138
0.004504, 386.103891
0.004898, 388.597886
0.005319, 392.116281
0.005718, 393.893343
0.006113, 396.016595
0.006485, 398.679688
0.006854, 400.056492
0.007269, 404.336908
0.007639, 405.897890
0.008024, 408.134430
0.008405, 411.164589
0.008765, 412.315917
0.009149, 416.022392
0.009523, 417.335544
0.009895, 419.184102
0.010268, 421.466336
0.010630, 423.433979
0.010991, 425.373129
0.011355, 427.517372
0.011700, 430.035123
0.012094, 431.330542
0.012431, 434.078922
0.012814, 434.961505
0.013168, 437.369871
0.013521, 438.827947
0.013888, 440.933808
0.014229, 442.843027
0.014591, 444.672640
0.014949, 447.008487
0.015312, 447.654264
0.015668, 450.562308
0.016007, 451.560641
0.016351, 453.015193
0.016694, 454.951275
0.017063, 456.876407
0.017390, 458.002652
0.017783, 459.905202
0.018127, 461.592051
0.018468, 463.068692
0.018806, 464.519229
0.019094, 465.579017
0.019427, 467.237184
0.019816, 469.427765
0.020154, 470.525783
0.020498, 471.773501
0.020845, 473.631948
0.021181, 473.956011
0.021558, 477.299019
0.021894, 477.535104
0.022245, 479.438715
0.022595, 480.705793
0.022924, 482.254992
0.023258, 482.306066
0.023631, 485.595044
0.023973, 486.177282
0.024313, 487.219452
0.024664, 488.698405
0.025001, 490.238245
0.025331, 491.297086
0.025685, 492.711325
0.026039, 494.444171
0.026365, 494.880158
0.026735, 496.628614
0.027079, 498.565112
0.027419, 498.901603
0.027760, 500.495207
0.028098, 501.574167
0.028441, 502.675861
0.028772, 504.029743
0.029157, 505.579207
0.029474, 506.583488
0.029847, 507.840640
0.030190, 509.042511
0.030529, 510.173190
0.030870, 511.312621
0.031205, 512.294245
0.031555, 513.620316
0.031889, 515.673285
0.032238, 515.328420
0.032598, 516.716099
0.032948, 518.615883
0.033281, 518.404956
0.033648, 520.645361
0.033981, 521.554124
0.034319, 522.408139
0.034672, 523.851248
0.035021, 524.854128
0.035377, 526.311977
0.035708, 527.563255
0.036075, 527.550297
0.036428, 529.429318
0.036739, 529.086500
0.037121, 530.583753
0.037458, 531.796575
0.037799, 533.091502
0.038137, 533.822680
0.038473, 535.091653
0.038823, 536.104876
0.039163, 537.834009
0.039523, 537.781268
0.039869, 539.265146
0.040208, 540.033532
0.040558, 540.896942
0.040888, 542.611791
0.041260, 542.172281
0.041606, 543.922783
0.041941, 544.409654
0.042294, 546.035502
0.042621, 547.427500
0.042985, 546.891941
0.043340, 549.135377
0.043679, 549.606562
0.044016, 549.944910
0.044383, 551.969310
0.044728, 552.453870
0.045072, 552.764331
0.045434, 554.279620
0.045772, 554.541735
0.046118, 556.112075
0.046460, 556.766074
0.046810, 557.700034
0.047162, 559.216686
0.047494, 558.387186
0.047858, 560.556435
0.048187, 561.149206
0.048524, 561.942826
0.048882, 563.073315
0.049225, 563.933581
0.049573, 564.572349
0.049894, 564.736673
0.050277, 566.568181
0.050617, 567.468495
0.050959, 567.915546
0.051310, 570.361346
0.051675, 569.363354
0.052018, 570.566969
0.052356, 571.238434
0.052703, 572.130072
0.053047, 573.257606
0.053367, 572.918236
0.053746, 575.292578
0.054060, 575.300913
0.054439, 576.364756
0.054781, 577.191869
0.055129, 578.014284
0.055478, 578.563445
0.055817, 579.681544
0.056157, 579.942257
0.056504, 582.116016
0.056849, 581.693328
0.057204, 582.318266
0.057538, 583.536506
0.057882, 584.160080
0.058220, 586.168908
0.058586, 585.463267
0.058938, 587.066495
0.059271, 586.601940
0.059649, 589.227560
0.059997, 589.195127
0.060343, 589.604175
0.060697, 590.792104
0.061011, 590.501421
0.061392, 592.008980
0.061721, 593.134695
0.062060, 593.484295
0.062420, 594.215815
0.062733, 594.458417
0.063108, 595.386163
0.063448, 596.664456
0.063787, 596.850225
0.064141, 598.260637
0.064472, 598.345319
0.064865, 599.508999
0.065194, 599.958095
0.065537, 600.871064
0.065882, 601.794415
0.066226, 602.261736
0.066573, 603.286440
0.066889, 603.002728
0.067274, 604.185958
0.067614, 605.036714
0.067958, 605.719547
0.068307, 606.272800
0.068646, 607.052287
0.068984, 607.801841
0.069296, 607.937029
0.069680, 609.388323
0.070014, 609.997007
0.070365, 610.324177
0.070713, 611.666010
0.071033, 611.184594
0.071413, 613.119956
0.071758, 613.406320
0.072102, 613.713560
0.072457, 614.944228
0.072808, 615.610389
0.073134, 615.382450
0.073511, 617.144394
0.073847, 617.419884
0.074190, 617.746372
0.074542, 618.852347
0.074882, 619.439207
0.075235, 619.932899
0.075585, 622.183344
0.075937, 621.036487
0.076282, 623.144470
0.076629, 622.244989
0.076976, 623.911795
0.077311, 624.180654
0.077651, 624.158148
0.078003, 625.847156
0.078348, 626.087144
0.078696, 626.458493
0.079043, 627.414466
0.079374, 627.608495
0.079731, 628.556966
0.080054, 628.985564
0.080432, 629.717311
0.080773, 630.982154
0.081104, 631.053423
0.081455, 632.197401
0.081785, 631.884515
0.082146, 633.707119
0.082501, 634.074300
0.082848, 634.127496
0.083199, 635.405752
0.083520, 635.459705
0.083903, 636.333801
0.084240, 637.342136
0.084570, 637.058879
0.084922, 638.047361
0.085236, 638.515364
0.085606, 639.535900
0.085950, 640.014246
0.086292, 640.959345
0.086631, 641.097867
0.086979, 641.945933
0.087333, 642.582124
0.087666, 643.679271
0.088040, 643.183534
0.088377, 645.373963
0.088722, 644.658546
0.089070, 645.667677
0.089412, 646.721934
0.089762, 646.680180
0.090106, 647.372826
0.090442, 647.665063
0.090795, 649.297996
0.091151, 648.380518
0.091494, 650.521009
0.091839, 650.303755
0.092180, 650.955708
0.092521, 651.400599
0.092866, 651.852461
0.093181, 651.984011
0.093566, 653.275793
0.093882, 653.635888
0.094258, 654.445156
0.094583, 654.895237
0.094922, 655.339105
0.095266, 656.018679
0.095618, 657.652029
0.095967, 657.006517
0.096320, 657.714697
0.096658, 658.613685
0.096991, 658.872466
0.097342, 659.914636
0.097663, 660.274808
0.098041, 660.874588
0.098399, 661.665745
0.098742, 662.134846
0.099079, 661.959800
0.099414, 664.297958
0.099768, 663.463077
0.100114, 663.868753
0.100458, 665.025196
0.100781, 664.289016
0.101138, 666.348274
0.101470, 666.117986
0.101818, 666.389346
0.102159, 667.914636
0.102489, 667.020346
0.102859, 668.756072
0.103198, 669.262835
0.103532, 669.305498
0.103869, 669.677604
0.104208, 671.217065
0.104549, 670.696889
0.104901, 673.189861
0.105248, 671.826242
0.105598, 673.063540
0.105937, 673.646838
0.106260, 673.329860
0.106631, 675.330353
0.106956, 674.980487
0.107294, 675.501686
0.107638, 676.212177
0.107957, 675.912894
0.108322, 677.832039
0.108612, 677.782783
0.108955, 677.813549
0.109288, 679.125601
0.109627, 679.247338
0.109968, 679.813663
0.110308, 680.710113
0.110634, 679.876786
0.111004, 682.553897
0.111326, 680.867010
0.111701, 682.804607
0.112035, 683.168226
0.112371, 683.758686
0.112710, 684.004319
0.113055, 684.922745
0.113403, 685.056985
0.113727, 685.204562
0.114112, 686.164362
0.114419, 686.262267
0.114782, 687.451749
0.115114, 687.717993
0.115449, 688.101997
0.115787, 688.295684
0.116103, 689.461941
0.116468, 689.383852
0.116783, 690.452961
0.117156, 690.559088
0.117495, 691.475012
0.117841, 691.904520
0.118178, 692.229531
0.118529, 693.008449
0.118868, 693.143674
0.119187, 693.837267
0.119557, 694.098966
0.119881, 695.755617
0.120239, 694.723298
0.120576, 695.795362
0.120917, 696.336453
0.121255, 696.708673
0.121588, 697.116584
0.121945, 698.332134
0.122268, 699.104043
0.122617, 698.462812
0.122960, 699.182207
0.123297, 699.862653
0.123642, 699.993559
0.123984, 700.605842
0.124308, 700.607623
0.124672, 702.162392
0.125010, 702.502216
0.125358, 702.489978
0.125685, 704.206380
0.126046, 703.168226
0.126398, 704.168037
0.126746, 705.171068
0.127085, 705.028455
0.127423, 705.238927
0.127752, 706.138143
0.128093, 706.057818
0.128450, 708.114349
0.128788, 706.624976
0.129160, 708.124237
0.129491, 708.545561
0.129826, 708.660023
0.130159, 709.143258
0.130496, 709.772402
0.130831, 710.130792
0.131184, 711.928693
0.131521, 710.950593
0.131863, 711.547948
0.132185, 711.947979
0.132519, 712.431971
0.132875, 714.329140
0.133214, 713.803205
0.133553, 714.271928
0.133887, 714.958360
0.134196, 713.663282
0.134567, 715.999432
0.134895, 715.768689
0.135231, 716.408214
0.135578, 717.177623
0.135900, 717.950934
0.136267, 717.573144
0.136607, 718.053044
0.136949, 718.984882
0.137280, 719.196226
0.137615, 719.964574
0.137951, 720.089797
0.138287, 721.883833
0.138640, 720.664040
0.138978, 721.702383
0.139318, 721.993862
0.139648, 722.784109
0.139989, 722.442087
0.140340, 724.344220
0.140689, 723.929527
0.141031, 724.356799
0.141371, 725.330959
0.141696, 724.653999
0.142068, 726.229720
0.142412, 725.945554
0.142746, 726.396204
0.143085, 727.010723
0.143424, 727.467700
0.143760, 727.853294
0.144095, 728.231311
0.144415, 727.924715
0.144790, 729.672716
0.145109, 729.186678
0.145481, 730.282840
0.145816, 730.697647
0.146149, 731.151328
0.146493, 731.147577
0.146832, 732.008222
0.147164, 731.313720
0.147526, 733.343803
0.147850, 732.984958
0.148185, 733.093358
0.148526, 733.953207
0.148870, 734.768158
0.149224, 735.082522
0.149568, 735.650135
0.149903, 735.109234
0.150275, 737.099004
0.150617, 736.886030
0.150950, 736.914220
0.151296, 737.414618
0.151611, 737.601637
0.151979, 737.919979
0.152316, 738.633804
0.152659, 739.438412
0.152996, 739.780662
0.153333, 740.095328
0.153674, 740.390596
0.153992, 740.552874
0.154366, 740.992877
0.154705, 741.563142
0.155052, 742.632478
0.155397, 742.535672
0.155715, 742.766870
0.156091, 742.933505
0.156432, 743.891524
0.156757, 743.963627
0.157105, 745.108476
0.157440, 744.902853
0.157792, 745.600917
0.158119, 747.113363
0.158480, 746.048005
0.158809, 746.523017
0.159144, 747.328610
0.159486, 747.639071
0.159820, 748.961164
0.160166, 748.204638
0.160495, 748.693441
0.160834, 749.463418
0.161164, 749.636419
0.161491, 749.385178
0.161865, 751.676960
0.162188, 750.355966
0.162546, 751.796461
0.162888, 751.691585
0.163231, 752.108097
0.163567, 752.286591
0.163898, 752.746258
0.164266, 753.869094
0.164609, 753.986095
0.164948, 753.871178
0.165296, 754.890160
0.165632, 755.040541
0.165978, 755.265601
0.166310, 756.876445
0.166649, 755.820521
0.166988, 757.024969
0.167332, 756.826507
0.167682, 757.501459
0.168018, 757.695639
0.168354, 757.408025
0.168725, 759.905998
0.169057, 758.983518
0.169410, 759.436820
0.169757, 759.914295
0.170058, 759.976964
0.170440, 760.785208
0.170783, 761.255484
0.171123, 761.188535
0.171470, 761.732429
0.171789, 761.970939
0.172166, 762.516197
0.172501, 762.958209
0.172840, 763.716440
0.173173, 763.554806
0.173520, 764.266472
0.173839, 764.142007
0.174213, 764.966393
0.174548, 765.184973
0.174883, 765.191945
0.175228, 766.045694
0.175566, 766.352821
0.175899, 766.227522
0.176266, 768.003031
0.176605, 767.559239
0.176947, 767.795779
0.177291, 768.399841
0.177630, 768.887129
0.177967, 769.363051
0.178305, 769.487288
0.178635, 770.427689
0.178994, 769.463380
0.179353, 771.596863
0.179701, 770.899822
0.180041, 770.857197
0.180390, 771.790285
0.180734, 772.221725
0.181086, 772.407987
0.181403, 773.434168
0.181771, 772.896829
0.182115, 773.683098
0.182455, 773.914523
0.182801, 774.340090
0.183114, 773.817868
0.183482, 774.956693
0.183826, 775.653052
0.184166, 775.910999
0.184514, 776.349752
0.184855, 776.055242
0.185208, 777.039101
0.185541, 778.609252
0.185890, 777.519001
0.186240, 778.075929
0.186579, 778.439359
0.186926, 778.672299
0.187261, 779.139317
0.187593, 778.526238
0.187961, 780.661463
0.188297, 780.181109
0.188638, 780.164324
0.188985, 780.975372
0.189306, 780.967832
0.189682, 781.707460
0.190017, 782.268935
0.190356, 782.452090
0.190709, 783.005039
0.191018, 782.894631
0.191390, 783.140833
0.191737, 784.020990
0.192075, 784.270375
0.192415, 784.465237
0.192760, 785.293601
0.193099, 785.394991
0.193412, 785.647785
0.193781, 785.864510
0.194121, 786.551396
0.194467, 786.963437
0.194821, 787.334407
0.195143, 787.091615
0.195537, 787.884628
0.195872, 788.855757
0.196220, 787.746903
0.196567, 789.049559
0.196906, 789.412837
0.197246, 789.128140
0.197592, 790.982836
0.197950, 790.079870
0.198295, 790.416588
0.198633, 791.201228
0.198973, 790.974198
0.199314, 791.802410
0.199665, 792.113288
0.199986, 792.022695
0.200381, 792.739287
0.200717, 794.365324
0.201057, 793.034668
0.201395, 793.616717
0.201738, 793.925283
0.202077, 794.178987
0.202436, 795.068996
0.202769, 793.958588
0.203152, 796.472436
0.203495, 795.741371
0.203833, 795.922972
0.204182, 796.679991
0.204525, 796.738756
0.204885, 797.238586
0.205215, 798.229531
0.205576, 797.441784
0.205921, 799.170310
0.206264, 798.097526
0.206611, 798.847649
0.206958, 799.191831
0.207310, 799.458985
0.207657, 799.644451
0.207986, 799.280946
0.208355, 800.790740
0.208697, 800.727314
0.209046, 800.863676
0.209402, 801.466715
0.209746, 801.640624
0.210090, 802.102110
0.210444, 803.190505
0.210790, 802.268594
0.211144, 804.041337
0.211497, 803.247073
0.211851, 803.493540
0.212191, 804.041905
0.212540, 804.515667
0.212890, 804.432274
0.213219, 806.150570
0.213574, 804.930209
0.213929, 805.826090
0.214275, 806.236805
0.214615, 805.812678
0.214971, 807.878377
0.215325, 807.049937
0.215679, 807.388702
0.216033, 808.236692
0.216380, 808.361459
0.216735, 808.430796
0.217062, 808.231804
0.217443, 808.899216
0.217785, 809.885614
0.218139, 809.365589
0.218498, 810.276929
0.218826, 811.119653
0.219185, 810.153488
0.219536, 810.955594
0.219874, 811.031448
0.220226, 811.221839
0.220572, 811.669496
0.220904, 811.298716
0.221272, 813.158337
0.221615, 813.005267
0.221974, 812.969386
0.222331, 813.961770
0.222675, 813.488501
0.223034, 813.946008
0.223374, 815.513432
0.223730, 814.332816
0.224078, 814.734778
0.224430, 815.128254
0.224783, 815.954306
0.225141, 815.900807
0.225476, 816.960520
0.225849, 816.024097
0.226203, 816.994923
0.226542, 816.739022
0.226896, 817.323343
0.227247, 819.110105
0.227605, 816.957261
0.227975, 819.782632
0.228326, 818.061797
0.228684, 818.977229
0.229028, 819.525253
0.229373, 819.199144
0.229736, 820.888758
0.230092, 819.989846
0.230452, 820.103361
0.230806, 820.965256
0.231157, 820.537226
0.231515, 822.457962
0.231866, 821.069450
0.232223, 821.496609
0.232573, 822.502595
0.232916, 821.922176
0.233283, 823.853635
0.233628, 822.858372
0.233981, 823.124427
0.234333, 823.812981
0.234670, 823.463191
0.235051, 825.363278
0.235400, 824.340128
0.235748, 824.251089
0.236087, 825.843671
0.236464, 825.252491
0.236817, 825.732808
0.237166, 826.071383
0.237518, 825.886902
0.237873, 827.639753
0.238228, 826.559201
0.238595, 827.216345
0.238951, 827.524192
0.239305, 827.806881
0.239665, 828.109764
0.239994, 828.456219
0.240383, 828.452885
0.240740, 829.368961
0.241092, 829.296291
0.241453, 829.551586
0.241815, 830.210056
0.242153, 829.237904
0.242530, 830.569810
0.242877, 830.812602
0.243253, 830.979388
0.243586, 831.717198
0.243982, 831.984200
0.244338, 831.932823
0.244685, 832.101125
0.245037, 832.538173
0.245368, 832.201985
0.245756, 833.562649
0.246104, 833.195734
0.246461, 833.198045
0.246819, 833.722616
0.247166, 834.158148
0.247526, 834.422839
0.247882, 835.677149
0.248251, 835.030690
0.248612, 835.028530
0.248981, 835.935059
0.249311, 834.714697
0.249693, 836.357330
0.250046, 836.470845
0.250405, 836.198878
0.250768, 836.759671
0.251105, 836.279165
0.251494, 838.138370
0.251850, 837.775243
0.252208, 837.787557
0.252541, 837.377486
0.252921, 838.819043
0.253278, 839.187663
0.253634, 838.944569
0.253994, 838.919676
0.254363, 839.911681
0.254705, 839.432956
0.255110, 840.092562
0.255472, 840.438487
0.255838, 840.671617
0.256205, 840.963551
0.256566, 841.212177
0.256934, 841.824613
0.257276, 842.537415
0.257653, 841.484068
0.258028, 842.439965
0.258361, 842.241238
0.258756, 842.973932
0.259115, 842.959383
0.259466, 843.696207
0.259829, 843.402796
0.260183, 843.824726
0.260548, 844.261509
0.260909, 845.550222
0.261276, 843.912515
0.261648, 845.450650
0.262006, 845.016595
0.262370, 844.940174
0.262739, 845.711477
0.263093, 845.917743
0.263454, 845.104611
0.263827, 846.938203
0.264180, 846.313265
0.264552, 846.788808
0.264916, 847.100292
0.265262, 846.327473
0.265655, 847.839844
0.266008, 848.041412
0.266366, 847.703596
0.266742, 848.729284
0.267070, 847.885121
0.267472, 849.034024
0.267847, 849.429167
0.268213, 849.419505
0.268581, 849.635850
0.268939, 849.829387
0.269304, 849.479066
0.269671, 851.102224
0.270038, 850.612700
0.270403, 850.896791
0.270770, 851.683401
0.271128, 851.097109
0.271503, 852.350775
0.271871, 851.584852
0.272247, 852.243095
0.272619, 852.684651
0.272989, 852.562839
0.273372, 853.213769
0.273711, 852.570985
0.274111, 853.757019
0.274449, 852.663206
0.274852, 854.551055
0.275222, 854.418747
0.275587, 854.242261
0.275960, 854.717690
0.276301, 854.368204
0.276719, 855.218846
0.277085, 855.744705
0.277451, 855.385860
0.277835, 855.925776
0.278172, 856.211799
0.278558, 856.267230
0.278925, 856.995340
0.279296, 857.076157
0.279663, 856.661046
0.280027, 858.383511
0.280397, 856.863600
0.280774, 857.696700
0.281139, 858.068351
0.281517, 858.444209
0.281865, 858.297389
0.282266, 858.274088
0.282640, 859.023188
0.282998, 859.172622
0.283380, 859.300837
0.283750, 859.858447
0.284097, 858.707347
0.284504, 860.129504
0.284874, 860.541621
0.285238, 860.201682
0.285614, 861.048687
0.285991, 860.797901
0.286354, 862.059789
0.286739, 861.054560
0.287126, 861.708408
0.287501, 862.156860
0.287869, 861.623688
0.288252, 863.292047
0.288624, 862.509036
0.289017, 862.718410
0.289398, 863.155875
0.289747, 862.406396
0.290159, 864.081954
0.290535, 863.931649
0.290906, 863.504793
0.291285, 863.811086
0.291666, 864.552533
0.292021, 863.271473
0.292428, 865.433145
0.292780, 864.676695
0.293160, 865.035312
0.293540, 865.631455
0.293918, 865.621756
0.294299, 865.613193
0.294680, 867.043193
0.295045, 865.283749
0.295445, 867.194445
0.295824, 866.894669
0.296207, 867.093282
0.296587, 867.317167
0.296958, 867.683022
0.297329, 867.141250
0.297711, 869.112075
0.298093, 867.850718
0.298476, 868.189861
0.298859, 869.012806
0.299232, 867.760126
0.299631, 869.497405
0.300025, 869.440268
0.300397, 868.646232
0.300783, 869.658356
0.301159, 869.931611
0.301535, 870.055052
0.301894, 870.149926
0.302316, 870.572273
0.302676, 871.419202
0.303085, 870.940363
0.303480, 871.297768
0.303860, 871.434471
0.304235, 871.046300
0.304622, 871.913310
0.304966, 871.439548
0.305393, 872.425264
0.305778, 872.817414
0.306161, 872.769825
0.306553, 872.365476
0.306944, 874.220399
0.307319, 872.651915
0.307699, 873.156405
0.308084, 873.576820
0.308472, 873.789793
0.308856, 874.040048
0.309252, 874.395105
0.309640, 874.501080
0.309996, 873.547645
0.310371, 875.010344
0.310718, 874.974690
0.311129, 875.096806
0.311523, 875.760353
0.311908, 875.669193
0.312292, 875.180995
0.312498, 844.979085
0.312610, 859.691509
0.312736, 871.803205
0.312923, 878.820483
0.313172, 881.163983
0.313455, 880.908802
0.313748, 880.369795
0.314050, 880.626568
0.314338, 879.257606
0.314678, 879.949911
0.314995, 879.865305
0.315308, 879.315993
0.315626, 879.223923
0.315918, 879.447278
0.316268, 879.364263
0.316581, 879.320956
0.316901, 879.789149
0.317218, 879.032130
0.317551, 881.026484
0.317870, 879.645967
0.318189, 879.980677
0.318506, 881.055318
0.318845, 880.089986
0.319164, 880.851324
0.319479, 880.449854
0.319800, 880.827795
0.320120, 881.488690
0.320426, 880.496912
0.320761, 882.140492
0.321074, 881.939492
0.321384, 881.207328
0.321708, 882.600690
0.321999, 881.851741
0.322333, 881.812602
0.322649, 882.722351
0.322961, 882.453529
0.323285, 883.184443
0.323595, 882.758686
0.323912, 884.147653
0.324241, 883.203084
0.324563, 883.547039
0.324879, 884.270337
0.325187, 882.761528
0.325522, 884.762058
0.325835, 884.014057
0.326150, 883.851779
0.326468, 884.686091
0.326766, 883.759557
0.327115, 885.879286
0.327423, 885.377979
0.327750, 884.982533
0.328070, 885.743871
0.328362, 884.538969
0.328706, 885.746675
0.329029, 886.459819
0.329345, 886.320615
0.329673, 886.496836
0.329997, 887.057515
0.330297, 886.267950
0.330645, 887.074489
0.330970, 887.649983
0.331294, 887.521388
0.331615, 886.817186
0.331942, 887.968401
0.332249, 886.949494
0.332587, 888.354943
0.332887, 887.533134
0.333233, 888.104801
0.333555, 888.498996
0.333873, 888.800705
0.334203, 888.997045
0.334537, 889.269427
0.334841, 888.374910
0.335189, 890.032547
0.335516, 889.830978
0.335844, 889.406850
0.336170, 890.150419
0.336485, 889.406775
0.336812, 891.333346
0.337142, 889.917630
0.337466, 890.115637
0.337786, 890.532187
0.338102, 890.708559
0.338441, 890.848710
0.338769, 891.716440
0.339100, 891.063615
0.339426, 891.105142
0.339752, 891.675596
0.340073, 891.661615
0.340402, 891.585079
0.340738, 893.118554
0.341067, 891.911075
0.341407, 892.446255
0.341735, 892.486152
0.342062, 892.207290
0.342393, 893.741863
0.342730, 892.708597
0.343075, 893.049142
0.343403, 893.443489
0.343728, 892.641193
0.344073, 894.135490
0.344409, 893.414049
0.344735, 893.221195
0.345068, 894.013110
0.345386, 892.832607
0.345742, 895.130224
0.346076, 894.575645
0.346406, 894.377032
0.346741, 894.597128
0.347077, 894.793127
0.347420, 895.326753
0.347716, 894.829273
0.348075, 894.699542
0.348408, 896.209449
0.348742, 895.028189
0.349082, 895.622627
0.349413, 895.729398
0.349752, 896.038722
0.350085, 896.260599
0.350425, 896.266359
0.350763, 896.255484
0.351103, 896.363316
0.351437, 896.048005
0.351794, 898.064373
0.352112, 895.923313
0.352478, 897.140113
0.352813, 897.375744
0.353149, 897.544955
0.353492, 897.700602
0.353831, 897.662410
0.354168, 897.966393
0.354503, 897.498920
0.354847, 898.318001
0.355192, 898.316296
0.355512, 898.399841
0.355889, 898.410488
0.356239, 899.180389
0.356558, 898.095745
0.356928, 899.481946
0.357271, 899.236426
0.357616, 899.321070
0.357955, 899.206608
0.358294, 899.388361
0.358638, 899.665479
0.358959, 898.871443
0.359327, 900.402038
0.359645, 899.429697
0.360023, 900.148486
0.360369, 900.537302
0.360712, 900.246694
0.361058, 900.498314
0.361396, 900.269124
0.361757, 901.254461
0.362083, 900.251658
0.362462, 901.172508
0.362812, 901.459857
0.363152, 901.033039
0.363504, 901.559201
0.363848, 901.416285
0.364201, 901.305270
0.364533, 902.123669
0.364904, 901.827530
0.365268, 902.254120
0.365612, 902.063274
0.365962, 902.088357
0.366323, 902.667525
0.366649, 902.094798
0.367036, 902.694161
0.367388, 902.931990
0.367736, 902.680105
0.368090, 902.509718
0.368451, 903.962983
0.368807, 903.054901
0.369174, 903.283712
0.369534, 903.545902
0.369887, 903.467397
0.370250, 903.733717
0.370570, 903.839995
0.370960, 903.549161
0.371332, 904.216497
0.371691, 904.199712
0.372050, 904.159171
0.372397, 904.247604
0.372756, 904.097450
0.373104, 905.659228
0.373485, 904.526049
0.373850, 904.756072
0.374201, 904.568825
0.374576, 905.061456
0.374909, 904.216800
0.375305, 905.462016
0.375664, 905.235972
0.376026, 905.130716
0.376393, 905.371689
0.376752, 905.706475
0.377113, 906.999129
0.377490, 905.163074
0.377836, 905.961240
0.378229, 905.898950
0.378601, 906.212177
0.378963, 906.368014
0.379327, 906.214868
0.379696, 906.497253
0.380054, 905.739628
0.380433, 907.358315
0.380799, 907.010723
0.381175, 906.573902
0.381558, 907.048839
0.381908, 907.631380
0.382295, 906.842004
0.382668, 907.470807
0.383042, 907.152465
0.383417, 907.602016
0.383760, 906.836093
0.384165, 907.862805
0.384540, 907.796916
0.384909, 907.738908
0.385289, 907.823211
0.385658, 907.867957
0.386046, 908.543743
0.386404, 908.983026
0.386797, 908.047361
0.387173, 908.545675
0.387539, 908.586368
0.387919, 908.790551
0.388296, 908.953814
0.388675, 908.616110
0.389034, 909.365248
0.389443, 909.241011
0.389829, 909.098625
0.390218, 909.592278
0.390584, 908.818209
0.390991, 909.666730
0.391369, 909.762134
0.391752, 909.405145
0.392137, 909.815860
0.392520, 909.621377
0.392910, 910.016520
0.393279, 910.594211
0.393684, 909.481870
0.394076, 910.118062
0.394462, 910.355094
0.394837, 909.429129
0.395244, 910.783579
0.395633, 910.576138
0.396028, 910.183723
0.396425, 910.924450
0.396793, 909.905846
0.397219, 910.866366
0.397610, 910.958663
0.397997, 910.605236
0.398396, 911.468761
0.398765, 911.314212
0.399191, 910.890804
0.399581, 910.783920
0.399964, 911.271473
0.400356, 910.882507
0.400739, 912.636343
0.401157, 911.396658
0.401558, 911.645474
0.401953, 911.514114
0.402347, 911.463494
0.402749, 911.999394
0.403129, 910.816656
0.403575, 912.077558
0.403983, 911.996514
0.404388, 912.321600
0.404801, 912.201569
0.405212, 912.324480
0.405588, 911.186224
0.406023, 912.919827
0.406429, 912.691623
0.406820, 911.655439
0.407227, 913.442163
0.407640, 912.145720
0.408053, 912.332285
0.408472, 912.853181
0.408851, 912.362596
0.409291, 912.676164
0.409702, 912.989088
0.410114, 913.085023
0.410536, 913.022771
0.410947, 913.106468
0.411349, 912.182548
0.411784, 914.046224
0.412209, 913.004054
0.412625, 913.015307
0.413040, 913.407798
0.413431, 912.728261
0.413886, 913.792824
0.414300, 913.525329
0.414723, 913.110257
0.415149, 913.830864
0.415544, 913.351267
0.415999, 914.089493
0.416409, 913.801652
0.416833, 913.948850
0.417264, 913.936271
0.417688, 913.913083
0.418088, 912.964763
0.418550, 914.813397
0.418978, 913.974349
0.419415, 914.193422
0.419845, 914.348501
0.420283, 914.303376
0.420712, 914.489941
0.421145, 914.268746
0.421551, 914.369378
0.422029, 914.589550
0.422450, 915.261547
0.422902, 914.235820
0.423346, 914.590649
0.423788, 914.508658
0.424232, 914.706892
0.424678, 914.759520
0.425131, 914.761982
0.425583, 915.035388
0.426006, 914.465426
0.426490, 914.925132
0.426931, 914.686546
0.427382, 915.036790
0.427825, 914.171447
0.428284, 915.747888
0.428729, 914.925586
0.429185, 914.797333
0.429635, 915.476755
0.430052, 914.632327
0.430546, 915.503012
0.430995, 915.093282
0.431443, 915.087144
0.431899, 915.037093
0.432352, 915.487857
0.432812, 914.655249
0.433283, 916.686015
0.433743, 915.004547
0.434198, 915.035767
0.434659, 915.401470
0.435116, 915.201606
0.435584, 915.049445
0.436047, 915.794491
0.436517, 915.337324
0.436992, 915.454552
0.437451, 915.732656
0.437918, 914.883113
0.438404, 916.180199
0.438881, 915.319706
0.439362, 915.142197
0.439822, 916.092752
0.440325, 915.180086
0.440817, 915.546092
0.441307, 915.658925
0.441787, 915.282423
0.442275, 915.840677
0.442739, 914.535369
0.443240, 916.418710
0.443730, 915.698973
0.444221, 915.116963
0.444713, 915.645323
0.445181, 915.026598
0.445726, 915.959004
0.446227, 915.829879
0.446720, 915.686243
0.447222, 915.429697
0.447714, 915.553632
0.448218, 915.261395
0.448713, 916.552722
0.449197, 914.645626
0.449716, 916.247604
0.450207, 915.889819
0.450712, 915.451370
0.451224, 915.692759
0.451720, 915.624976
0.452209, 914.835525
0.452739, 916.355738
0.453246, 915.818550
0.453769, 915.355662
0.454289, 915.646005
0.454788, 915.019930
0.455309, 916.681506
0.455828, 915.331982
0.456363, 915.705566
0.456878, 915.718713
0.457388, 914.740878
0.457944, 916.314894
0.458485, 915.573182
0.459005, 915.480885
0.459536, 915.341606
0.460068, 915.970863
0.460614, 915.441367
0.461168, 915.709393
0.461680, 915.601372
0.462254, 915.120865
0.462777, 916.275149
0.463347, 914.888001
0.463890, 915.002842
0.464431, 915.384685
0.464988, 915.188421
0.465535, 915.509377
0.466070, 914.310044
0.466633, 915.969083
0.467208, 915.376918
0.467779, 914.848558
0.468329, 915.208502
0.468874, 913.729284
0.469457, 915.278483
0.470030, 915.326602
0.470598, 914.573637
0.471178, 914.521691
0.471743, 914.791952
0.472280, 913.560490
0.472892, 914.837684
0.473455, 914.503315
0.474032, 914.428295
0.474620, 914.225022
0.475160, 913.703747
0.475797, 914.276967
0.476397, 914.250824
0.476986, 914.046755
0.477584, 913.883189
0.478159, 914.648657
0.478777, 913.480317
0.479385, 913.445118
0.479984, 913.433713
0.480583, 913.449324
0.481184, 913.174554
0.481759, 914.791195
0.482396, 913.315311
0.483016, 912.856780
0.483632, 913.106013
0.484230, 912.113970
0.484853, 913.596522
0.485472, 912.546509
0.486106, 912.442883
0.486735, 912.489751
0.487348, 911.821051
0.487990, 913.409199
0.488629, 912.087826
0.489281, 911.494260
0.489921, 912.042322
0.490535, 910.753609
0.491191, 911.957906
0.491821, 911.536392
0.492453, 910.844921
0.493096, 911.006820
0.493742, 910.974842
0.494355, 910.013488
0.495045, 911.330504
0.495693, 910.524836
0.496343, 909.502520
0.497012, 910.892926
0.497672, 909.469215
0.498318, 909.426363
0.498972, 909.836434
0.499645, 909.521843
0.500306, 909.172394
0.500924, 908.610503
0.501653, 908.860342
0.502312, 908.861895
0.502962, 908.191869
0.503648, 908.542568
0.504279, 907.782442
0.505013, 907.650854
0.505693, 907.456901
0.506366, 907.329747
0.507062, 907.061077
0.507731, 906.976168
0.508389, 905.897018
0.509092, 906.804797
0.509772, 906.244610
0.510467, 905.662410
0.511152, 905.906036
0.511822, 905.155572
0.512515, 905.153753
0.513169, 905.063843
0.513908, 904.136589
0.514615, 904.457470
0.515296, 903.278824
0.515990, 903.029212
0.516657, 904.173455
0.517396, 902.517524
0.518109, 902.943887
0.518797, 901.997727
0.519516, 901.753154
0.520176, 902.374228
0.520926, 901.156822
0.521633, 900.744781
0.522337, 900.905808
0.523033, 899.247907
0.523727, 900.731558
0.524444, 899.140302
0.525135, 898.945592
0.525838, 898.759557
0.526554, 898.434623
0.527281, 898.027318
0.527946, 898.117872
0.528707, 896.319858
0.529419, 897.323987
0.530148, 896.168378
0.530870, 895.451824
0.531557, 895.158262
0.532271, 894.720343
0.532974, 894.406471
0.533682, 893.760884
0.534387, 892.716970
0.535097, 894.013905
0.535814, 891.438412
0.536562, 892.475353
0.537279, 891.285606
0.537991, 890.733566
0.538701, 890.122381
0.539400, 889.894972
0.540125, 889.150078
0.540833, 888.785095
0.541544, 887.094533
0.542292, 887.917781
0.543012, 887.249195
0.543710, 886.047702
0.544440, 885.782026
0.545168, 885.257379
0.545858, 883.754253
0.546594, 885.302050
0.547325, 882.365324
0.548086, 883.226386
0.548821, 882.396317
0.549535, 881.595991
0.550261, 880.931914
0.550973, 880.506915
0.551667, 879.065131
0.552453, 879.559239
0.553161, 878.550979
0.553891, 877.616830
0.554632, 877.396469
0.555356, 876.174705
0.556082, 875.733225
0.556777, 875.852120
0.557512, 873.347251
0.558257, 874.105824
0.558988, 872.653696
0.559709, 871.470276
0.560447, 871.386049
0.561179, 870.785019
0.561906, 868.571023
0.562663, 869.512863
0.563358, 867.243057
0.564124, 867.006327
0.564858, 866.577198
0.565599, 865.013792
0.566342, 864.840753
0.567043, 864.020308
0.567826, 862.312356
0.568546, 861.702952
0.569271, 860.791611
0.570028, 859.866897
0.570764, 859.191111
0.571467, 857.797674
0.572258, 856.509302
0.572993, 856.274921
0.573724, 854.559504
0.574468, 853.731482
0.575171, 853.405752
0.575971, 851.374910
0.576715, 850.391998
0.577456, 849.126738
0.578215, 847.705035
0.578926, 847.571136
0.579733, 845.006706
0.580507, 843.592240
0.581272, 842.632781
0.582011, 839.542720
0.582817, 838.012882
0.583715, 833.309476
0.584101, 830.207328