File: Original_Data/Stress_Strain/SR_HIP_HT/18-068_RT_SR+HIP+HT.csv
Eng_Strain, Eng_Stress (MPa)
0.000027, 5.202121
0.000113, 23.817172
0.000224, 47.345713
0.000315, 66.089481
0.000402, 84.976398
0.000492, 103.909760
0.000579, 122.240974
0.000678, 142.709632
0.000765, 161.219222
0.000854, 180.183912
0.000946, 199.439154
0.001040, 218.815299
0.001127, 236.813770
0.001209, 254.359705
0.001289, 270.728771
0.001364, 286.387638
0.001440, 302.166411
0.001528, 317.225883
0.001634, 331.883062
0.001771, 345.455492
0.001942, 355.953657
0.002177, 364.257776
0.002471, 369.499762
0.002853, 375.668567
0.003232, 378.484652
0.003656, 380.321427
0.004056, 383.395280
0.004468, 385.892543
0.004864, 388.735322
0.005263, 391.361299
0.005659, 393.488880
0.006047, 396.068794
0.006442, 399.031678
0.006839, 401.223183
0.007225, 403.864565
0.007603, 406.186898
0.007991, 408.426204
0.008358, 410.373230
0.008734, 413.120030
0.009106, 415.462639
0.009461, 416.685105
0.009850, 419.896205
0.010217, 422.116028
0.010605, 423.180404
0.010960, 425.628507
0.011333, 427.656334
0.011694, 429.712177
0.012014, 431.284803
0.012371, 433.427412
0.012728, 435.210232
0.013096, 437.103304
0.013457, 439.030093
0.013824, 440.998263
0.014173, 442.629488
0.014524, 444.531810
0.014881, 446.345516
0.015238, 448.074419
0.015590, 449.853729
0.015952, 451.527544
0.016300, 453.501152
0.016651, 454.787918
0.016980, 456.173457
0.017351, 457.717425
0.017711, 460.669889
0.018065, 461.214159
0.018415, 462.697300
0.018772, 464.614612
0.019121, 466.026845
0.019470, 467.677516
0.019820, 469.012762
0.020170, 470.789390
0.020519, 472.033566
0.020857, 473.578063
0.021194, 474.876043
0.021538, 476.295337
0.021886, 477.796904
0.022247, 479.513272
0.022593, 481.053351
0.022938, 482.607400
0.023278, 483.320332
0.023612, 484.354993
0.023989, 487.218765
0.024319, 487.883141
0.024683, 488.575080
0.025025, 490.354578
0.025373, 491.590221
0.025713, 493.123693
0.026063, 494.387918
0.026411, 495.689938
0.026752, 496.617293
0.027103, 498.256485
0.027446, 499.138909
0.027794, 500.286162
0.028137, 501.549556
0.028488, 503.183764
0.028841, 504.187616
0.029186, 505.104814
0.029512, 506.507570
0.029876, 507.044742
0.030227, 509.613819
0.030578, 510.088918
0.030928, 511.331093
0.031280, 512.275363
0.031629, 513.504739
0.031977, 515.004531
0.032322, 515.958127
0.032658, 516.872343
0.033006, 518.275401
0.033358, 519.498018
0.033709, 520.666944
0.034066, 521.723617
0.034414, 522.700019
0.034753, 523.531886
0.035087, 524.535171
0.035471, 526.020162
0.035811, 528.019143
0.036160, 528.115688
0.036500, 529.007023
0.036845, 529.779762
0.037193, 530.982594
0.037544, 532.015141
0.037896, 533.039154
0.038242, 534.380706
0.038582, 534.622088
0.038923, 535.937399
0.039265, 537.133434
0.039616, 538.088767
0.039966, 539.223863
0.040315, 540.246404
0.040667, 540.930225
0.041013, 541.654672
0.041349, 542.546498
0.041727, 544.643270
0.042062, 545.804229
0.042422, 545.647725
0.042768, 546.898395
0.043122, 548.052369
0.043476, 548.875703
0.043823, 549.468492
0.044175, 550.598830
0.044526, 551.361639
0.044868, 552.773155
0.045214, 553.295337
0.045567, 554.388295
0.045908, 555.157561
0.046262, 556.165490
0.046615, 556.924599
0.046969, 558.051388
0.047313, 558.727468
0.047656, 559.478686
0.048021, 560.562469
0.048373, 562.350160
0.048734, 562.123655
0.049085, 563.277365
0.049435, 563.942382
0.049781, 565.040098
0.050131, 565.590901
0.050489, 566.712630
0.050834, 567.089598
0.051181, 568.514744
0.051527, 569.183274
0.051876, 569.754465
0.052227, 570.849386
0.052568, 571.576742
0.052922, 572.674042
0.053275, 573.277704
0.053624, 573.839985
0.053974, 575.596904
0.054317, 574.975382
0.054697, 576.445195
0.055042, 577.503228
0.055387, 578.325996
0.055735, 579.164055
0.056078, 579.640211
0.056429, 580.898282
0.056782, 581.828469
0.057130, 582.162394
0.057475, 583.193581
0.057828, 583.905796
0.058175, 584.776704
0.058537, 585.819105
0.058896, 586.622466
0.059241, 587.745177
0.059585, 586.721918
0.059964, 588.369756
0.060313, 589.292618
0.060661, 589.867774
0.061013, 590.815480
0.061358, 591.533359
0.061709, 592.452407
0.062057, 593.454068
0.062404, 593.937927
0.062752, 594.661053
0.063103, 595.432207
0.063451, 595.918331
0.063801, 596.828091
0.064159, 597.721692
0.064516, 598.383009
0.064872, 599.198339
0.065220, 599.607023
0.065591, 601.585728
0.065929, 601.835152
0.066301, 601.913649
0.066652, 602.588484
0.066995, 603.428167
0.067339, 604.163300
0.067683, 605.186785
0.068033, 605.997546
0.068385, 606.692845
0.068740, 607.157938
0.069090, 607.654521
0.069445, 608.503870
0.069796, 609.062677
0.070133, 610.072079
0.070479, 610.384746
0.070836, 611.418274
0.071188, 611.728072
0.071535, 612.572437
0.071885, 613.565943
0.072228, 613.563904
0.072601, 616.107646
0.072950, 616.339286
0.073326, 615.996979
0.073683, 616.615896
0.074042, 617.677214
0.074396, 618.558656
0.074746, 618.789617
0.075096, 619.886615
0.075439, 620.410345
0.075781, 621.111459
0.076134, 621.572664
0.076485, 622.169681
0.076834, 622.814008
0.077174, 623.258599
0.077527, 624.527959
0.077873, 624.773532
0.078227, 625.507646
0.078564, 625.355069
0.078894, 626.678724
0.079257, 627.567113
0.079602, 628.228922
0.079958, 628.882046
0.080303, 629.188182
0.080664, 629.993997
0.081013, 630.787993
0.081352, 631.135926
0.081704, 632.228016
0.082066, 633.061393
0.082420, 633.315575
0.082766, 633.833038
0.083108, 634.347291
0.083454, 634.881027
0.083797, 635.451727
0.084147, 637.407023
0.084492, 636.618010
0.084872, 637.968133
0.085225, 638.604531
0.085571, 639.121352
0.085930, 639.740155
0.086287, 640.375835
0.086643, 641.035454
0.086990, 641.185841
0.087341, 641.993846
0.087698, 642.921389
0.088050, 643.344195
0.088405, 644.230017
0.088757, 644.871135
0.089120, 645.387427
0.089465, 645.384633
0.089822, 647.240853
0.090171, 646.807816
0.090533, 647.516141
0.090879, 648.494280
0.091230, 648.935850
0.091581, 649.460638
0.091924, 650.260827
0.092271, 650.780442
0.092616, 651.470682
0.092960, 651.752766
0.093317, 652.639456
0.093669, 652.996828
0.094016, 653.607061
0.094373, 654.617066
0.094720, 654.949519
0.095071, 655.783878
0.095410, 655.635492
0.095772, 657.336115
0.096116, 657.904890
0.096487, 657.700132
0.096838, 658.408193
0.097190, 658.876270
0.097543, 659.746687
0.097897, 660.315008
0.098249, 661.071625
0.098596, 661.378629
0.098942, 661.879743
0.099294, 662.414310
0.099634, 663.101378
0.099987, 663.546800
0.100334, 663.899150
0.100686, 664.755182
0.101045, 665.358354
0.101382, 666.181763
0.101752, 665.700887
0.102121, 667.616387
0.102470, 667.502398
0.102812, 668.123617
0.103160, 668.706928
0.103517, 669.063432
0.103870, 669.719162
0.104226, 670.641344
0.104575, 671.178856
0.104928, 671.433642
0.105280, 672.083330
0.105626, 672.638626
0.105980, 673.104172
0.106323, 673.778554
0.106669, 674.569643
0.107025, 674.948763
0.107358, 674.732226
0.107737, 676.095564
0.108077, 676.948914
0.108430, 677.144874
0.108772, 677.641684
0.109120, 678.311724
0.109474, 678.778290
0.109828, 679.355635
0.110179, 679.869587
0.110523, 680.082197
0.110871, 680.804153
0.111214, 681.455088
0.111571, 681.961337
0.111929, 682.924599
0.112279, 682.950198
0.112622, 682.983160
0.112984, 684.658486
0.113311, 685.005135
0.113682, 684.985766
0.114023, 685.636776
0.114374, 686.519426
0.114713, 686.471323
0.115062, 687.296017
0.115402, 687.641004
0.115750, 688.294959
0.116100, 688.864112
0.116454, 689.235076
0.116814, 689.487257
0.117161, 690.327015
0.117508, 690.927582
0.117851, 691.355900
0.118196, 691.833679
0.118543, 692.569492
0.118895, 693.155182
0.119250, 693.688276
0.119584, 694.007589
0.119941, 693.167567
0.120312, 695.544346
0.120652, 695.356164
0.120990, 695.959184
0.121334, 696.417633
0.121679, 697.034133
0.122023, 697.502549
0.122371, 697.971569
0.122724, 698.710591
0.123072, 698.832245
0.123417, 699.413744
0.123761, 699.615556
0.124114, 700.767000
0.124463, 701.345705
0.124807, 701.029035
0.125164, 702.433038
0.125508, 702.600529
0.125853, 702.974476
0.126199, 703.516934
0.126533, 703.116519
0.126910, 705.005248
0.127252, 705.684840
0.127616, 705.329507
0.127971, 706.393808
0.128316, 706.401624
0.128653, 707.172173
0.128998, 707.516632
0.129343, 707.807249
0.129687, 708.317803
0.130032, 708.798188
0.130380, 709.377081
0.130721, 709.965830
0.131070, 710.338607
0.131420, 711.059317
0.131774, 711.565226
0.132120, 711.848178
0.132455, 711.752803
0.132818, 713.569303
0.133141, 712.603851
0.133519, 713.716179
0.133859, 714.436020
0.134209, 714.617066
0.134552, 715.115348
0.134905, 715.611365
0.135258, 716.180215
0.135608, 716.819143
0.135951, 716.791127
0.136297, 717.400415
0.136644, 717.759600
0.136982, 718.432622
0.137331, 718.875212
0.137680, 719.466075
0.138024, 719.761941
0.138357, 720.392600
0.138725, 721.083557
0.139079, 722.137587
0.139431, 721.665584
0.139779, 722.335095
0.140130, 722.590561
0.140480, 723.278799
0.140832, 723.799736
0.141185, 724.020729
0.141528, 724.331886
0.141873, 725.165867
0.142221, 725.558694
0.142575, 725.866490
0.142922, 726.233981
0.143282, 726.888956
0.143626, 727.071059
0.143967, 727.517198
0.144309, 728.048291
0.144647, 728.168133
0.144998, 730.057769
0.145339, 729.431150
0.145718, 729.811025
0.146062, 730.351218
0.146394, 730.512630
0.146742, 731.028393
0.147088, 732.026619
0.147435, 732.110968
0.147777, 732.450859
0.148117, 732.791618
0.148463, 733.452747
0.148810, 734.096772
0.149158, 734.619407
0.149502, 734.818879
0.149849, 735.474155
0.150201, 735.500208
0.150564, 736.338078
0.150909, 736.562771
0.151268, 737.043534
0.151583, 737.353898
0.151943, 737.048518
0.152314, 738.483255
0.152662, 738.859203
0.153004, 739.122145
0.153343, 739.694204
0.153689, 740.046102
0.154040, 740.735246
0.154393, 741.245044
0.154745, 741.396526
0.155097, 742.206834
0.155447, 742.359335
0.155798, 742.699453
0.156150, 742.769190
0.156498, 743.580404
0.156846, 743.420427
0.157198, 744.752275
0.157545, 745.103379
0.157882, 744.809402
0.158251, 746.421824
0.158586, 747.060412
0.158942, 746.389768
0.159290, 747.000529
0.159637, 747.202870
0.159976, 747.586785
0.160333, 748.174438
0.160681, 748.576288
0.161026, 749.086313
0.161377, 749.591165
0.161724, 749.844629
0.162064, 750.114027
0.162409, 750.672116
0.162756, 751.318180
0.163101, 751.381235
0.163458, 752.171984
0.163818, 752.780819
0.164168, 752.800151
0.164505, 754.090919
0.164865, 752.423976
0.165245, 754.451161
0.165592, 754.180215
0.165942, 754.911082
0.166284, 754.826128
0.166623, 755.465509
0.166968, 756.098886
0.167315, 756.667774
0.167665, 757.353219
0.168006, 757.534340
0.168361, 758.022466
0.168708, 758.076345
0.169052, 758.541250
0.169409, 759.278611
0.169744, 758.894695
0.170126, 760.310440
0.170476, 761.207174
0.170839, 760.589050
0.171180, 761.135209
0.171529, 761.432094
0.171881, 762.156051
0.172224, 762.255843
0.172570, 762.611780
0.172921, 762.779649
0.173255, 762.812309
0.173608, 763.476383
0.173963, 764.396111
0.174317, 764.771116
0.174662, 764.772664
0.175004, 765.259430
0.175357, 765.900585
0.175700, 766.071286
0.176038, 766.068945
0.176422, 767.762281
0.176760, 768.401057
0.177123, 767.664263
0.177467, 767.986143
0.177806, 768.170436
0.178156, 768.838210
0.178509, 769.433226
0.178860, 769.760015
0.179212, 769.835454
0.179565, 770.550047
0.179925, 770.901718
0.180275, 771.125543
0.180633, 771.510251
0.180977, 771.822126
0.181321, 772.403323
0.181668, 772.534114
0.182033, 774.351784
0.182374, 773.831678
0.182745, 773.986596
0.183104, 774.160770
0.183460, 774.526336
0.183812, 774.743364
0.184165, 775.518067
0.184497, 775.546536
0.184847, 776.446290
0.185204, 776.779536
0.185558, 777.278120
0.185915, 777.231716
0.186272, 777.532150
0.186623, 778.245800
0.186967, 778.121767
0.187318, 778.846064
0.187669, 778.928450
0.188025, 780.688805
0.188366, 779.461771
0.188743, 780.300170
0.189086, 780.437266
0.189435, 780.895148
0.189787, 781.383991
0.190140, 781.713574
0.190487, 781.864791
0.190849, 782.688692
0.191196, 782.898697
0.191550, 783.165377
0.191910, 783.941174
0.192260, 784.116141
0.192610, 784.428544
0.192953, 784.015783
0.193324, 785.797546
0.193666, 785.194148
0.194044, 785.396073
0.194402, 786.629828
0.194752, 786.704436
0.195112, 787.083632
0.195475, 787.720408
0.195841, 787.727129
0.196190, 788.022617
0.196542, 788.775194
0.196900, 788.662299
0.197253, 789.279517
0.197607, 789.531961
0.197957, 790.040438
0.198303, 790.047272
0.198657, 790.790938
0.199011, 791.058033
0.199354, 791.005135
0.199728, 792.284765
0.200077, 792.900623
0.200442, 792.120332
0.200795, 792.646253
0.201150, 793.160279
0.201503, 793.310100
0.201860, 793.675741
0.202210, 794.134869
0.202565, 794.332075
0.202915, 794.803587
0.203263, 795.049009
0.203621, 795.352086
0.203985, 795.944195
0.204335, 796.032320
0.204697, 796.811591
0.205047, 796.821106
0.205399, 797.009741
0.205758, 798.456900
0.206097, 797.449047
0.206479, 798.410006
0.206833, 798.779762
0.207189, 798.678724
0.207546, 799.209741
0.207896, 799.478346
0.208242, 800.084199
0.208586, 800.195054
0.208946, 800.965377
0.209296, 801.180933
0.209653, 801.356013
0.210003, 801.547971
0.210366, 802.075401
0.210715, 802.413215
0.211049, 800.618879
0.211380, 802.767113
0.211732, 804.282726
0.212077, 803.148763
0.212460, 804.070908
0.212824, 804.565377
0.213183, 804.869926
0.213541, 804.950160
0.213892, 805.252029
0.214239, 805.298093
0.214606, 806.191958
0.214958, 806.559713
0.215323, 806.957448
0.215685, 807.156768
0.216037, 807.168397
0.216390, 807.756466
0.216743, 808.023712
0.217099, 808.441118
0.217457, 808.852218
0.217824, 809.264301
0.218189, 809.575080
0.218545, 809.656711
0.218885, 809.916859
0.219253, 809.454635
0.219638, 811.096130
0.219995, 810.996715
0.220353, 811.020464
0.220708, 811.483708
0.221058, 812.006192
0.221415, 812.144535
0.221772, 812.536341
0.222137, 813.212309
0.222498, 813.375873
0.222859, 813.597621
0.223213, 813.607551
0.223571, 814.027601
0.223932, 814.609024
0.224294, 814.669285
0.224628, 815.020238
0.224998, 814.772060
0.225381, 816.024693
0.225742, 816.254786
0.226099, 816.502133
0.226460, 816.701378
0.226819, 817.188597
0.227179, 817.058750
0.227536, 817.596035
0.227890, 817.588975
0.228250, 818.411440
0.228607, 818.299339
0.228965, 819.142307
0.229330, 819.163338
0.229688, 819.421220
0.230048, 820.059052
0.230404, 820.121654
0.230756, 819.949821
0.231131, 821.617331
0.231486, 821.233189
0.231874, 821.377799
0.232236, 821.625977
0.232591, 821.688503
0.232953, 822.427789
0.233315, 822.536266
0.233684, 822.938305
0.234051, 823.326222
0.234414, 823.421069
0.234769, 823.541552
0.235121, 823.906060
0.235482, 824.624278
0.235847, 824.853917
0.236199, 825.132377
0.236567, 825.203813
0.236914, 826.401812
0.237270, 825.346762
0.237665, 826.458675
0.238029, 826.527091
0.238387, 826.380140
0.238757, 827.257240
0.239118, 827.335435
0.239483, 827.784142
0.239847, 828.187918
0.240201, 828.337889
0.240559, 828.518860
0.240931, 828.964131
0.241295, 829.220464
0.241662, 829.449235
0.242021, 829.711308
0.242386, 830.206796
0.242749, 830.109685
0.243126, 830.934756
0.243484, 830.727884
0.243858, 832.195545
0.244216, 831.000982
0.244606, 831.699830
0.244968, 831.852332
0.245326, 832.152652
0.245694, 832.752766
0.246071, 833.222881
0.246431, 833.391693
0.246793, 833.732226
0.247164, 833.770965
0.247531, 834.010610
0.247891, 834.333774
0.248261, 834.683255
0.248619, 834.664301
0.248984, 835.003965
0.249352, 835.599811
0.249707, 835.284576
0.250080, 837.162243
0.250437, 836.861242
0.250834, 836.797584
0.251203, 836.873249
0.251565, 837.108137
0.251924, 837.590938
0.252291, 837.723428
0.252662, 838.065924
0.253030, 838.521050
0.253393, 838.417897
0.253754, 839.171267
0.254124, 839.887030
0.254493, 839.459166
0.254866, 839.926336
0.255239, 839.975533
0.255608, 840.195205
0.255974, 840.291977
0.256345, 841.113423
0.256709, 840.839456
0.257098, 842.119879
0.257457, 842.733207
0.257842, 841.949594
0.258211, 842.173494
0.258577, 842.086540
0.258943, 842.705833
0.259319, 843.105758
0.259694, 842.853917
0.260066, 843.712894
0.260445, 843.979649
0.260810, 843.958996
0.261173, 844.324259
0.261540, 844.380442
0.261915, 844.810232
0.262277, 844.910440
0.262654, 845.499604
0.263001, 845.085747
0.263387, 846.317916
0.263753, 847.271361
0.264136, 846.565641
0.264511, 847.036058
0.264885, 847.216877
0.265253, 847.187314
0.265618, 847.376968
0.265995, 847.957636
0.266365, 847.864301
0.266742, 848.168246
0.267110, 848.487710
0.267484, 849.070908
0.267860, 849.324335
0.268225, 849.527657
0.268602, 850.116368
0.268976, 849.976024
0.269345, 849.854370
0.269701, 849.772702
0.270103, 851.095488
0.270469, 851.352841
0.270857, 851.287446
0.271241, 851.259543
0.271627, 851.715084
0.272004, 852.190145
0.272378, 852.223107
0.272755, 852.476119
0.273131, 852.569266
0.273501, 852.653238
0.273879, 853.111044
0.274259, 853.659656
0.274634, 853.697187
0.275004, 853.957787
0.275383, 854.295639
0.275751, 854.272683
0.276114, 855.286313
0.276488, 853.971456
0.276879, 855.076421
0.277260, 855.302888
0.277645, 855.820955
0.278018, 855.813593
0.278394, 856.518595
0.278772, 856.402794
0.279153, 856.934869
0.279528, 856.799018
0.279903, 857.098282
0.280276, 857.383462
0.280652, 857.575042
0.281008, 857.765528
0.281396, 858.203851
0.281780, 858.370436
0.282152, 857.903417
0.282534, 859.543893
0.282893, 859.025675
0.283290, 859.337625
0.283670, 859.614876
0.284051, 859.767189
0.284429, 859.992826
0.284822, 860.333812
0.285197, 860.334567
0.285581, 860.911157
0.285951, 860.755069
0.286337, 861.185199
0.286714, 861.297225
0.287098, 861.744346
0.287476, 861.968888
0.287859, 862.105154
0.288239, 862.314253
0.288615, 862.590636
0.288982, 862.429564
0.289391, 862.510553
0.289787, 863.854182
0.290178, 863.654975
0.290570, 863.854975
0.290948, 863.913989
0.291330, 864.118709
0.291715, 864.548046
0.292105, 864.585803
0.292486, 864.544195
0.292864, 865.069926
0.293255, 865.550311
0.293643, 865.872947
0.294032, 866.089220
0.294419, 866.245913
0.294799, 866.283821
0.295175, 866.072343
0.295545, 866.386483
0.295920, 867.464716
0.296303, 866.556843
0.296716, 867.093260
0.297097, 867.424731
0.297488, 868.041533
0.297872, 868.418803
0.298260, 868.345969
0.298643, 868.369266
0.299030, 868.906702
0.299413, 868.848065
0.299794, 868.912743
0.300178, 869.539060
0.300566, 869.827034
0.300965, 870.005210
0.301346, 870.121050
0.301734, 870.153596
0.302118, 870.468265
0.302493, 870.052332
0.302901, 871.155409
0.303278, 871.678308
0.303678, 871.237908
0.304062, 871.518595
0.304455, 871.719690
0.304853, 872.148008
0.305243, 872.455163
0.305629, 872.394903
0.306029, 872.756239
0.306422, 872.609779
0.306812, 872.899604
0.307207, 873.273778
0.307604, 873.412347
0.307999, 873.697980
0.308396, 873.934982
0.308764, 873.655503
0.309177, 874.112403
0.309574, 875.446592
0.309959, 874.316103
0.310351, 874.887181
0.310736, 875.109081
0.311135, 875.367680
0.311527, 875.604493
0.311929, 875.769832
0.312319, 875.598225
0.312709, 876.325996
0.313105, 876.172702
0.313393, 848.015405
0.313507, 862.983462
0.313637, 874.778176
0.313831, 880.675665
0.314094, 882.124184
0.314382, 881.242099
0.314684, 881.282953
0.314999, 881.082877
0.315318, 880.311459
0.315636, 880.465282
0.315952, 879.930338
0.316272, 880.156730
0.316591, 880.059543
0.316911, 880.073702
0.317235, 880.082537
0.317554, 879.746423
0.317889, 881.305003
0.318200, 880.078724
0.318553, 880.613744
0.318881, 880.807023
0.319206, 880.913196
0.319522, 880.875212
0.319844, 881.179724
0.320170, 881.568133
0.320492, 881.334151
0.320813, 881.503153
0.321152, 882.196300
0.321472, 882.265396
0.321793, 882.287672
0.322114, 882.444893
0.322438, 882.668114
0.322751, 883.445158
0.323068, 882.229753
0.323414, 883.196489
0.323737, 883.219294
0.324059, 883.311535
0.324376, 883.431792
0.324697, 883.665886
0.325016, 883.938493
0.325337, 884.230961
0.325655, 884.432509
0.325981, 884.567982
0.326307, 884.940608
0.326627, 884.958845
0.326946, 885.185766
0.327269, 885.338984
0.327602, 885.750425
0.327907, 885.554163
0.328225, 884.577270
0.328566, 886.171569
0.328890, 886.134265
0.329215, 886.164282
0.329543, 886.430206
0.329862, 886.337927
0.330179, 886.479366
0.330508, 887.172211
0.330830, 887.461658
0.331148, 887.421257
0.331476, 887.814310
0.331801, 887.614159
0.332139, 888.210232
0.332460, 887.679290
0.332777, 888.633981
0.333108, 887.344988
0.333462, 888.705267
0.333795, 888.730413
0.334113, 888.857769
0.334441, 888.811931
0.334770, 889.475628
0.335098, 889.443005
0.335424, 889.588597
0.335752, 890.004078
0.336072, 889.860638
0.336392, 889.893147
0.336715, 889.954238
0.337041, 890.534076
0.337369, 890.432962
0.337700, 890.874268
0.338033, 891.293109
0.338360, 891.016953
0.338686, 891.108476
0.339002, 891.566509
0.339340, 890.658410
0.339692, 891.507268
0.340029, 891.921578
0.340358, 892.118860
0.340693, 892.170700
0.341019, 892.412045
0.341347, 892.550538
0.341678, 892.702964
0.342013, 892.925543
0.342344, 892.716783
0.342678, 893.174136
0.343008, 893.063281
0.343345, 893.690202
0.343679, 893.745441
0.344015, 894.173608
0.344354, 894.143704
0.344680, 893.549783
0.345042, 895.062488
0.345363, 894.999660
0.345715, 894.429564
0.346063, 894.925505
0.346398, 894.666566
0.346734, 895.202416
0.347070, 895.041495
0.347402, 895.176591
0.347739, 895.633566
0.348077, 896.008646
0.348408, 895.712630
0.348741, 895.753634
0.349084, 896.251803
0.349421, 896.310855
0.349768, 896.346687
0.350112, 896.496319
0.350459, 896.903039
0.350793, 896.724561
0.351148, 898.122598
0.351478, 897.432056
0.351835, 897.022843
0.352169, 897.087597
0.352507, 897.379913
0.352844, 897.070040
0.353182, 898.059619
0.353520, 897.645648
0.353864, 898.168548
0.354205, 898.287295
0.354545, 898.266717
0.354890, 898.536379
0.355232, 898.691410
0.355569, 898.768095
0.355918, 898.967340
0.356259, 898.897527
0.356614, 899.297225
0.356959, 899.551860
0.357292, 899.630621
0.357647, 898.837191
0.358021, 900.450595
0.358375, 899.944233
0.358720, 900.035114
0.359060, 900.189541
0.359411, 900.183764
0.359762, 900.558241
0.360111, 900.527204
0.360458, 900.614348
0.360810, 900.914367
0.361159, 901.087937
0.361503, 900.898207
0.361852, 901.016877
0.362206, 901.501076
0.362560, 901.521956
0.362909, 901.436096
0.363254, 901.676874
0.363603, 901.825562
0.363951, 902.831036
0.364298, 902.027110
0.364670, 902.245762
0.365026, 902.242137
0.365382, 902.470379
0.365729, 902.494922
0.366088, 902.891826
0.366442, 902.840551
0.366796, 902.995356
0.367154, 903.446970
0.367510, 903.191807
0.367860, 903.436511
0.368215, 903.422277
0.368574, 903.602567
0.368928, 903.747782
0.369282, 903.421673
0.369635, 904.589201
0.369983, 903.663545
0.370364, 904.196942
0.370720, 904.684916
0.371088, 904.482651
0.371453, 904.641571
0.371819, 904.635643
0.372179, 904.571418
0.372537, 904.743326
0.372899, 904.873249
0.373265, 904.931735
0.373622, 905.122749
0.373983, 905.773532
0.374345, 905.587125
0.374709, 905.539475
0.375069, 905.867321
0.375428, 905.272381
0.375793, 906.496810
0.376145, 905.694544
0.376533, 906.206268
0.376893, 905.958203
0.377262, 906.604946
0.377631, 906.413555
0.378004, 906.558845
0.378376, 906.638777
0.378741, 906.915235
0.379099, 906.749330
0.379471, 907.167982
0.379849, 907.209402
0.380212, 907.186407
0.380582, 907.248216
0.380953, 907.616840
0.381327, 907.526827
0.381700, 907.365377
0.382054, 908.001359
0.382430, 907.016575
0.382828, 908.406003
0.383204, 907.838475
0.383574, 907.849537
0.383954, 908.337134
0.384317, 908.211667
0.384699, 908.454219
0.385074, 908.377610
0.385455, 908.760053
0.385836, 909.121163
0.386210, 908.955107
0.386585, 908.718142
0.386958, 908.892354
0.387344, 909.174627
0.387726, 909.290504
0.388095, 908.537247
0.388493, 910.158920
0.388868, 910.370096
0.389254, 909.576553
0.389642, 909.806834
0.390028, 909.783236
0.390406, 909.775798
0.390783, 909.721238
0.391172, 910.205286
0.391555, 910.024089
0.391941, 910.336190
0.392321, 910.190674
0.392713, 910.329092
0.393093, 910.551746
0.393489, 910.775911
0.393876, 910.784180
0.394273, 910.866793
0.394632, 910.381612
0.395037, 910.592146
0.395436, 911.633264
0.395831, 911.294884
0.396214, 911.068529
0.396602, 911.176364
0.396991, 911.533510
0.397382, 911.319653
0.397782, 911.815594
0.398183, 911.796828
0.398589, 911.724863
0.398986, 911.605324
0.399384, 912.065131
0.399775, 911.948386
0.400176, 912.366283
0.400558, 911.427752
0.400977, 913.110100
0.401371, 913.023900
0.401781, 912.134529
0.402178, 912.355824
0.402576, 912.216953
0.402977, 912.327053
0.403386, 912.654068
0.403791, 912.647272
0.404189, 912.793959
0.404583, 912.777195
0.404983, 912.834435
0.405389, 913.147631
0.405797, 912.957297
0.406183, 912.712441
0.406603, 913.147782
0.407000, 914.144648
0.407430, 913.398716
0.407845, 913.713158
0.408257, 913.562054
0.408663, 913.722900
0.409069, 913.754993
0.409482, 913.676609
0.409895, 913.650255
0.410307, 913.696810
0.410725, 913.828884
0.411137, 913.554389
0.411553, 914.006608
0.411967, 914.098697
0.412389, 914.057353
0.412809, 914.327695
0.413228, 914.297074
0.413649, 915.295148
0.414073, 913.821710
0.414525, 914.586030
0.414952, 914.485067
0.415370, 914.443761
0.415791, 914.608873
0.416213, 914.918142
0.416632, 914.654068
0.417064, 915.127355
0.417483, 914.646328
0.417907, 914.944723
0.418332, 915.031943
0.418759, 914.878497
0.419190, 915.096545
0.419626, 915.056485
0.420032, 914.432773
0.420475, 915.876043
0.420903, 916.017406
0.421358, 915.405739
0.421801, 915.482462
0.422241, 915.594261
0.422674, 915.441080
0.423118, 915.232811
0.423562, 915.444100
0.423999, 915.305154
0.424440, 915.734151
0.424882, 915.937663
0.425316, 915.424127
0.425752, 915.516519
0.426197, 915.759713
0.426644, 915.757976
0.427093, 915.878988
0.427521, 915.155409
0.427984, 916.630055
0.428424, 916.870417
0.428900, 916.434586
0.429351, 916.007438
0.429805, 916.119917
0.430256, 916.208911
0.430710, 916.103530
0.431170, 916.024618
0.431620, 915.597999
0.432069, 916.380593
0.432517, 916.402643
0.432976, 916.511120
0.433433, 916.438399
0.433887, 916.232358
0.434346, 916.624391
0.434807, 916.492467
0.435252, 915.894242
0.435725, 917.270304
0.436205, 916.597999
0.436675, 916.584859
0.437151, 916.687219
0.437619, 916.628129
0.438088, 916.733170
0.438565, 916.497753
0.439026, 916.206532
0.439506, 917.553936
0.439971, 916.161639
0.440474, 916.794223
0.440958, 916.754087
0.441441, 916.526751
0.441919, 916.691410
0.442390, 916.580933
0.442871, 916.943100
0.443352, 916.742156
0.443844, 917.230432
0.444340, 917.186558
0.444831, 916.984708
0.445324, 916.949028
0.445833, 916.900396
0.446327, 916.800415
0.446798, 916.079932
0.447325, 917.275326
0.447813, 917.697942
0.448329, 916.838626
0.448826, 916.959638
0.449322, 916.714706
0.449821, 917.043119
0.450307, 916.645120
0.450808, 916.968926
0.451317, 916.958089
0.451820, 916.732113
0.452324, 917.079403
0.452824, 916.764999
0.453338, 917.094053
0.453861, 917.007854
0.454361, 916.271814
0.454897, 917.358014
0.455387, 917.297904
0.455925, 916.867019
0.456449, 916.930640
0.456966, 916.699604
0.457487, 916.815518
0.457994, 916.631527
0.458515, 916.850330
0.459048, 916.782065
0.459592, 917.129847
0.460112, 916.549821
0.460636, 916.528224
0.461182, 916.837795
0.461721, 916.810648
0.462269, 916.753898
0.462794, 916.416877
0.463369, 916.552690
0.463901, 917.266264
0.464465, 916.632282
0.465008, 916.535662
0.465551, 916.288767
0.466094, 916.282726
0.466646, 916.283972
0.467217, 916.311648
0.467787, 916.335020
0.468361, 916.314367
0.468920, 915.991731
0.469480, 915.934491
0.470046, 916.070342
0.470606, 916.155446
0.471162, 915.638588
0.471697, 915.686728
0.472307, 915.422956
0.472872, 916.677855
0.473461, 915.486728
0.474035, 915.494620
0.474615, 915.644856
0.475182, 915.375458
0.475762, 915.655616
0.476343, 915.452671
0.476945, 915.662299
0.477527, 915.213857
0.478116, 915.281782
0.478697, 914.962469
0.479278, 914.597281
0.479878, 915.103644
0.480485, 914.732264
0.481095, 915.020162
0.481685, 914.026657
0.482323, 915.453389
0.482906, 915.324410
0.483547, 914.210572
0.484155, 914.235567
0.484776, 914.380555
0.485398, 914.041835
0.486010, 914.050104
0.486626, 913.932566
0.487253, 913.861695
0.487872, 913.684765
0.488499, 913.756768
0.489132, 913.616122
0.489768, 913.393204
0.490402, 913.171380
0.491021, 913.083670
0.491667, 913.204493
0.492322, 912.948008
0.492978, 912.991882
0.493612, 912.127355
0.494219, 912.188371
0.494866, 911.793468
0.495566, 912.441608
0.496220, 911.902435
0.496861, 911.342873
0.497520, 911.630697
0.498170, 911.324863
0.498808, 911.136228
0.499470, 911.226732
0.500134, 911.049802
0.500787, 911.057769
0.501454, 910.550274
0.502134, 910.601661
0.502816, 910.191958
0.503490, 909.865396
0.504167, 909.627412
0.504843, 909.535473
0.505481, 908.813668
0.506165, 909.134076
0.506869, 908.930829
0.507558, 908.988371
0.508250, 908.585992
0.508934, 908.396489
0.509623, 908.050783
0.510313, 907.539928
0.511001, 907.421673
0.511679, 906.977799
0.512364, 906.665320
0.513069, 906.879101
0.513770, 906.415631
0.514474, 906.295488
0.515176, 905.698093
0.515884, 905.676043
0.516588, 905.082764
0.517288, 904.974136
0.517997, 904.444969
0.518700, 904.347555
0.519390, 903.918331
0.520102, 903.796073
0.520792, 902.932603
0.521502, 903.133849
0.522247, 903.326411
0.522968, 902.065056
0.523677, 901.825184
0.524387, 901.583878
0.525095, 900.873815
0.525796, 900.502209
0.526490, 900.321880
0.527206, 900.171909
0.527923, 899.871701
0.528635, 899.275552
0.529346, 898.699604
0.530061, 898.405626
0.530777, 897.946800
0.531503, 897.684878
0.532232, 897.257127
0.532962, 896.716141
0.533683, 896.220880
0.534404, 895.754729
0.535101, 895.807551
0.535837, 895.198112
0.536598, 894.126336
0.537323, 893.717047
0.538036, 893.299641
0.538760, 893.062488
0.539482, 892.234623
0.540192, 891.857202
0.540925, 891.509798
0.541651, 890.613064
0.542386, 890.490655
0.543122, 889.785992
0.543855, 888.946800
0.544574, 888.637644
0.545298, 887.872909
0.546026, 887.688994
0.546739, 886.837757
0.547475, 886.278422
0.548247, 886.036927
0.549005, 884.900887
0.549734, 884.637606
0.550466, 883.721843
0.551204, 883.228733
0.551926, 882.187578
0.552667, 881.954049
0.553391, 881.350576
0.554112, 880.589013
0.554845, 880.137625
0.555585, 879.266566
0.556325, 878.398301
0.557063, 878.247725
0.557810, 877.030130
0.558559, 876.463847
0.559297, 875.848367
0.560043, 875.337512
0.560777, 874.023183
0.561473, 873.493336
0.562224, 872.541363
0.562962, 871.904776
0.563732, 871.023976
0.564467, 870.396413
0.565215, 869.233830
0.565968, 868.639758
0.566699, 867.797357
0.567434, 866.662148
0.568179, 865.957523
0.568906, 864.877440
0.569654, 864.537474
0.570403, 863.186558
0.571149, 862.384217
0.571903, 861.540646
0.572644, 860.126373
0.573396, 859.698509
0.574152, 858.566245
0.574910, 857.311346
0.575661, 855.769492
0.576399, 854.808080
0.577191, 853.838928
0.578024, 851.751520
0.578879, 847.801586
0.580279, 830.628129