File: Original_Data/Stress_Strain/SR/18-326_RT_SRonly.csv
Eng_Strain, Eng_Stress (MPa)
0.000035, 6.876621
0.000084, 16.784200
0.000156, 31.153020
0.000220, 43.284756
0.000281, 55.492670
0.000330, 65.333343
0.000390, 77.541033
0.000447, 88.188102
0.000502, 98.781020
0.000557, 109.994491
0.000613, 121.176894
0.000669, 132.192944
0.000729, 144.126954
0.000786, 155.264802
0.000842, 166.539384
0.000905, 178.426965
0.000958, 189.143663
0.001017, 200.516155
0.001073, 211.411493
0.001122, 222.262546
0.001182, 233.774829
0.001236, 244.700247
0.001294, 255.806917
0.001354, 267.398703
0.001410, 278.241726
0.001464, 288.751847
0.001521, 299.937544
0.001569, 309.199865
0.001626, 320.700401
0.001674, 330.578700
0.001725, 341.002443
0.001782, 351.758281
0.001834, 362.192086
0.001883, 371.635423
0.001936, 381.928127
0.001988, 391.956044
0.002038, 402.027205
0.002089, 411.818706
0.002141, 422.224013
0.002190, 432.105711
0.002234, 440.303230
0.002283, 450.036124
0.002334, 459.950611
0.002382, 469.815896
0.002437, 480.245634
0.002486, 489.416548
0.002544, 500.858765
0.002591, 509.986847
0.002645, 520.457581
0.002690, 529.777486
0.002738, 538.988121
0.002785, 547.720603
0.002843, 558.470884
0.002891, 567.546017
0.002947, 577.511204
0.002998, 587.116840
0.003042, 593.712021
0.003108, 603.934460
0.003176, 611.716293
0.003260, 620.359364
0.003360, 628.277486
0.003457, 634.050851
0.003607, 642.157011
0.003737, 647.427040
0.003905, 653.726861
0.004074, 657.754178
0.004259, 663.009968
0.004451, 666.348647
0.004663, 669.848984
0.004886, 673.110208
0.005117, 675.294012
0.005366, 677.682118
0.005617, 679.882860
0.005886, 681.465787
0.006159, 683.210897
0.006436, 684.984711
0.006719, 686.339354
0.006997, 687.413138
0.007261, 688.348984
0.007567, 690.226448
0.007828, 690.119201
0.008125, 692.617890
0.008414, 692.438957
0.008685, 694.444540
0.008996, 695.427040
0.009282, 696.526343
0.009574, 697.314809
0.009850, 697.840441
0.010142, 699.223563
0.010418, 699.935547
0.010698, 701.056547
0.010970, 701.862924
0.011255, 703.061343
0.011540, 703.873866
0.011822, 704.724312
0.012097, 705.627258
0.012390, 706.803118
0.012655, 706.600015
0.012947, 709.334220
0.013230, 708.594656
0.013498, 710.870456
0.013787, 710.585326
0.014038, 711.793450
0.014338, 712.772427
0.014602, 713.101252
0.014880, 714.398973
0.015149, 715.605786
0.015423, 716.275838
0.015693, 716.849996
0.015959, 717.870944
0.016239, 718.805778
0.016517, 719.595856
0.016788, 720.188826
0.017046, 721.087162
0.017329, 722.992206
0.017590, 722.659559
0.017869, 724.773552
0.018136, 724.242262
0.018376, 725.611407
0.018664, 726.448025
0.018922, 727.284719
0.019186, 727.988608
0.019457, 729.271153
0.019712, 729.774488
0.019971, 730.373979
0.020240, 731.736229
0.020500, 732.161021
0.020755, 732.910253
0.021022, 733.852957
0.021275, 734.948662
0.021547, 735.976879
0.021808, 736.572060
0.022045, 737.146219
0.022329, 738.401709
0.022556, 738.596605
0.022837, 740.449899
0.023089, 740.084913
0.023338, 741.619838
0.023608, 742.141760
0.023861, 743.136176
0.024115, 744.028929
0.024371, 744.687364
0.024623, 745.379487
0.024876, 746.443678
0.025128, 746.778348
0.025380, 747.679532
0.025627, 748.747733
0.025872, 749.044293
0.026080, 750.400922
0.026332, 750.879675
0.026557, 751.521472
0.026835, 753.457731
0.027067, 752.322866
0.027327, 754.990107
0.027570, 754.507045
0.027814, 755.752454
0.028057, 756.753803
0.028308, 757.418759
0.028553, 758.510417
0.028799, 758.812336
0.029041, 760.034887
0.029284, 760.313872
0.029524, 761.421832
0.029772, 761.784119
0.030009, 763.106348
0.030267, 763.828262
0.030495, 764.027655
0.030758, 766.145582
0.030990, 765.529716
0.031220, 767.156412
0.031485, 767.735629
0.031715, 768.362550
0.031954, 768.884846
0.032196, 769.917185
0.032426, 770.412576
0.032668, 771.392603
0.032900, 772.176759
0.033144, 773.181031
0.033377, 773.441093
0.033621, 774.548940
0.033861, 774.944165
0.034105, 776.221315
0.034354, 777.084089
0.034585, 777.484186
0.034836, 778.637001
0.035069, 778.654575
0.035297, 779.461178
0.035542, 780.488758
0.035775, 781.215394
0.036013, 782.031590
0.036254, 783.196995
0.036483, 783.668328
0.036735, 784.614779
0.036967, 784.923068
0.037185, 785.354231
0.037434, 786.905906
0.037652, 786.596380
0.037891, 789.020985
0.038136, 788.650004
0.038361, 789.354980
0.038597, 790.085888
0.038826, 790.637825
0.039053, 791.420220
0.039295, 792.239864
0.039530, 793.059132
0.039758, 793.829311
0.040002, 795.068463
0.040234, 795.430263
0.040458, 795.868508
0.040698, 797.054898
0.040925, 797.095668
0.041155, 798.109196
0.041413, 799.062242
0.041628, 799.103088
0.041884, 800.916511
0.042105, 800.341003
0.042341, 802.650566
0.042575, 801.683729
0.042792, 803.210972
0.043044, 803.769692
0.043268, 804.486098
0.043502, 805.310687
0.043724, 806.048902
0.043953, 806.722364
0.044180, 807.155587
0.044406, 808.389717
0.044642, 808.757026
0.044862, 809.604474
0.045105, 810.708761
0.045321, 810.088923
0.045571, 812.544068
0.045799, 811.451435
0.046032, 813.607922
0.046274, 813.335832
0.046479, 813.761410
0.046729, 814.847673
0.046941, 815.470659
0.047173, 816.167429
0.047399, 816.983137
0.047629, 817.764333
0.047858, 818.601102
0.048080, 819.058533
0.048308, 819.557858
0.048536, 820.588211
0.048759, 820.868358
0.048988, 821.763097
0.049222, 822.212846
0.049452, 822.960204
0.049688, 823.429626
0.049919, 824.245185
0.050153, 824.936971
0.050383, 825.649891
0.050627, 826.463614
0.050839, 826.596380
0.051090, 828.099903
0.051317, 827.362887
0.051544, 829.417297
0.051790, 829.585476
0.052012, 830.133591
0.052231, 830.775463
0.052458, 831.342989
0.052685, 832.148580
0.052908, 832.519186
0.053133, 832.743536
0.053368, 833.777336
0.053579, 834.011954
0.053814, 835.337555
0.054041, 835.828374
0.054254, 836.255078
0.054504, 837.887094
0.054722, 837.355018
0.054948, 838.353032
0.055192, 838.881324
0.055400, 839.117777
0.055651, 840.233905
0.055872, 839.850708
0.056111, 842.003035
0.056343, 841.573447
0.056561, 842.212021
0.056793, 843.105636
0.057018, 843.773289
0.057249, 844.493817
0.057477, 844.889830
0.057705, 845.460429
0.057926, 846.052687
0.058158, 846.595368
0.058386, 847.389193
0.058611, 848.027018
0.058836, 848.239414
0.059072, 849.289702
0.059295, 849.380349
0.059525, 850.572398
0.059764, 850.760998
0.059967, 850.747321
0.060220, 852.233044
0.060425, 851.974406
0.060671, 853.505808
0.060895, 853.472383
0.061123, 854.385033
0.061348, 854.676535
0.061572, 855.292888
0.061805, 856.382073
0.062025, 856.707787
0.062254, 857.243161
0.062483, 858.095218
0.062706, 857.734917
0.062944, 859.050101
0.063179, 859.584164
0.063408, 859.874503
0.063649, 860.574271
0.063878, 861.178895
0.064114, 861.810425
0.064328, 862.003148
0.064569, 863.534550
0.064790, 862.466087
0.065022, 864.534250
0.065258, 863.994641
0.065491, 865.165517
0.065727, 865.729708
0.065961, 866.562018
0.066191, 866.630818
0.066415, 867.186165
0.066648, 867.444915
0.066873, 868.037810
0.067104, 868.531627
0.067332, 868.940830
0.067574, 870.542719
0.067801, 870.272990
0.068034, 871.549352
0.068276, 871.678108
0.068481, 871.796672
0.068732, 872.748857
0.068959, 873.037211
0.069186, 873.393202
0.069416, 874.150416
0.069643, 874.678558
0.069869, 874.990257
0.070101, 875.928989
0.070327, 875.973132
0.070561, 876.500824
0.070788, 877.055947
0.071023, 877.650341
0.071247, 878.262984
0.071481, 879.173986
0.071710, 878.978940
0.071941, 880.532227
0.072192, 880.642359
0.072401, 880.163269
0.072650, 882.203065
0.072881, 881.745110
0.073108, 882.059619
0.073337, 882.834970
0.073563, 883.410890
0.073796, 883.840740
0.074028, 883.980102
0.074254, 884.609496
0.074488, 885.087874
0.074725, 885.799558
0.074957, 886.329536
0.075191, 886.666192
0.075425, 887.321667
0.075643, 887.473694
0.075890, 889.051563
0.076119, 888.500974
0.076343, 889.965038
0.076597, 889.785093
0.076814, 890.085663
0.077054, 890.553699
0.077277, 891.039309
0.077508, 891.429214
0.077737, 892.165480
0.077965, 892.559170
0.078187, 892.787941
0.078421, 893.587537
0.078655, 893.926141
0.078886, 894.324065
0.079118, 895.009331
0.079349, 895.708724
0.079584, 895.997452
0.079825, 896.433448
0.080067, 896.905344
0.080293, 896.734767
0.080538, 897.575058
0.080769, 898.107847
0.080987, 898.044330
0.081245, 899.560069
0.081455, 898.705576
0.081703, 900.838305
0.081945, 900.099790
0.082169, 901.377801
0.082429, 901.470322
0.082664, 901.779173
0.082898, 902.244585
0.083129, 902.761373
0.083364, 903.286217
0.083604, 903.936858
0.083838, 904.196620
0.084065, 904.447950
0.084290, 904.458480
0.084524, 905.389792
0.084765, 905.653714
0.084989, 905.293937
0.085233, 907.423743
0.085469, 906.816983
0.085689, 908.000675
0.085950, 908.525444
0.086159, 907.819906
0.086396, 908.994829
0.086614, 908.727085
0.086855, 909.876377
0.087088, 910.150678
0.087318, 910.418047
0.087550, 910.875478
0.087778, 911.177958
0.088017, 911.807465
0.088245, 911.936071
0.088480, 912.497939
0.088717, 912.922506
0.088955, 913.614292
0.089201, 914.070561
0.089420, 914.066814
0.089685, 915.485498
0.089907, 914.660609
0.090150, 916.461553
0.090380, 915.103912
0.090624, 917.256839
0.090868, 916.744510
0.091102, 917.196770
0.091339, 917.924043
0.091576, 918.240950
0.091815, 918.829161
0.092062, 919.423893
0.092286, 918.704527
0.092528, 919.694259
0.092753, 919.823128
0.092990, 920.810762
0.093227, 920.510605
0.093450, 921.241775
0.093718, 922.249494
0.093940, 921.944091
0.094187, 923.038934
0.094422, 922.918309
0.094657, 923.173462
0.094888, 923.346923
0.095115, 923.851270
0.095350, 924.600352
0.095584, 924.834033
0.095824, 925.315971
0.096065, 926.105411
0.096294, 925.814847
0.096540, 927.158510
0.096790, 926.621225
0.097020, 927.429963
0.097279, 927.327587
0.097493, 927.476392
0.097746, 928.686427
0.097975, 928.683917
0.098215, 929.237840
0.098449, 929.223413
0.098689, 930.054560
0.098924, 930.253916
0.099162, 930.374091
0.099403, 931.108184
0.099648, 931.767968
0.099893, 931.677734
0.100120, 932.474256
0.100373, 932.934310
0.100592, 932.431949
0.100850, 934.350296
0.101080, 932.709248
0.101325, 934.959305
0.101564, 934.162595
0.101803, 934.956532
0.102039, 935.226598
0.102273, 935.619688
0.102511, 936.014614
0.102749, 936.191224
0.102987, 936.531177
0.103225, 936.570786
0.103465, 937.537023
0.103699, 937.792700
0.103944, 938.077157
0.104185, 938.598628
0.104423, 938.607360
0.104665, 939.085063
0.104904, 939.693472
0.105138, 939.599940
0.105378, 940.350296
0.105606, 940.291726
0.105850, 941.010305
0.106076, 940.965488
0.106342, 942.269804
0.106559, 940.961403
0.106816, 943.039084
0.107052, 942.068163
0.107287, 943.339466
0.107538, 943.618676
0.107778, 943.677246
0.108020, 944.115042
0.108261, 944.751068
0.108500, 944.738327
0.108737, 945.099528
0.108984, 945.650416
0.109230, 945.754253
0.109475, 946.338679
0.109719, 946.555385
0.109959, 946.830360
0.110193, 946.708949
0.110427, 947.211384
0.110667, 947.746271
0.110909, 947.787529
0.111139, 948.366522
0.111392, 949.333658
0.111616, 948.586600
0.111867, 950.358165
0.112101, 949.148617
0.112359, 951.463614
0.112612, 950.172900
0.112851, 950.691524
0.113084, 950.991906
0.113325, 951.318107
0.113568, 951.846886
0.113812, 952.570674
0.114052, 952.098141
0.114296, 952.865023
0.114527, 952.563704
0.114771, 953.372218
0.115007, 953.653564
0.115238, 953.405006
0.115481, 954.822566
0.115734, 954.562879
0.115959, 955.215956
0.116234, 956.085438
0.116458, 955.497190
0.116712, 956.740163
0.116952, 955.890729
0.117193, 956.635239
0.117434, 956.863412
0.117680, 957.412988
0.117918, 957.618002
0.118165, 958.141310
0.118404, 958.445402
0.118646, 958.593682
0.118886, 958.717380
0.119131, 959.163307
0.119366, 959.443566
0.119610, 960.010193
0.119842, 959.927490
0.120097, 960.965225
0.120342, 960.705126
0.120574, 961.610020
0.120832, 961.031177
0.121065, 961.431612
0.121312, 961.816046
0.121554, 961.850596
0.121801, 962.561043
0.122044, 963.183954
0.122293, 963.270104
0.122535, 963.366484
0.122773, 963.777037
0.123017, 963.856517
0.123264, 964.437608
0.123514, 964.653226
0.123762, 964.862325
0.124013, 966.222064
0.124277, 965.520985
0.124491, 965.410665
0.124759, 966.549502
0.124979, 965.777786
0.125249, 967.228697
0.125491, 966.785243
0.125738, 967.154201
0.125988, 968.011954
0.126238, 968.309750
0.126490, 968.536274
0.126730, 968.349059
0.126972, 968.962527
0.127214, 968.619951
0.127457, 969.591096
0.127696, 969.960916
0.127939, 970.152439
0.128181, 970.612456
0.128425, 970.639511
0.128682, 971.341977
0.128927, 971.337218
0.129171, 971.322454
0.129421, 971.350558
0.129662, 971.893053
0.129898, 971.837930
0.130139, 972.464925
0.130380, 973.244623
0.130642, 973.425541
0.130869, 973.225287
0.131139, 974.513490
0.131366, 973.195421
0.131627, 975.157723
0.131868, 974.065577
0.132114, 974.838005
0.132353, 975.150903
0.132602, 975.441992
0.132846, 975.613543
0.133091, 975.752679
0.133336, 975.684441
0.133583, 976.116278
0.133827, 976.692648
0.134083, 977.420070
0.134324, 977.196170
0.134579, 977.724387
0.134825, 977.857791
0.135080, 978.274039
0.135324, 978.234130
0.135566, 978.274676
0.135819, 979.148580
0.136047, 978.107585
0.136305, 980.098703
0.136553, 979.173949
0.136780, 979.983962
0.137059, 980.459979
0.137289, 979.938844
0.137549, 980.842876
0.137795, 980.992505
0.138042, 981.291164
0.138288, 981.098479
0.138536, 981.618789
0.138789, 982.023346
0.139034, 982.308814
0.139286, 982.358128
0.139536, 983.001461
0.139784, 982.945477
0.140032, 983.317208
0.140288, 983.656412
0.140526, 983.581991
0.140793, 984.518661
0.141035, 983.959155
0.141302, 985.570899
0.141556, 984.767219
0.141789, 985.372480
0.142058, 985.412014
0.142306, 985.623398
0.142553, 985.712808
0.142800, 986.058120
0.143050, 986.379225
0.143308, 986.993255
0.143563, 987.257776
0.143812, 987.314060
0.144061, 987.115117
0.144307, 987.517013
0.144553, 987.794911
0.144803, 987.803605
0.145055, 988.649104
0.145302, 988.846699
0.145566, 988.945814
0.145801, 988.913250
0.146069, 989.909128
0.146310, 988.388706
0.146568, 990.860076
0.146826, 989.706400
0.147073, 990.671738
0.147327, 990.817470
0.147578, 991.079480
0.147830, 991.060519
0.148078, 991.206850
0.148324, 991.287567
0.148573, 991.856891
0.148815, 991.840740
0.149073, 992.461740
0.149317, 992.769505
0.149569, 992.774339
0.149821, 993.275238
0.150075, 993.658510
0.150341, 993.669002
0.150579, 993.200667
0.150860, 994.863599
0.151095, 993.765383
0.151367, 995.431837
0.151626, 994.544106
0.151874, 994.946451
0.152129, 994.948250
0.152374, 995.130743
0.152629, 995.481076
0.152880, 995.663044
0.153134, 996.327662
0.153385, 996.285431
0.153633, 996.473095
0.153881, 996.551563
0.154130, 997.046391
0.154392, 997.640148
0.154637, 996.822716
0.154893, 998.156374
0.155158, 997.795773
0.155387, 997.549464
0.155680, 999.183579
0.155922, 998.178558
0.156190, 999.137825
0.156444, 999.071236
0.156692, 999.339541
0.156953, 999.329574
0.157212, 999.905868
0.157473, 1000.247396
0.157733, 1000.407442
0.157986, 1000.468710
0.158245, 1000.597804
0.158502, 1000.922544
0.158752, 1001.234280
0.159004, 1001.151278
0.159258, 1001.285131
0.159508, 1001.576482
0.159769, 1002.195009
0.160021, 1001.814659
0.160266, 1002.141422
0.160552, 1003.103800
0.160790, 1001.909278
0.161064, 1003.614217
0.161312, 1002.067451
0.161551, 1003.549164
0.161816, 1003.277711
0.162072, 1003.994379
0.162333, 1004.506970
0.162590, 1004.520760
0.162855, 1004.697857
0.163111, 1004.655550
0.163367, 1004.846137
0.163624, 1005.117665
0.163872, 1005.167016
0.164126, 1005.217792
0.164390, 1006.189088
0.164641, 1006.176347
0.164892, 1006.232556
0.165157, 1006.423743
0.165409, 1006.502848
0.165677, 1006.965787
0.165944, 1007.364723
0.166195, 1007.097354
0.166455, 1007.782995
0.166722, 1007.731769
0.166975, 1007.934123
0.167240, 1008.191486
0.167500, 1008.347148
0.167753, 1008.115004
0.168016, 1009.274301
0.168291, 1008.892640
0.168522, 1008.126171
0.168816, 1010.283894
0.169063, 1008.907704
0.169343, 1010.499063
0.169606, 1009.930675
0.169867, 1009.990444
0.170132, 1010.318294
0.170390, 1010.267631
0.170645, 1010.477591
0.170901, 1011.032152
0.171157, 1011.196170
0.171412, 1011.100165
0.171671, 1011.563891
0.171936, 1011.738215
0.172190, 1011.525519
0.172448, 1011.952072
0.172711, 1012.240238
0.172969, 1012.264671
0.173228, 1012.840965
0.173513, 1013.528142
0.173758, 1012.419771
0.174036, 1014.265008
0.174299, 1012.920220
0.174550, 1013.778498
0.174825, 1013.745559
0.175083, 1013.927902
0.175349, 1014.321854
0.175609, 1014.704864
0.175874, 1014.602563
0.176144, 1014.893615
0.176410, 1014.998951
0.176671, 1015.000562
0.176936, 1015.355093
0.177200, 1015.576257
0.177461, 1015.561830
0.177727, 1015.768455
0.177986, 1016.164168
0.178252, 1016.191261
0.178499, 1016.354268
0.178772, 1017.120175
0.179033, 1016.765495
0.179296, 1016.992168
0.179554, 1016.866297
0.179816, 1017.266394
0.180080, 1017.530316
0.180340, 1017.676572
0.180605, 1018.045717
0.180857, 1018.100315
0.181115, 1018.087686
0.181387, 1018.496740
0.181636, 1018.307764
0.181920, 1019.183804
0.182177, 1018.447463
0.182442, 1019.641235
0.182724, 1019.317095
0.182985, 1019.635165
0.183251, 1019.594057
0.183519, 1019.782508
0.183784, 1019.989470
0.184047, 1020.203702
0.184311, 1020.158398
0.184582, 1020.852769
0.184843, 1020.960129
0.185110, 1021.045529
0.185377, 1021.030765
0.185647, 1021.137900
0.185913, 1021.300232
0.186175, 1021.714270
0.186461, 1022.013303
0.186712, 1021.376340
0.186986, 1023.043806
0.187256, 1021.825227
0.187518, 1023.147980
0.187799, 1022.797759
0.188069, 1022.925317
0.188339, 1022.966087
0.188619, 1023.640523
0.188889, 1023.345275
0.189160, 1023.402009
0.189414, 1023.547778
0.189683, 1023.723226
0.189945, 1023.762984
0.190219, 1023.939669
0.190489, 1024.291988
0.190755, 1024.575283
0.191031, 1024.790489
0.191296, 1024.609496
0.191562, 1024.813160
0.191827, 1025.155625
0.192100, 1025.235404
0.192352, 1024.847411
0.192637, 1026.268305
0.192902, 1025.561006
0.193162, 1026.291276
0.193450, 1026.503110
0.193698, 1026.304317
0.193999, 1026.923555
0.194264, 1026.603500
0.194538, 1026.819343
0.194806, 1026.801694
0.195081, 1027.096230
0.195355, 1027.407367
0.195621, 1027.080567
0.195891, 1027.483474
0.196159, 1027.795848
0.196429, 1027.772278
0.196703, 1027.955595
0.196968, 1028.353744
0.197242, 1028.572435
0.197508, 1028.444952
0.197776, 1028.651503
0.198042, 1028.800007
0.198314, 1028.997827
0.198585, 1028.965750
0.198863, 1029.430675
0.199134, 1029.502548
0.199410, 1029.583115
0.199689, 1029.712209
0.199956, 1029.693060
0.200227, 1029.943266
0.200500, 1030.119014
0.200758, 1030.134977
0.201049, 1031.020610
0.201316, 1030.190362
0.201579, 1031.139699
0.201863, 1030.701454
0.202111, 1030.475230
0.202420, 1031.919546
0.202685, 1031.360676
0.202965, 1031.648880
0.203234, 1031.665330
0.203513, 1031.739639
0.203783, 1031.814210
0.204054, 1031.822941
0.204324, 1032.169265
0.204590, 1032.322154
0.204863, 1032.386270
0.205133, 1032.518661
0.205407, 1032.914674
0.205677, 1032.474818
0.205956, 1033.216218
0.206238, 1033.174736
0.206520, 1033.551937
0.206790, 1033.677621
0.207073, 1033.870681
0.207341, 1033.314435
0.207630, 1034.494267
0.207905, 1033.576894
0.208175, 1034.699393
0.208468, 1033.852807
0.208721, 1033.995990
0.209012, 1034.381324
0.209289, 1034.867009
0.209564, 1034.933748
0.209847, 1035.231769
0.210127, 1035.286967
0.210402, 1035.063741
0.210684, 1035.539084
0.210959, 1035.638649
0.211233, 1035.685416
0.211509, 1035.813048
0.211772, 1035.739414
0.212064, 1036.476579
0.212337, 1035.778798
0.212610, 1036.853444
0.212913, 1036.734730
0.213174, 1036.765083
0.213483, 1036.697032
0.213761, 1036.857828
0.214039, 1036.856067
0.214306, 1036.718017
0.214588, 1037.311587
0.214854, 1037.276849
0.215129, 1037.496178
0.215406, 1037.455407
0.215687, 1037.913138
0.215975, 1038.231432
0.216256, 1038.172450
0.216545, 1038.736304
0.216832, 1038.278048
0.217105, 1038.384921
0.217392, 1038.425017
0.217662, 1037.844788
0.217942, 1039.230121
0.218234, 1038.647456
0.218495, 1038.728472
0.218813, 1039.836768
0.219068, 1038.451585
0.219378, 1040.086113
0.219653, 1039.511654
0.219937, 1039.233681
0.220213, 1039.556097
0.220493, 1039.895114
0.220772, 1039.929514
0.221052, 1040.178033
0.221336, 1040.540133
0.221618, 1040.475118
0.221905, 1040.764821
0.222188, 1040.588061
0.222478, 1040.692798
0.222761, 1040.986210
0.223046, 1040.683504
0.223329, 1041.129506
0.223617, 1041.570636
0.223886, 1040.740276
0.224202, 1042.379300
0.224467, 1040.707712
0.224765, 1042.396837
0.225053, 1041.537323
0.225339, 1042.060968
0.225623, 1041.896837
0.225909, 1042.215844
0.226191, 1042.152027
0.226478, 1042.302818
0.226761, 1042.199543
0.227052, 1042.658210
0.227342, 1042.647006
0.227630, 1042.949299
0.227916, 1042.658135
0.228205, 1042.848422
0.228497, 1043.294424
0.228780, 1043.242637
0.229067, 1043.326950
0.229363, 1043.899573
0.229645, 1042.918609
0.229924, 1043.653151
0.230022, 1018.190437
0.230089, 1027.268231
0.230175, 1035.083190
0.230279, 1041.481826
0.230397, 1045.867983
0.230565, 1049.945140
0.230723, 1048.596343
0.230920, 1051.426179
0.231153, 1050.985236
0.231366, 1050.373454
0.231614, 1050.393427
0.231849, 1050.052949
0.232094, 1049.558045
0.232344, 1049.332047
0.232599, 1049.261485
0.232847, 1048.577681
0.233094, 1048.602263
0.233345, 1048.242899
0.233600, 1048.476017
0.233857, 1048.463876
0.234111, 1047.886120
0.234368, 1047.893652
0.234620, 1047.679495
0.234881, 1048.002623
0.235140, 1047.882748
0.235383, 1047.307540
0.235649, 1048.148505
0.235898, 1047.325714
0.236147, 1048.476804
0.236419, 1047.894439
0.236656, 1047.531665
0.236930, 1048.370044
0.237179, 1047.518699
0.237436, 1047.701604
0.237693, 1047.845912
0.237950, 1047.991793
0.238212, 1048.349472
0.238461, 1048.226223
0.238723, 1048.138687
0.238982, 1048.372068
0.239238, 1048.152065
0.239501, 1048.334108
0.239758, 1048.717305
0.240007, 1048.521397
0.240266, 1048.740313
0.240524, 1049.094881
0.240779, 1048.515176
0.241032, 1048.829798
0.241291, 1049.104774
0.241543, 1048.899835
0.241790, 1049.041407
0.242047, 1049.263247
0.242305, 1049.483662
0.242560, 1049.595593
0.242826, 1049.709098
0.243084, 1049.502361
0.243336, 1049.471221
0.243596, 1049.489620
0.243845, 1049.181781
0.244096, 1050.107397
0.244353, 1050.027992
0.244602, 1050.139961
0.244857, 1050.403245
0.245117, 1050.254366
0.245377, 1050.543019
0.245634, 1050.483587
0.245891, 1050.405494
0.246153, 1050.439669
0.246408, 1050.686315
0.246657, 1050.278798
0.246908, 1050.887019
0.247167, 1050.803043
0.247408, 1050.538260
0.247681, 1051.753803
0.247940, 1050.474818
0.248188, 1051.362437
0.248461, 1050.973732
0.248709, 1050.951623
0.248969, 1051.372480
0.249222, 1051.338942
0.249483, 1051.409953
0.249742, 1051.453721
0.249996, 1051.493667
0.250252, 1051.442517
0.250508, 1051.449262
0.250763, 1051.874466
0.251023, 1052.108446
0.251276, 1052.139287
0.251530, 1051.907929
0.251776, 1051.776924
0.252034, 1052.339391
0.252288, 1051.882148
0.252553, 1052.215019
0.252815, 1052.412201
0.253068, 1052.255003
0.253323, 1052.514015
0.253587, 1052.772577
0.253842, 1052.601626
0.254110, 1052.941430
0.254370, 1052.937533
0.254631, 1052.644795
0.254892, 1052.943341
0.255147, 1052.935209
0.255406, 1053.309863
0.255665, 1053.027430
0.255917, 1053.200817
0.256201, 1053.803230
0.256448, 1052.970396
0.256718, 1054.020535
0.256977, 1052.623510
0.257229, 1053.602751
0.257508, 1053.346511
0.257774, 1053.345500
0.258033, 1053.518512
0.258300, 1053.756239
0.258566, 1053.931237
0.258831, 1053.895376
0.259103, 1053.548228
0.259367, 1053.629319
0.259628, 1053.814997
0.259891, 1054.009406
0.260159, 1054.383759
0.260424, 1054.290377
0.260692, 1054.036911
0.260957, 1053.990819
0.261221, 1054.345762
0.261491, 1054.253916
0.261752, 1054.018249
0.262022, 1054.144008
0.262293, 1054.392903
0.262562, 1054.599228
0.262827, 1054.423368
0.263102, 1054.825452
0.263368, 1054.748895
0.263636, 1054.732894
0.263917, 1054.751330
0.264176, 1054.182418
0.264454, 1055.254553
0.264740, 1055.487034
0.265003, 1054.898636
0.265288, 1055.785918
0.265557, 1054.649142
0.265811, 1055.101177
0.266103, 1055.498726
0.266370, 1055.378251
0.266648, 1055.317732
0.266922, 1055.463014
0.267194, 1055.565690
0.267468, 1055.333546
0.267747, 1055.626958
0.268025, 1055.716668
0.268294, 1055.533726
0.268563, 1055.267294
0.268831, 1055.245110
0.269108, 1055.903545
0.269387, 1055.730683
0.269662, 1055.856629
0.269944, 1055.988159
0.270221, 1056.313535
0.270496, 1055.658922
0.270764, 1055.666192
0.271060, 1056.080379
0.271322, 1055.556022
0.271618, 1056.387769
0.271885, 1055.382635
0.272170, 1056.585513
0.272466, 1056.014802
0.272734, 1056.379787
0.273031, 1056.529828
0.273310, 1056.691636
0.273590, 1056.190962
0.273875, 1056.442667
0.274162, 1056.539047
0.274439, 1056.260099
0.274724, 1056.196732
0.275006, 1057.019673
0.275293, 1057.012853
0.275564, 1056.324065
0.275834, 1056.474406
0.276113, 1056.479765
0.276380, 1056.217230
0.276683, 1057.450986
0.276962, 1055.799895
0.277251, 1057.238065
0.277549, 1056.962377
0.277845, 1057.074796
0.278143, 1057.035262
0.278441, 1057.365772
0.278724, 1056.556322
0.279015, 1056.695233
0.279310, 1057.036573
0.279604, 1057.200292
0.279902, 1057.382485
0.280190, 1056.913325
0.280478, 1056.994417
0.280766, 1057.068838
0.281054, 1057.103388
0.281346, 1056.854343
0.281637, 1057.200292
0.281938, 1057.452897
0.282244, 1057.681219
0.282538, 1057.392003
0.282835, 1057.443641
0.283129, 1057.369969
0.283428, 1057.437495
0.283719, 1057.279060
0.284016, 1057.591359
0.284316, 1057.319756
0.284612, 1057.267181
0.284909, 1057.650641
0.285200, 1057.169565
0.285494, 1057.426366
0.285801, 1057.894514
0.286104, 1057.932474
0.286410, 1057.380049
0.286710, 1057.699955
0.287011, 1057.679757
0.287308, 1057.769842
0.287608, 1057.734730
0.287909, 1057.820205
0.288214, 1057.382260
0.288521, 1057.573409
0.288823, 1057.337368
0.289131, 1057.787417
0.289440, 1057.993442
0.289742, 1057.594994
0.290043, 1057.811999
0.290344, 1057.973020
0.290647, 1057.371918
0.290955, 1057.622611
0.291262, 1057.846998
0.291579, 1057.752380
0.291893, 1057.886944
0.292199, 1057.713071
0.292506, 1057.505134
0.292815, 1058.180319
0.293124, 1057.643596
0.293434, 1057.947051
0.293747, 1057.932849
0.294052, 1057.650866
0.294370, 1057.535150
0.294683, 1057.833958
0.295006, 1057.712396
0.295324, 1057.934760
0.295644, 1058.315109
0.295965, 1057.766282
0.296286, 1057.594357
0.296603, 1057.383347
0.296906, 1057.399161
0.297224, 1058.117440
0.297547, 1057.815371
0.297866, 1057.874091
0.298190, 1057.954508
0.298497, 1057.475418
0.298818, 1057.981826
0.299143, 1057.969797
0.299456, 1057.433786
0.299772, 1057.918197
0.300111, 1058.065915
0.300416, 1056.740838
0.300763, 1058.535862
0.301091, 1057.888368
0.301418, 1057.837630
0.301752, 1058.165293
0.302080, 1057.816908
0.302414, 1057.425054
0.302747, 1057.608484
0.303076, 1057.627295
0.303411, 1057.577082
0.303747, 1057.677284
0.304075, 1057.551600
0.304409, 1057.750244
0.304739, 1057.492543
0.305070, 1057.543918
0.305408, 1057.501986
0.305749, 1057.651428
0.306082, 1057.342652
0.306415, 1057.123885
0.306747, 1057.283894
0.307083, 1057.265945
0.307424, 1057.377052
0.307766, 1057.748183
0.308109, 1057.297572
0.308454, 1057.329611
0.308793, 1057.016526
0.309138, 1057.204752
0.309486, 1057.000637
0.309801, 1056.978678
0.310159, 1057.574533
0.310488, 1056.471333
0.310821, 1057.930450
0.311178, 1056.807802
0.311521, 1057.480027
0.311880, 1057.206738
0.312224, 1056.616091
0.312571, 1056.963764
0.312904, 1056.595481
0.313246, 1056.800757
0.313592, 1056.840740
0.313934, 1056.515776
0.314289, 1056.536836
0.314633, 1056.752080
0.314979, 1056.491231
0.315325, 1056.637975
0.315680, 1056.833771
0.316036, 1056.687814
0.316398, 1056.840928
0.316756, 1056.537810
0.317098, 1055.939331
0.317456, 1056.551563
0.317817, 1056.440231
0.318170, 1056.126321
0.318533, 1056.606610
0.318902, 1056.408042
0.319266, 1056.257551
0.319623, 1055.884359
0.319973, 1055.652215
0.320341, 1055.820168
0.320706, 1055.693622
0.321067, 1055.660459
0.321440, 1055.737540
0.321789, 1055.778311
0.322164, 1055.633890
0.322537, 1055.653376
0.322905, 1055.513078
0.323270, 1055.179120
0.323640, 1055.533351
0.324003, 1055.156187
0.324370, 1055.225886
0.324736, 1055.189650
0.325116, 1055.368883
0.325494, 1055.040208
0.325862, 1054.936558
0.326235, 1054.945477
0.326616, 1054.918497
0.326994, 1054.597130
0.327371, 1054.304055
0.327745, 1054.094881
0.328128, 1054.742674
0.328510, 1054.361013
0.328892, 1054.515139
0.329272, 1054.376077
0.329650, 1053.848235
0.330036, 1054.019711
0.330410, 1053.900510
0.330791, 1053.717005
0.331170, 1053.630368
0.331556, 1053.920857
0.331931, 1053.418534
0.332310, 1053.845462
0.332684, 1053.419808
0.333065, 1053.232631
0.333444, 1053.156449
0.333825, 1053.187064
0.334212, 1053.290977
0.334603, 1052.838155
0.334984, 1052.535899
0.335387, 1052.686352
0.335781, 1052.642022
0.336163, 1052.058907
0.336554, 1052.792475
0.336955, 1052.398748
0.337342, 1051.752380
0.337736, 1051.796972
0.338132, 1052.032714
0.338530, 1051.876077
0.338927, 1051.651390
0.339319, 1051.686615
0.339714, 1051.307764
0.340092, 1051.326950
0.340513, 1051.494979
0.340887, 1050.246234
0.341298, 1051.666754
0.341705, 1050.307277
0.342096, 1050.678558
0.342499, 1050.331147
0.342898, 1050.144795
0.343305, 1050.263509
0.343713, 1050.312636
0.344118, 1050.011879
0.344518, 1049.479352
0.344922, 1049.563029
0.345314, 1048.840403
0.345714, 1049.204527
0.346115, 1049.144383
0.346530, 1049.108934
0.346935, 1048.571536
0.347322, 1048.486547
0.347751, 1049.211497
0.348160, 1048.351158
0.348569, 1047.910328
0.348978, 1048.027580
0.349383, 1047.777636
0.349793, 1047.693622
0.350204, 1047.317133
0.350623, 1047.325714
0.351026, 1046.947913
0.351442, 1046.741288
0.351850, 1046.656374
0.352259, 1046.453009
0.352672, 1046.190699
0.353077, 1046.192348
0.353486, 1045.750094
0.353900, 1045.953121
0.354307, 1045.394327
0.354707, 1045.472420
0.355149, 1045.757851
0.355571, 1045.249681
0.355994, 1044.807277
0.356412, 1044.680507
0.356825, 1044.300719
0.357246, 1044.361463
0.357656, 1044.011467
0.358070, 1044.083939
0.358485, 1043.163644
0.358875, 1042.933336
0.359318, 1043.381623
0.359725, 1041.962752
0.360158, 1043.371056
0.360585, 1042.345762
0.361014, 1042.281271
0.361435, 1042.271978
0.361857, 1041.467586
0.362266, 1040.936146
0.362677, 1040.719666
0.363089, 1040.419996
0.363509, 1040.431425
0.363932, 1040.351420
0.364357, 1040.184629
0.364783, 1039.870157
0.365196, 1039.532302
0.365617, 1039.097354
0.366048, 1038.770179
0.366476, 1038.649779
0.366908, 1038.128082
0.367332, 1037.787679
0.367756, 1037.167429
0.368186, 1037.116615
0.368614, 1036.495915
0.369048, 1036.003185
0.369498, 1034.457656
0.369954, 1033.095481
0.370443, 1030.119239
0.371008, 1019.654276