File: Original_Data/Stress_Strain/SR/18-321_RT_SRonly.csv
Eng_Strain, Eng_Stress (MPa)
0.000010, 1.951054
0.000070, 14.118398
0.000143, 28.185940
0.000209, 41.765450
0.000269, 53.326842
0.000325, 64.755909
0.000381, 75.742758
0.000443, 87.524889
0.000494, 98.207175
0.000552, 109.560191
0.000602, 120.453336
0.000656, 131.396492
0.000731, 144.969476
0.000783, 156.202990
0.000843, 167.983991
0.000899, 179.095004
0.000962, 191.345027
0.001018, 202.712651
0.001078, 214.512783
0.001138, 225.878886
0.001192, 237.103614
0.001243, 247.672275
0.001309, 260.862873
0.001353, 269.971167
0.001422, 282.972831
0.001472, 292.484009
0.001527, 303.512430
0.001578, 314.269638
0.001633, 325.020923
0.001689, 335.135031
0.001738, 345.627192
0.001790, 356.063155
0.001845, 366.749730
0.001899, 377.210728
0.001950, 387.574638
0.002003, 397.962174
0.002054, 408.156412
0.002086, 414.248028
0.002155, 427.028398
0.002200, 436.947187
0.002251, 447.043235
0.002312, 458.307077
0.002362, 468.517429
0.002412, 478.190594
0.002467, 488.786342
0.002519, 499.052776
0.002573, 509.850800
0.002622, 519.042596
0.002672, 528.634024
0.002722, 538.883104
0.002776, 549.126061
0.002827, 558.445233
0.002879, 568.648599
0.002924, 576.675043
0.002975, 585.493802
0.003046, 597.128766
0.003101, 604.262264
0.003192, 615.506273
0.003275, 622.011043
0.003383, 629.925513
0.003514, 636.720945
0.003655, 642.803659
0.003806, 648.373075
0.003980, 653.355758
0.004164, 657.932762
0.004365, 662.125648
0.004574, 665.902412
0.004805, 669.063707
0.005052, 670.996657
0.005294, 673.558298
0.005622, 677.212456
0.005866, 676.424423
0.006172, 680.775148
0.006466, 681.032567
0.006750, 682.355495
0.007048, 683.998648
0.007334, 685.096725
0.007621, 685.930208
0.007913, 687.669709
0.008211, 688.256254
0.008506, 689.555556
0.008804, 690.622042
0.009092, 692.042784
0.009393, 692.894185
0.009689, 693.429457
0.009965, 694.631808
0.010312, 696.961085
0.010586, 695.690632
0.010868, 698.947374
0.011189, 698.260837
0.011482, 700.066261
0.011774, 700.763654
0.012067, 701.388100
0.012351, 702.777778
0.012649, 703.311772
0.012930, 703.979040
0.013213, 705.586921
0.013494, 705.491849
0.013765, 706.792653
0.014060, 708.038765
0.014336, 707.945985
0.014613, 710.573097
0.014946, 710.334085
0.015183, 711.196416
0.015500, 711.333747
0.015755, 712.672301
0.016034, 713.940050
0.016301, 714.899932
0.016574, 715.478514
0.016844, 716.519833
0.017117, 717.388138
0.017388, 718.155811
0.017655, 719.064383
0.017942, 719.943505
0.018221, 720.611261
0.018473, 721.006423
0.018775, 723.890617
0.019054, 722.952220
0.019283, 723.852603
0.019593, 725.772519
0.019858, 725.920780
0.020131, 726.808730
0.020381, 727.240328
0.020651, 728.544737
0.020910, 729.314514
0.021165, 729.835474
0.021424, 730.738224
0.021684, 731.933927
0.021955, 732.861468
0.022208, 733.578394
0.022480, 734.515852
0.022722, 734.613064
0.023005, 737.390542
0.023271, 735.649050
0.023527, 738.815942
0.023802, 738.070393
0.024051, 739.348922
0.024304, 739.874390
0.024551, 740.902224
0.024809, 741.786643
0.025063, 742.402900
0.025311, 743.488205
0.025578, 744.085305
0.025826, 744.337616
0.026058, 746.083127
0.026354, 746.698633
0.026599, 747.671625
0.026860, 748.408947
0.027095, 748.639095
0.027345, 750.167869
0.027605, 750.475021
0.027849, 751.577868
0.028111, 752.716287
0.028341, 752.270566
0.028589, 754.863309
0.028860, 754.320036
0.029072, 755.083239
0.029369, 756.692360
0.029613, 757.104462
0.029855, 757.417925
0.030104, 758.727819
0.030354, 759.976486
0.030605, 760.335287
0.030848, 761.063294
0.031082, 761.792052
0.031322, 762.351364
0.031565, 763.635865
0.031811, 764.278229
0.032055, 765.188190
0.032304, 765.992262
0.032534, 766.074788
0.032762, 767.617609
0.033052, 768.450943
0.033261, 767.985388
0.033545, 770.301668
0.033783, 770.183683
0.034027, 771.102509
0.034268, 772.068139
0.034505, 772.571632
0.034738, 773.136278
0.034979, 774.078920
0.035208, 774.747126
0.035453, 775.919503
0.035703, 776.907670
0.035948, 777.717414
0.036187, 777.967208
0.036430, 779.093081
0.036678, 779.969499
0.036899, 779.757456
0.037138, 782.143603
0.037405, 782.025317
0.037639, 782.479303
0.037876, 783.324168
0.038116, 784.092255
0.038361, 785.108932
0.038593, 785.512208
0.038831, 786.355909
0.039061, 786.416310
0.039269, 787.739576
0.039536, 788.365450
0.039763, 789.199046
0.040003, 790.506160
0.040235, 790.465893
0.040475, 791.709451
0.040709, 792.046841
0.040950, 792.960672
0.041183, 793.647322
0.041418, 793.885959
0.041653, 794.753587
0.041869, 795.887649
0.042138, 796.544362
0.042355, 796.433401
0.042612, 798.869281
0.042852, 798.457629
0.043082, 799.138983
0.043312, 800.018631
0.043543, 800.806701
0.043782, 801.684284
0.044011, 802.180340
0.044252, 803.182255
0.044482, 803.541244
0.044703, 804.139546
0.044942, 804.975021
0.045169, 805.465555
0.045376, 805.603749
0.045653, 808.354669
0.045865, 806.459995
0.046113, 809.580347
0.046370, 809.138795
0.046611, 810.013673
0.046845, 810.395237
0.047075, 811.503831
0.047309, 811.907069
0.047537, 812.343663
0.047773, 813.513523
0.048008, 813.828938
0.048233, 814.428781
0.048478, 815.546052
0.048706, 815.515363
0.048921, 816.271167
0.049191, 818.738299
0.049395, 816.700023
0.049642, 819.516791
0.049876, 818.924649
0.050101, 819.780182
0.050334, 820.384456
0.050564, 821.964766
0.050798, 822.085944
0.051028, 822.323943
0.051259, 823.140297
0.051495, 823.721058
0.051727, 824.494516
0.051956, 825.130907
0.052182, 825.639171
0.052412, 826.292653
0.052619, 826.447224
0.052896, 828.624671
0.053103, 827.369356
0.053375, 830.855195
0.053604, 829.424649
0.053844, 830.222711
0.054071, 830.464165
0.054307, 831.421944
0.054544, 832.365863
0.054771, 832.582000
0.055010, 833.567951
0.055239, 833.766772
0.055471, 834.670122
0.055702, 835.067162
0.055911, 835.333033
0.056132, 836.919841
0.056401, 837.513823
0.056598, 836.441289
0.056861, 839.476110
0.057094, 838.887499
0.057323, 839.595184
0.057560, 840.094583
0.057790, 840.687739
0.058019, 841.252197
0.058259, 842.056945
0.058490, 842.434716
0.058715, 843.057283
0.058948, 843.665615
0.059170, 843.858876
0.059378, 844.062993
0.059653, 846.514311
0.059855, 844.905492
0.060109, 847.936368
0.060346, 847.106153
0.060572, 847.875404
0.060805, 848.239201
0.061034, 848.999437
0.061276, 849.868642
0.061514, 850.545864
0.061741, 850.760461
0.061984, 851.697431
0.062220, 851.790211
0.062455, 852.500751
0.062691, 853.141086
0.062927, 853.742243
0.063151, 853.562054
0.063374, 854.134663
0.063588, 855.424574
0.063854, 856.241004
0.064059, 855.651641
0.064314, 858.384344
0.064548, 857.707723
0.064778, 858.290286
0.065005, 858.478101
0.065240, 859.478890
0.065474, 859.755090
0.065701, 860.386710
0.065941, 860.707310
0.066163, 860.822215
0.066402, 862.155248
0.066633, 862.278792
0.066856, 862.423259
0.067074, 863.526670
0.067341, 864.015551
0.067559, 863.859440
0.067827, 866.631846
0.068057, 865.499512
0.068289, 865.975208
0.068515, 866.518631
0.068750, 867.221997
0.068987, 867.785779
0.069218, 868.750470
0.069456, 869.180452
0.069693, 869.421531
0.069920, 869.749831
0.070152, 870.621216
0.070386, 871.205695
0.070618, 871.718954
0.070853, 871.892420
0.071090, 872.279243
0.071311, 872.011344
0.071570, 874.415709
0.071813, 873.495793
0.072027, 874.972429
0.072287, 874.982158
0.072514, 875.399482
0.072746, 875.772256
0.072973, 876.552100
0.073206, 877.242243
0.073440, 877.642401
0.073672, 878.061152
0.073905, 878.563556
0.074144, 879.481519
0.074382, 879.622718
0.074605, 880.020096
0.074850, 880.728420
0.075077, 880.601270
0.075311, 882.373413
0.075588, 882.422771
0.075791, 881.889790
0.076075, 884.219292
0.076309, 883.425776
0.076545, 884.045977
0.076779, 884.529750
0.077012, 885.224664
0.077252, 885.433701
0.077483, 885.898881
0.077723, 886.772970
0.077959, 886.869431
0.078197, 887.814101
0.078433, 888.154647
0.078663, 888.420592
0.078903, 889.427015
0.079145, 889.097626
0.079360, 889.993164
0.079646, 890.960221
0.079851, 889.958681
0.080124, 892.226617
0.080357, 891.317557
0.080592, 891.817407
0.080827, 892.555030
0.081059, 893.195139
0.081308, 893.974645
0.081537, 894.002291
0.081776, 894.697431
0.082015, 894.695665
0.082248, 895.390429
0.082480, 895.738487
0.082715, 896.160844
0.082962, 897.063068
0.083194, 897.331944
0.083412, 896.960221
0.083666, 899.469011
0.083915, 897.988355
0.084143, 899.876568
0.084413, 899.601382
0.084645, 899.753662
0.084884, 900.178461
0.085120, 900.939035
0.085351, 901.074299
0.085586, 901.716024
0.085826, 902.262903
0.086058, 902.682481
0.086309, 903.223387
0.086539, 903.474683
0.086785, 903.898956
0.087017, 903.894110
0.087244, 904.624671
0.087528, 905.716062
0.087747, 904.680189
0.088000, 907.215574
0.088254, 906.588724
0.088493, 907.085493
0.088727, 907.173015
0.088977, 907.827774
0.089208, 908.170686
0.089449, 908.755428
0.089684, 908.660920
0.089919, 909.531853
0.090157, 909.401773
0.090367, 909.994478
0.090641, 911.517091
0.090854, 909.829352
0.091114, 912.657689
0.091359, 911.713357
0.091597, 912.322778
0.091838, 912.797912
0.092075, 913.227669
0.092320, 913.850763
0.092564, 914.014537
0.092799, 914.181654
0.093051, 915.016678
0.093295, 915.498685
0.093524, 915.528548
0.093773, 916.298099
0.094019, 916.510255
0.094236, 916.398092
0.094509, 918.705845
0.094757, 917.738600
0.095004, 917.939411
0.095247, 918.573586
0.095485, 919.445384
0.095733, 919.325933
0.095961, 919.196792
0.096191, 920.505071
0.096467, 920.663361
0.096697, 920.577229
0.096943, 921.278454
0.097177, 921.316768
0.097423, 922.389002
0.097672, 922.428668
0.097899, 921.925701
0.098122, 923.008189
0.098403, 924.367065
0.098635, 923.789234
0.098884, 924.432124
0.099131, 924.676358
0.099368, 924.990684
0.099611, 925.481557
0.099854, 925.986027
0.100099, 926.078957
0.100318, 926.309932
0.100583, 927.651416
0.100813, 926.798738
0.101045, 928.229660
0.101324, 928.190106
0.101566, 928.828826
0.101815, 928.907257
0.102066, 929.205131
0.102308, 929.856322
0.102558, 929.880174
0.102796, 930.221734
0.103036, 930.636466
0.103270, 930.288145
0.103493, 931.129630
0.103781, 932.645143
0.104006, 931.338292
0.104247, 933.128615
0.104518, 933.095523
0.104771, 933.739388
0.105014, 933.830216
0.105266, 934.426940
0.105503, 934.483360
0.105743, 934.699497
0.105986, 935.016453
0.106219, 935.195027
0.106470, 935.896401
0.106718, 936.243708
0.106958, 936.772294
0.107203, 936.807302
0.107419, 936.197393
0.107696, 938.448764
0.107917, 936.527834
0.108161, 939.050409
0.108420, 938.526895
0.108664, 938.970663
0.108912, 939.320337
0.109155, 939.612125
0.109405, 940.306363
0.109658, 940.678537
0.109905, 941.086808
0.110154, 941.228195
0.110396, 941.238111
0.110647, 942.230449
0.110889, 941.806664
0.111106, 941.633837
0.111380, 944.006836
0.111606, 941.714597
0.111854, 944.396251
0.112123, 943.877996
0.112366, 944.089588
0.112613, 944.414131
0.112859, 944.650289
0.113106, 944.803584
0.113348, 945.468560
0.113592, 945.775862
0.113830, 946.026106
0.114076, 946.411126
0.114321, 946.599091
0.114571, 947.395199
0.114812, 947.491811
0.115064, 947.829502
0.115287, 947.109195
0.115540, 949.196529
0.115800, 948.376869
0.116023, 948.994403
0.116297, 950.464766
0.116553, 949.919240
0.116790, 949.849673
0.117036, 950.244535
0.117279, 950.320750
0.117529, 951.269439
0.117770, 951.103861
0.118012, 951.169146
0.118268, 952.226730
0.118515, 952.222110
0.118756, 952.128841
0.118984, 952.241229
0.119260, 954.180640
0.119508, 952.726317
0.119754, 954.782098
0.120023, 953.958117
0.120270, 954.506836
0.120512, 954.794193
0.120752, 954.672414
0.121002, 955.630719
0.121248, 955.742656
0.121496, 956.172076
0.121748, 956.266584
0.121989, 956.342499
0.122249, 957.479077
0.122505, 957.444444
0.122747, 957.479378
0.123005, 958.054166
0.123243, 957.568853
0.123459, 957.582075
0.123745, 959.570355
0.123980, 958.648712
0.124239, 960.597588
0.124499, 959.369243
0.124744, 959.819473
0.124992, 960.199309
0.125234, 960.543385
0.125482, 960.767523
0.125727, 961.060251
0.125971, 961.236158
0.126215, 961.290023
0.126465, 962.186537
0.126726, 962.654609
0.126958, 961.696078
0.127199, 963.493464
0.127485, 963.303321
0.127710, 962.483360
0.127984, 965.275073
0.128243, 964.101608
0.128492, 964.230486
0.128744, 964.931335
0.128987, 964.655999
0.129234, 965.024604
0.129487, 965.833822
0.129732, 965.251521
0.129985, 966.080234
0.130232, 966.179889
0.130461, 966.169521
0.130752, 968.179739
0.130993, 967.009053
0.131246, 967.143828
0.131489, 967.576178
0.131741, 968.180114
0.131989, 967.987003
0.132216, 968.110247
0.132489, 970.062805
0.132749, 969.259372
0.132998, 969.609984
0.133248, 969.545489
0.133496, 970.311735
0.133748, 970.255803
0.133973, 970.271580
0.134245, 972.249944
0.134512, 971.401210
0.134758, 971.429382
0.135007, 971.251596
0.135265, 972.550522
0.135517, 972.255315
0.135769, 972.190895
0.135995, 971.935655
0.136277, 973.698558
0.136530, 973.266359
0.136783, 973.872361
0.137036, 973.945797
0.137294, 974.400947
0.137552, 974.260536
0.137808, 974.822665
0.138057, 974.821238
0.138300, 974.905680
0.138533, 975.201563
0.138829, 976.532943
0.139056, 974.497408
0.139323, 977.522989
0.139596, 976.309969
0.139857, 977.481181
0.140109, 976.816205
0.140366, 977.484111
0.140619, 977.414619
0.140871, 977.758996
0.141113, 978.175006
0.141368, 978.338667
0.141612, 978.252160
0.141862, 978.823529
0.142119, 979.301518
0.142375, 979.361393
0.142607, 979.369018
0.142904, 980.519157
0.143157, 980.376005
0.143413, 980.432875
0.143653, 980.592067
0.143909, 980.712043
0.144151, 980.943205
0.144408, 981.318308
0.144642, 980.937495
0.144902, 982.604124
0.145185, 982.115581
0.145410, 982.075952
0.145695, 983.131771
0.145948, 982.951431
0.146192, 982.836376
0.146450, 983.558223
0.146704, 983.607956
0.146952, 983.608932
0.147214, 984.105326
0.147465, 984.312937
0.147717, 984.560401
0.147977, 984.893622
0.148246, 985.340320
0.148492, 984.835888
0.148756, 985.831380
0.149011, 985.534445
0.149244, 985.145256
0.149535, 987.770791
0.149772, 985.424423
0.150044, 987.365299
0.150312, 986.892608
0.150561, 987.266847
0.150811, 987.616558
0.151066, 987.659192
0.151322, 988.127413
0.151575, 988.100932
0.151824, 988.567012
0.152071, 988.363421
0.152325, 989.182330
0.152588, 989.535797
0.152824, 988.315303
0.153084, 990.446398
0.153361, 989.696229
0.153622, 990.196604
0.153883, 990.573999
0.154118, 989.548193
0.154393, 991.999887
0.154671, 991.162873
0.154931, 991.585831
0.155191, 991.264405
0.155456, 991.826046
0.155714, 991.897190
0.155976, 992.410600
0.156229, 992.236233
0.156481, 992.359177
0.156740, 993.069116
0.157000, 992.900533
0.157256, 993.127301
0.157520, 993.593682
0.157760, 993.076178
0.158030, 995.117835
0.158288, 993.514387
0.158543, 995.473067
0.158817, 994.438359
0.159070, 994.555293
0.159332, 995.153783
0.159578, 995.186237
0.159844, 995.803959
0.160094, 995.531478
0.160356, 996.015025
0.160616, 996.025881
0.160870, 996.460484
0.161140, 997.032905
0.161392, 996.928931
0.161653, 997.270228
0.161908, 996.727481
0.162139, 997.080723
0.162437, 998.095147
0.162667, 996.872887
0.162948, 999.307715
0.163203, 997.916272
0.163468, 998.714860
0.163717, 998.723312
0.163986, 999.443656
0.164244, 999.150515
0.164503, 999.078769
0.164772, 999.611750
0.165036, 1000.294794
0.165298, 1000.037037
0.165559, 1000.136391
0.165825, 1000.215123
0.166083, 1000.055330
0.166334, 1001.011494
0.166627, 1001.111487
0.166857, 1000.446510
0.167156, 1002.783112
0.167417, 1001.558410
0.167680, 1001.714484
0.167931, 1001.702877
0.168190, 1002.549583
0.168445, 1002.441364
0.168703, 1002.732702
0.168965, 1002.960221
0.169227, 1003.020359
0.169487, 1003.676395
0.169751, 1003.670235
0.170009, 1003.291826
0.170258, 1003.909999
0.170557, 1004.621253
0.170810, 1003.844903
0.171072, 1004.393171
0.171335, 1004.083277
0.171589, 1004.839907
0.171886, 1005.787995
0.172148, 1005.011870
0.172394, 1005.454474
0.172702, 1006.623695
0.172965, 1006.079108
0.173235, 1006.243445
0.173481, 1005.782548
0.173749, 1006.719593
0.174004, 1006.535084
0.174267, 1006.975997
0.174539, 1007.050109
0.174771, 1006.651641
0.175077, 1008.410563
0.175342, 1007.822628
0.175612, 1007.930246
0.175866, 1008.025693
0.176123, 1008.041695
0.176378, 1008.305950
0.176640, 1008.632635
0.176906, 1008.856622
0.177149, 1008.651792
0.177448, 1009.903538
0.177708, 1009.032642
0.177952, 1009.850199
0.178242, 1009.541507
0.178504, 1009.937871
0.178768, 1009.929682
0.179032, 1010.103636
0.179286, 1010.579333
0.179554, 1010.884156
0.179823, 1010.990760
0.180077, 1010.744685
0.180334, 1010.917512
0.180633, 1011.943242
0.180903, 1011.788521
0.181168, 1011.626249
0.181430, 1011.884419
0.181691, 1011.735632
0.181961, 1012.419841
0.182235, 1012.949966
0.182491, 1012.434415
0.182772, 1013.096762
0.183019, 1012.092856
0.183288, 1013.987717
0.183582, 1013.400421
0.183833, 1012.749230
0.184108, 1014.549020
0.184403, 1014.274360
0.184670, 1014.268763
0.184935, 1013.957028
0.185204, 1014.299940
0.185463, 1014.298475
0.185733, 1014.921644
0.185998, 1014.592029
0.186237, 1014.219029
0.186521, 1016.407370
0.186816, 1015.881865
0.187077, 1015.252761
0.187348, 1016.052062
0.187619, 1016.368041
0.187886, 1015.905191
0.188158, 1016.645857
0.188433, 1016.557697
0.188700, 1016.904327
0.188982, 1017.038389
0.189224, 1016.430922
0.189515, 1018.202314
0.189793, 1016.988431
0.190036, 1017.485989
0.190335, 1018.022726
0.190610, 1018.190594
0.190879, 1017.862557
0.191152, 1018.365863
0.191430, 1018.512809
0.191698, 1018.292390
0.191972, 1018.795094
0.192227, 1018.153445
0.192490, 1019.134400
0.192799, 1019.539328
0.193057, 1019.192660
0.193335, 1019.646571
0.193599, 1019.306175
0.193867, 1019.741868
0.194139, 1019.859703
0.194402, 1020.284990
0.194673, 1020.007400
0.194926, 1019.387912
0.195201, 1021.562505
0.195495, 1020.816242
0.195737, 1020.156525
0.196036, 1021.934340
0.196307, 1021.262377
0.196582, 1021.254000
0.196856, 1021.582113
0.197111, 1020.620727
0.197378, 1021.906656
0.197643, 1021.695365
0.197917, 1022.146495
0.198202, 1022.729171
0.198467, 1022.371084
0.198746, 1022.715874
0.199011, 1022.463151
0.199265, 1023.576816
0.199571, 1023.183307
0.199835, 1023.044850
0.200115, 1023.485538
0.200386, 1023.674893
0.200660, 1023.679325
0.200930, 1023.717151
0.201221, 1024.364097
0.201493, 1024.330140
0.201781, 1024.848884
0.202031, 1023.446510
0.202312, 1025.505522
0.202603, 1024.520359
0.202855, 1024.175644
0.203159, 1026.183908
0.203452, 1025.465029
0.203730, 1025.158065
0.204012, 1025.568815
0.204293, 1025.525393
0.204551, 1025.465104
0.204837, 1026.151717
0.205106, 1026.017016
0.205392, 1026.648035
0.205664, 1026.028811
0.205911, 1025.799189
0.206232, 1027.559312
0.206484, 1026.120089
0.206778, 1027.644843
0.207064, 1027.347495
0.207339, 1026.971941
0.207612, 1027.363121
0.207893, 1027.694426
0.208171, 1027.589099
0.208444, 1028.020021
0.208721, 1027.847044
0.208996, 1028.203366
0.209292, 1028.513335
0.209551, 1027.448727
0.209826, 1029.223950
0.210134, 1029.073173
0.210410, 1028.827474
0.210696, 1028.832019
0.210971, 1029.204868
0.211257, 1028.960935
0.211522, 1028.649726
0.211801, 1030.228908
0.212099, 1029.528285
0.212378, 1029.778754
0.212658, 1029.638682
0.212938, 1029.896063
0.213219, 1030.348058
0.213500, 1030.528510
0.213784, 1030.608482
0.214071, 1030.380099
0.214340, 1030.250394
0.214613, 1031.391593
0.214928, 1031.444257
0.215180, 1030.118849
0.215490, 1032.038389
0.215772, 1031.486027
0.216053, 1031.282060
0.216340, 1031.655135
0.216614, 1031.456389
0.216895, 1031.462400
0.217167, 1031.707798
0.217443, 1032.132372
0.217726, 1032.394411
0.218005, 1032.133686
0.218285, 1032.319660
0.218569, 1032.613064
0.218846, 1032.412178
0.219110, 1032.726241
0.219426, 1034.346668
0.219707, 1033.155886
0.219984, 1032.996882
0.220267, 1033.156187
0.220518, 1032.678649
0.220840, 1034.577755
0.221134, 1033.993915
0.221418, 1033.825257
0.221696, 1033.633273
0.221988, 1034.384532
0.222273, 1034.380926
0.222552, 1033.930095
0.222820, 1034.220494
0.223152, 1035.389265
0.223433, 1034.407633
0.223731, 1035.413756
0.224010, 1034.593757
0.224295, 1035.018105
0.224577, 1034.787657
0.224860, 1035.167042
0.225156, 1035.231162
0.225415, 1034.934302
0.225734, 1036.568026
0.226041, 1035.647660
0.226302, 1035.569304
0.226615, 1036.187852
0.226900, 1035.705469
0.227187, 1035.904064
0.227471, 1036.287845
0.227755, 1036.250432
0.228031, 1036.200586
0.228322, 1036.494854
0.228617, 1036.778341
0.228883, 1035.664375
0.229172, 1037.547066
0.229502, 1037.835775
0.229762, 1036.043761
0.230066, 1038.239651
0.230359, 1037.360341
0.230643, 1037.326009
0.230932, 1037.525054
0.231221, 1037.961160
0.231509, 1037.850274
0.231796, 1037.643753
0.232091, 1038.516678
0.232386, 1038.249756
0.232676, 1038.199008
0.232976, 1038.431560
0.233275, 1038.229284
0.233561, 1038.346969
0.233859, 1038.868079
0.234136, 1037.918451
0.234420, 1039.526595
0.234749, 1039.354143
0.235013, 1038.100406
0.235333, 1040.113177
0.235631, 1039.014462
0.235924, 1039.234393
0.236215, 1039.459995
0.236501, 1039.304447
0.236793, 1039.930772
0.237080, 1039.681542
0.237370, 1040.363647
0.237670, 1040.492525
0.237931, 1038.984862
0.238267, 1041.531741
0.238571, 1040.392232
0.238869, 1040.498197
0.239166, 1040.392532
0.239451, 1040.472579
0.239751, 1040.685110
0.240030, 1040.149763
0.240312, 1041.048569
0.240651, 1041.622793
0.240946, 1040.750620
0.241240, 1040.953985
0.241534, 1040.989933
0.241828, 1041.760724
0.242132, 1041.549207
0.242418, 1040.807190
0.242699, 1042.146045
0.243031, 1042.177147
0.243324, 1041.762415
0.243627, 1042.164601
0.243925, 1041.737172
0.244224, 1042.038690
0.244524, 1042.133499
0.244818, 1042.112426
0.245121, 1042.332545
0.245405, 1042.036361
0.245690, 1042.439712
0.246030, 1043.158102
0.246297, 1041.493614
0.246615, 1043.787882
0.246918, 1042.824731
0.247215, 1042.596124
0.247523, 1043.239238
0.247819, 1043.096199
0.248123, 1043.343851
0.248421, 1043.061791
0.248721, 1043.279017
0.249017, 1043.210202
0.249314, 1043.564270
0.249612, 1044.111412
0.249919, 1043.479453
0.250190, 1042.935279
0.250528, 1045.155248
0.250836, 1043.538953
0.251138, 1044.900308
0.251478, 1044.531928
0.251779, 1044.101420
0.252082, 1044.216625
0.252383, 1044.340320
0.252687, 1044.562542
0.252996, 1044.640598
0.253301, 1044.617647
0.253616, 1044.792465
0.253930, 1045.129066
0.254232, 1044.812561
0.254543, 1045.294343
0.254838, 1045.066787
0.255122, 1043.798137
0.255424, 1046.064157
0.255756, 1045.500000
0.256016, 1044.267448
0.256368, 1045.863647
0.256676, 1045.619375
0.256981, 1045.522162
0.257283, 1045.564571
0.257591, 1045.903275
0.257891, 1045.675644
0.258197, 1046.048193
0.258498, 1045.716475
0.258811, 1045.890654
0.259120, 1046.374953
0.259443, 1046.525693
0.259748, 1046.088686
0.260062, 1046.588573
0.260369, 1046.235707
0.260665, 1045.800729
0.260985, 1047.721696
0.261321, 1046.630268
0.261598, 1046.364661
0.261953, 1047.317670
0.262263, 1046.795094
0.262576, 1047.086733
0.262878, 1046.619525
0.263200, 1047.048869
0.263513, 1047.316505
0.263824, 1046.930922
0.264139, 1047.304185
0.264453, 1047.319210
0.264753, 1046.978439
0.265070, 1047.498310
0.265374, 1047.456127
0.265684, 1047.209038
0.265978, 1046.984825
0.266316, 1048.521298
0.266655, 1047.433326
0.266981, 1048.030802
0.267306, 1047.912253
0.267618, 1047.596537
0.267932, 1047.909098
0.268234, 1047.347532
0.268524, 1048.255503
0.268876, 1048.580009
0.269186, 1048.273420
0.269516, 1048.479491
0.269827, 1048.255803
0.270151, 1048.617271
0.270469, 1048.075689
0.270765, 1048.194313
0.271118, 1049.617384
0.271435, 1048.365262
0.271766, 1049.005146
0.272090, 1048.468485
0.272419, 1049.316092
0.272733, 1048.492976
0.273050, 1048.821388
0.273376, 1049.322515
0.273668, 1048.335324
0.274009, 1050.161521
0.274345, 1049.384081
0.274664, 1048.839043
0.274989, 1048.864435
0.275279, 1048.416685
0.275611, 1050.365938
0.275953, 1049.428330
0.276272, 1049.312786
0.276601, 1049.206671
0.276923, 1049.761100
0.277257, 1049.918113
0.277569, 1049.143904
0.277900, 1049.957516
0.278223, 1049.555668
0.278541, 1049.263767
0.278860, 1049.887386
0.279193, 1049.854594
0.279488, 1049.191346
0.279858, 1051.633987
0.280179, 1049.319510
0.280491, 1050.452070
0.280847, 1050.378484
0.281176, 1049.877620
0.281502, 1050.097250
0.281816, 1050.331230
0.282150, 1050.240177
0.282474, 1050.318609
0.282795, 1050.253174
0.283138, 1050.712944
0.283480, 1050.792690
0.283800, 1050.292803
0.284135, 1050.797085
0.284467, 1050.375254
0.284765, 1049.480054
0.285132, 1052.074600
0.285455, 1049.837390
0.285796, 1051.869319
0.286150, 1050.719555
0.286486, 1050.822703
0.286816, 1050.746262
0.287159, 1051.154909
0.287497, 1051.113741
0.287829, 1050.922019
0.288162, 1050.967809
0.288487, 1050.773759
0.288824, 1051.274848
0.289164, 1051.220269
0.289501, 1051.359965
0.289838, 1051.063181
0.290187, 1051.426189
0.290522, 1050.932086
0.290833, 1051.220645
0.291222, 1052.194426
0.291531, 1050.504508
0.291880, 1052.424273
0.292237, 1051.593907
0.292569, 1051.277289
0.292915, 1051.461423
0.293245, 1051.335812
0.293580, 1051.189618
0.293922, 1051.458568
0.294259, 1051.544474
0.294600, 1051.793892
0.294945, 1051.850612
0.295256, 1050.251859
0.295592, 1052.180753
0.295964, 1051.983472
0.296266, 1050.531816
0.296653, 1052.702539
0.297010, 1051.932499
0.297355, 1051.928330
0.297696, 1051.557021
0.298037, 1051.943580
0.298382, 1051.966757
0.298730, 1051.828676
0.299071, 1051.666404
0.299419, 1051.872098
0.299761, 1051.960521
0.300112, 1052.362482
0.300462, 1052.089287
0.300792, 1051.306326
0.301128, 1052.792841
0.301520, 1052.443618
0.301842, 1051.415483
0.302232, 1053.110660
0.302584, 1052.039591
0.302938, 1052.242769
0.303285, 1051.808053
0.303635, 1052.378784
0.303981, 1051.981219
0.304318, 1051.753174
0.304666, 1052.207460
0.305023, 1052.336376
0.305366, 1051.900233
0.305728, 1052.338780
0.306071, 1051.656412
0.306417, 1052.052663
0.306800, 1052.885358
0.307137, 1051.779806
0.307508, 1053.588724
0.307893, 1052.223988
0.308220, 1051.617459
0.308622, 1052.962625
0.308994, 1052.547217
0.309355, 1052.288371
0.309715, 1052.077981
0.310055, 1052.018706
0.310416, 1052.097851
0.310780, 1052.351251
0.311132, 1052.477312
0.311502, 1052.348246
0.311862, 1052.297987
0.312219, 1052.480618
0.312591, 1052.490947
0.312926, 1051.365375
0.313298, 1053.436331
0.313685, 1052.123019
0.314027, 1052.619638
0.314201, 1024.644279
0.314274, 1032.677973
0.314356, 1040.455864
0.314466, 1048.173991
0.314594, 1053.675569
0.314750, 1057.663023
0.314954, 1059.664526
0.315204, 1060.550034
0.315491, 1060.459920
0.315792, 1059.416761
0.316076, 1058.156487
0.316437, 1059.453497
0.316772, 1057.108707
0.317110, 1057.092179
0.317443, 1056.017392
0.317775, 1056.175644
0.318126, 1055.572121
0.318458, 1054.799376
0.318781, 1054.724777
0.319158, 1055.207948
0.319500, 1054.375028
0.319849, 1054.282736
0.320187, 1053.861318
0.320536, 1054.133386
0.320892, 1053.863083
0.321222, 1052.651266
0.321566, 1054.588160
0.321932, 1053.199008
0.322281, 1053.030388
0.322629, 1053.178837
0.322966, 1052.536436
0.323320, 1053.440087
0.323669, 1052.986102
0.324014, 1053.074412
0.324373, 1053.282999
0.324710, 1052.145707
0.325064, 1053.934716
0.325448, 1053.095184
0.325769, 1051.419615
0.326140, 1053.359740
0.326494, 1052.389866
0.326848, 1052.709939
0.327205, 1052.582601
0.327554, 1052.441139
0.327899, 1052.027346
0.328239, 1052.215987
0.328600, 1052.576854
0.328945, 1052.018556
0.329282, 1052.322290
0.329671, 1052.736496
0.330015, 1051.676809
0.330378, 1052.431222
0.330728, 1051.822665
0.331085, 1052.005935
0.331434, 1051.789648
0.331799, 1052.007926
0.332156, 1051.539704
0.332480, 1051.700962
0.332884, 1052.307678
0.333256, 1051.720457
0.333619, 1051.708286
0.333965, 1051.236271
0.334328, 1051.526332
0.334682, 1051.486665
0.335049, 1051.814890
0.335409, 1051.181391
0.335738, 1050.704004
0.336138, 1052.239952
0.336503, 1050.859965
0.336870, 1051.390842
0.337238, 1050.899745
0.337595, 1051.010968
0.337972, 1051.483735
0.338321, 1049.838968
0.338695, 1052.027346
0.339089, 1050.878108
0.339464, 1050.715724
0.339843, 1050.838254
0.340205, 1050.541207
0.340566, 1050.262865
0.340914, 1050.137105
0.341278, 1050.320074
0.341648, 1050.215236
0.341987, 1049.278078
0.342396, 1051.368905
0.342751, 1049.156450
0.343127, 1050.935166
0.343520, 1049.826272
0.343898, 1050.186275
0.344274, 1049.688904
0.344648, 1049.937045
0.345022, 1050.065998
0.345395, 1049.441815
0.345774, 1049.998648
0.346168, 1049.679588
0.346549, 1049.308880
0.346932, 1049.579596
0.347322, 1049.470889
0.347706, 1049.105965
0.348052, 1048.435843
0.348474, 1050.430997
0.348857, 1048.207084
0.349232, 1049.611825
0.349661, 1049.232439
0.350051, 1048.587334
0.350435, 1048.494178
0.350820, 1048.263053
0.351201, 1048.142514
0.351594, 1048.578469
0.351985, 1048.345316
0.352374, 1048.026745
0.352771, 1048.120314
0.353160, 1047.797724
0.353551, 1047.611224
0.353915, 1047.128052
0.354338, 1048.937721
0.354758, 1047.818609
0.355152, 1047.419428
0.355553, 1047.281722
0.355956, 1047.368530
0.356356, 1047.095898
0.356767, 1047.092292
0.357163, 1046.877733
0.357526, 1045.789798
0.357967, 1047.926827
0.358390, 1046.719180
0.358785, 1046.537225
0.359216, 1046.557096
0.359634, 1046.100856
0.360040, 1045.717377
0.360447, 1045.903125
0.360858, 1046.093156
0.361248, 1044.896702
0.361643, 1046.010480
0.362095, 1045.785365
0.362511, 1045.022162
0.362928, 1045.065097
0.363338, 1045.209676
0.363749, 1044.530388
0.364141, 1044.064157
0.364547, 1045.530163
0.364995, 1044.644542
0.365399, 1044.069228
0.365812, 1043.859252
0.366226, 1044.109796
0.366650, 1044.011494
0.367043, 1042.657915
0.367470, 1044.612801
0.367919, 1043.257081
0.368346, 1042.961423
0.368777, 1043.155097
0.369195, 1042.584629
0.369608, 1042.422320
0.370036, 1042.775299
0.370450, 1041.842085
0.370842, 1042.070243
0.371301, 1043.305274
0.371746, 1041.856885
0.372181, 1041.533732
0.372606, 1041.570769
0.373029, 1041.247014
0.373439, 1041.180039
0.373886, 1041.249380
0.374282, 1039.623732
0.374730, 1041.528285
0.375180, 1040.349035
0.375613, 1040.011983
0.376043, 1040.080009
0.376469, 1039.802081
0.376917, 1039.860266
0.377344, 1038.797949
0.377747, 1039.203967
0.378232, 1039.384644
0.378657, 1038.711291
0.379092, 1038.251822
0.379524, 1038.264067
0.379966, 1038.043385
0.380380, 1037.391255
0.380783, 1037.704230
0.381267, 1038.384982
0.381702, 1036.623169
0.382134, 1037.388964
0.382598, 1037.092593
0.383041, 1036.500225
0.383490, 1036.511081
0.383924, 1035.543235
0.384379, 1036.252235
0.384820, 1035.449703
0.385255, 1035.195290
0.385703, 1035.142514
0.386114, 1033.875141
0.386535, 1035.265870
0.387030, 1034.743220
0.387471, 1033.806401
0.387913, 1033.481181
0.388355, 1033.441627
0.388805, 1033.204755
0.389254, 1032.599617
0.389707, 1032.742243
0.390171, 1032.143002
0.390594, 1031.281046
0.391039, 1032.660657
0.391504, 1030.924686
0.391930, 1031.583878
0.392418, 1030.619337
0.392872, 1030.343663
0.393317, 1029.819736
0.393762, 1029.648674
0.394202, 1029.188679
0.394658, 1029.690031
0.395123, 1028.964841
0.395569, 1027.857899
0.396031, 1028.269326
0.396476, 1027.418789
0.396923, 1026.905454
0.397377, 1026.173052
0.397802, 1025.283600
0.398288, 1026.789685
0.398772, 1024.625122
0.399206, 1024.260273
0.399750, 1023.988393
0.400226, 1021.947825
0.400776, 1020.873526
0.401371, 1017.818759
0.401929, 1015.187815
0.402433, 1013.063594
0.402905, 1011.896214
0.403403, 1011.393021
0.403771, 1008.154008