File: Original_Data/Stress_Strain/SR/18-325_RT_SRonly.csv
Eng_Strain, Eng_Stress (MPa)
0.000026, 5.113910
0.000083, 16.107669
0.000157, 31.531001
0.000218, 43.343995
0.000275, 54.569725
0.000330, 65.103041
0.000389, 76.916077
0.000445, 88.086182
0.000496, 97.790933
0.000562, 111.533538
0.000615, 121.841672
0.000675, 133.763624
0.000731, 144.426741
0.000785, 155.556497
0.000845, 167.194674
0.000899, 178.213074
0.000957, 189.294395
0.001013, 200.218844
0.001066, 211.137011
0.001122, 222.468853
0.001178, 233.664996
0.001236, 245.070642
0.001295, 256.519930
0.001344, 266.543766
0.001405, 278.088039
0.001461, 288.831696
0.001512, 299.369139
0.001572, 310.337857
0.001626, 320.991170
0.001670, 330.220847
0.001739, 343.679371
0.001784, 352.702379
0.001835, 363.070541
0.001890, 373.018317
0.001943, 383.569259
0.001994, 393.709845
0.002045, 403.701086
0.002095, 413.293726
0.002143, 423.446679
0.002200, 433.600120
0.002236, 440.680337
0.002294, 452.070255
0.002343, 461.933617
0.002394, 471.420968
0.002448, 482.289328
0.002497, 491.982145
0.002548, 501.830019
0.002602, 511.999549
0.002639, 519.981431
0.002712, 533.827463
0.002750, 541.146036
0.002813, 552.407360
0.002860, 561.830921
0.002914, 571.135549
0.002967, 580.945382
0.003019, 590.246551
0.003076, 598.154983
0.003141, 607.254107
0.003215, 615.796790
0.003311, 624.841484
0.003419, 631.962335
0.003545, 638.477690
0.003680, 644.535654
0.003835, 650.200616
0.004002, 655.400782
0.004179, 660.019096
0.004378, 664.132391
0.004589, 668.085855
0.004819, 671.500996
0.005054, 673.715070
0.005303, 676.115739
0.005575, 678.720220
0.005847, 680.497500
0.006127, 681.746570
0.006417, 683.264256
0.006701, 684.459647
0.006963, 685.922189
0.007324, 688.582115
0.007583, 688.071345
0.007878, 690.090591
0.008163, 690.904522
0.008461, 692.534075
0.008757, 693.620456
0.009051, 693.977333
0.009347, 695.389016
0.009639, 696.109875
0.009935, 697.616134
0.010235, 698.369319
0.010532, 699.217006
0.010819, 700.387550
0.011112, 700.981205
0.011396, 701.897079
0.011683, 702.988535
0.011968, 703.541292
0.012259, 704.729467
0.012515, 706.352517
0.012877, 706.748149
0.013138, 707.090291
0.013431, 708.778822
0.013709, 708.966545
0.013982, 710.379882
0.014256, 711.027666
0.014533, 712.076871
0.014813, 712.611923
0.015094, 713.590948
0.015370, 714.700222
0.015646, 715.533286
0.015926, 716.407022
0.016197, 717.339962
0.016469, 718.148855
0.016733, 718.229410
0.017002, 719.336090
0.017268, 720.546818
0.017545, 721.430553
0.017824, 722.004248
0.018099, 723.240875
0.018361, 724.018005
0.018634, 725.099275
0.018894, 725.561516
0.019136, 725.635455
0.019423, 728.446604
0.019692, 726.954253
0.019941, 729.229448
0.020210, 729.362854
0.020462, 730.273165
0.020722, 731.263730
0.020973, 732.039883
0.021232, 732.759463
0.021497, 733.919295
0.021749, 734.550389
0.022005, 735.343683
0.022264, 736.158328
0.022519, 737.280871
0.022767, 737.328008
0.023026, 738.712438
0.023283, 739.394843
0.023527, 740.092095
0.023790, 741.473894
0.024046, 741.848401
0.024266, 742.663459
0.024589, 744.763561
0.024814, 743.645190
0.025079, 745.381611
0.025325, 745.613164
0.025568, 746.591362
0.025819, 747.421268
0.026067, 748.394655
0.026316, 749.275533
0.026554, 748.846333
0.026779, 750.720595
0.027029, 751.103409
0.027270, 752.354359
0.027517, 753.141525
0.027758, 753.777619
0.028010, 754.835282
0.028254, 755.601812
0.028503, 756.069579
0.028753, 757.353043
0.029002, 758.007142
0.029239, 757.878811
0.029475, 760.724016
0.029750, 759.762771
0.029986, 761.090291
0.030234, 761.808631
0.030468, 762.352404
0.030701, 763.315566
0.030941, 764.223809
0.031192, 765.165169
0.031438, 766.010224
0.031676, 766.572154
0.031918, 767.312559
0.032156, 768.077886
0.032393, 768.939856
0.032641, 769.569071
0.032881, 770.670338
0.033116, 771.262715
0.033355, 771.942939
0.033592, 772.544600
0.033837, 773.447844
0.034065, 773.817727
0.034298, 774.816938
0.034542, 775.762921
0.034748, 774.868022
0.035024, 778.911288
0.035254, 777.063076
0.035486, 779.064504
0.035731, 779.659700
0.035961, 780.008007
0.036200, 781.220840
0.036431, 781.949667
0.036663, 782.052738
0.036893, 783.028606
0.037124, 783.488554
0.037356, 784.196519
0.037585, 785.386272
0.037822, 786.088637
0.038061, 787.107920
0.038299, 787.536143
0.038533, 788.217607
0.038759, 789.068752
0.038987, 789.437131
0.039222, 790.474082
0.039452, 791.221404
0.039680, 791.948164
0.039917, 792.556215
0.040121, 793.013532
0.040409, 795.283088
0.040621, 794.439387
0.040858, 795.722700
0.041085, 796.031425
0.041310, 796.504078
0.041548, 797.846258
0.041783, 798.742886
0.042017, 799.214074
0.042246, 799.630004
0.042480, 800.744014
0.042713, 801.585911
0.042939, 801.732361
0.043174, 802.657520
0.043405, 803.564598
0.043630, 803.598880
0.043867, 804.771342
0.044103, 805.703830
0.044308, 804.547495
0.044556, 808.116603
0.044799, 806.756682
0.045015, 808.518926
0.045250, 808.783258
0.045470, 809.512574
0.045700, 810.185731
0.045915, 810.176709
0.046141, 811.139195
0.046376, 812.197534
0.046607, 812.989024
0.046834, 813.507086
0.047060, 814.213623
0.047288, 814.462241
0.047516, 815.522310
0.047749, 816.268391
0.047973, 817.241514
0.048211, 817.709619
0.048444, 818.208285
0.048670, 818.998609
0.048908, 819.586024
0.049144, 820.223208
0.049373, 821.197346
0.049616, 821.831673
0.049845, 822.077397
0.050071, 822.684772
0.050298, 823.061534
0.050494, 823.310717
0.050783, 825.814908
0.050993, 824.772544
0.051220, 826.117769
0.051456, 826.330827
0.051673, 827.414164
0.051897, 828.031312
0.052129, 828.847949
0.052355, 829.391610
0.052583, 829.944442
0.052817, 830.518250
0.053050, 831.047250
0.053275, 831.348833
0.053504, 832.388640
0.053738, 833.062173
0.053962, 833.452994
0.054187, 834.428861
0.054413, 834.572605
0.054635, 835.281209
0.054838, 836.056573
0.055110, 836.686652
0.055320, 836.680337
0.055554, 838.003458
0.055772, 838.183250
0.056004, 839.381310
0.056234, 840.006090
0.056460, 840.340488
0.056691, 840.616697
0.056918, 841.682066
0.057153, 842.191257
0.057388, 842.965380
0.057622, 843.555313
0.057864, 844.320377
0.058089, 844.206142
0.058322, 845.167913
0.058562, 846.195016
0.058791, 846.595948
0.059028, 846.464835
0.059226, 847.356050
0.059486, 847.976356
0.059705, 848.377852
0.059932, 849.044206
0.060152, 850.143706
0.060380, 850.223208
0.060612, 851.037214
0.060836, 851.509642
0.061064, 852.170469
0.061311, 853.005902
0.061519, 852.190730
0.061749, 855.068263
0.061998, 854.421456
0.062214, 854.786415
0.062450, 855.554712
0.062668, 856.139120
0.062907, 856.650754
0.063141, 857.610721
0.063365, 858.017818
0.063599, 858.205691
0.063827, 858.776416
0.064057, 859.369056
0.064273, 859.673947
0.064503, 860.458069
0.064739, 861.349998
0.064965, 861.515205
0.065198, 862.175507
0.065424, 862.459723
0.065653, 863.120964
0.065892, 863.947074
0.066109, 863.890388
0.066338, 866.156411
0.066596, 865.705484
0.066820, 866.310754
0.067067, 867.218472
0.067287, 866.972898
0.067510, 867.391610
0.067746, 868.556516
0.067972, 869.041950
0.068196, 868.920610
0.068427, 869.878698
0.068652, 870.405443
0.068879, 870.550690
0.069108, 871.196970
0.069342, 871.919107
0.069571, 872.505432
0.069803, 872.963237
0.070032, 873.485998
0.070263, 873.820622
0.070495, 874.300981
0.070732, 874.931587
0.070966, 875.516934
0.071199, 875.807728
0.071438, 876.429275
0.071674, 877.148931
0.071904, 877.462730
0.072145, 878.094839
0.072370, 878.361050
0.072603, 879.052438
0.072830, 879.354847
0.073060, 880.254783
0.073296, 880.228433
0.073511, 879.566139
0.073758, 882.306582
0.074011, 881.605533
0.074235, 882.355186
0.074471, 882.729391
0.074711, 883.831974
0.074946, 884.223885
0.075171, 884.283352
0.075408, 885.323009
0.075642, 885.436379
0.075872, 885.875991
0.076110, 886.492200
0.076336, 886.830433
0.076572, 887.148968
0.076804, 887.479420
0.077040, 888.232981
0.077266, 888.831034
0.077501, 889.122731
0.077732, 889.717851
0.077967, 890.375672
0.078195, 890.519641
0.078426, 891.314889
0.078664, 891.565763
0.078883, 891.732060
0.079150, 893.245574
0.079379, 892.274180
0.079620, 894.067098
0.079844, 893.445476
0.080090, 894.581551
0.080317, 894.653874
0.080545, 895.017780
0.080778, 895.780513
0.081011, 896.155622
0.081238, 896.658234
0.081475, 897.119347
0.081707, 897.432620
0.081942, 898.190730
0.082177, 898.315265
0.082415, 899.092320
0.082655, 899.412134
0.082893, 899.784648
0.083128, 899.965154
0.083366, 901.013645
0.083603, 901.141525
0.083832, 901.113784
0.084074, 902.312032
0.084313, 902.566139
0.084540, 902.532872
0.084769, 904.163252
0.085032, 904.144157
0.085247, 903.439650
0.085491, 905.046611
0.085705, 904.148855
0.085945, 905.531895
0.086173, 905.318423
0.086411, 906.875089
0.086657, 907.090178
0.086870, 906.421268
0.087118, 908.571890
0.087379, 908.472879
0.087602, 908.607300
0.087856, 909.197421
0.088085, 909.472353
0.088331, 910.218509
0.088553, 910.045183
0.088800, 911.057587
0.089036, 910.840281
0.089264, 910.844040
0.089507, 912.040597
0.089732, 912.059317
0.089971, 913.250949
0.090221, 912.990377
0.090439, 913.800774
0.090708, 913.663421
0.090919, 913.594970
0.091153, 914.568131
0.091388, 915.120663
0.091626, 915.892869
0.091870, 916.031839
0.092107, 916.095741
0.092341, 916.495922
0.092575, 916.875202
0.092817, 917.721535
0.093052, 918.335601
0.093290, 918.067060
0.093523, 918.851220
0.093769, 919.298425
0.093990, 918.599256
0.094244, 921.264820
0.094489, 919.999850
0.094726, 920.638950
0.094959, 920.853776
0.095207, 921.632861
0.095440, 921.880201
0.095672, 922.183588
0.095916, 922.869000
0.096150, 923.158554
0.096381, 923.191069
0.096629, 924.016239
0.096869, 924.336616
0.097106, 924.743488
0.097354, 924.980491
0.097600, 925.510469
0.097840, 925.756870
0.098078, 926.095628
0.098310, 926.690824
0.098550, 927.122129
0.098788, 927.155020
0.099007, 927.239747
0.099272, 929.151111
0.099523, 928.132504
0.099757, 928.759275
0.100008, 929.560275
0.100239, 929.105139
0.100488, 930.437845
0.100731, 930.593993
0.100970, 930.727098
0.101204, 930.734353
0.101443, 931.234861
0.101685, 932.018344
0.101924, 932.210653
0.102164, 932.569785
0.102417, 933.465211
0.102616, 931.909785
0.102896, 934.458896
0.103126, 933.576288
0.103364, 934.373454
0.103597, 934.468669
0.103829, 934.885314
0.104068, 935.428749
0.104303, 935.976506
0.104548, 936.202947
0.104793, 936.654663
0.105037, 936.945269
0.105279, 937.051348
0.105528, 937.603090
0.105766, 938.230350
0.106003, 938.096079
0.106236, 938.289253
0.106478, 939.114874
0.106719, 939.282637
0.106947, 939.096530
0.107202, 940.355223
0.107423, 939.354885
0.107692, 941.607262
0.107934, 940.797617
0.108177, 941.568958
0.108421, 941.738676
0.108663, 941.946886
0.108903, 942.240349
0.109139, 942.381310
0.109379, 942.861294
0.109609, 943.173777
0.109861, 944.242153
0.110093, 943.651881
0.110336, 944.378190
0.110577, 944.846371
0.110820, 945.339962
0.111060, 945.190918
0.111298, 945.555013
0.111542, 946.253768
0.111784, 945.417697
0.112024, 947.643649
0.112283, 947.450400
0.112522, 947.380596
0.112766, 947.681991
0.113005, 948.158666
0.113254, 948.667444
0.113493, 948.647483
0.113735, 948.972146
0.113984, 949.769161
0.114234, 949.570349
0.114449, 949.968838
0.114729, 951.240011
0.114963, 950.470661
0.115216, 951.412547
0.115445, 950.988836
0.115691, 951.589182
0.115926, 951.587039
0.116175, 952.494643
0.116415, 952.417848
0.116654, 952.802240
0.116900, 953.604067
0.117151, 953.737661
0.117389, 953.617111
0.117641, 954.471338
0.117883, 954.601925
0.118132, 954.959854
0.118383, 955.354471
0.118616, 955.203361
0.118856, 955.743149
0.119098, 955.584483
0.119327, 957.105702
0.119589, 956.732587
0.119822, 956.945420
0.120079, 957.719693
0.120312, 957.382852
0.120558, 957.824757
0.120801, 958.295117
0.121043, 958.464872
0.121284, 958.964102
0.121529, 959.216968
0.121770, 959.565763
0.122016, 960.001203
0.122262, 959.859640
0.122510, 960.191069
0.122759, 961.147239
0.123006, 960.794046
0.123247, 961.135285
0.123496, 962.222080
0.123742, 961.413600
0.123973, 962.664850
0.124246, 962.638875
0.124459, 961.273465
0.124728, 963.693531
0.124974, 962.471714
0.125216, 963.790362
0.125460, 963.674961
0.125707, 964.106868
0.125958, 964.647371
0.126198, 964.983536
0.126444, 964.863775
0.126687, 965.307221
0.126935, 965.838928
0.127176, 965.763824
0.127425, 966.153742
0.127673, 966.555313
0.127913, 966.501973
0.128159, 966.872571
0.128405, 967.499117
0.128650, 967.754539
0.128897, 967.632447
0.129134, 968.548998
0.129386, 968.604180
0.129628, 968.464271
0.129883, 969.337631
0.130126, 969.281848
0.130350, 969.658084
0.130634, 970.282825
0.130883, 969.918054
0.131132, 971.015374
0.131369, 969.925723
0.131620, 971.259858
0.131876, 971.635680
0.132120, 971.602263
0.132377, 972.131113
0.132615, 972.078224
0.132867, 972.264256
0.133121, 972.830621
0.133372, 972.789573
0.133611, 973.337631
0.133863, 973.360486
0.134109, 973.784160
0.134353, 974.201631
0.134602, 974.077698
0.134848, 974.012254
0.135085, 975.016126
0.135372, 975.653009
0.135597, 974.109461
0.135862, 976.673420
0.136128, 976.288125
0.136355, 975.839417
0.136613, 976.571815
0.136842, 976.224711
0.137097, 976.675112
0.137347, 977.286772
0.137588, 977.436455
0.137840, 978.016239
0.138088, 977.980115
0.138338, 978.197572
0.138594, 978.704169
0.138842, 978.866256
0.139091, 979.069616
0.139337, 979.470285
0.139583, 979.721873
0.139826, 979.367928
0.140081, 980.136300
0.140309, 978.861068
0.140566, 981.436455
0.140837, 981.158817
0.141054, 980.176897
0.141335, 981.976807
0.141582, 981.302485
0.141822, 981.651205
0.142073, 981.914183
0.142325, 982.555201
0.142569, 982.306018
0.142819, 982.940495
0.143072, 983.032252
0.143324, 983.355223
0.143578, 983.926625
0.143824, 983.752847
0.144082, 984.176258
0.144330, 984.348720
0.144583, 984.716009
0.144840, 984.880465
0.145084, 985.357930
0.145340, 985.500620
0.145588, 985.215690
0.145834, 985.950983
0.146091, 986.220953
0.146301, 985.510694
0.146598, 987.064805
0.146845, 986.817953
0.147100, 987.285193
0.147351, 987.398639
0.147604, 987.488704
0.147854, 987.946998
0.148099, 987.586776
0.148350, 988.345863
0.148612, 988.948991
0.148854, 988.358193
0.149114, 989.330451
0.149369, 989.347856
0.149612, 989.216818
0.149865, 989.372251
0.150123, 989.922941
0.150377, 990.239597
0.150641, 990.687817
0.150889, 990.391911
0.151146, 990.988310
0.151400, 990.926926
0.151626, 990.723114
0.151924, 992.655603
0.152162, 991.735894
0.152423, 992.272751
0.152670, 992.046311
0.152921, 992.404240
0.153172, 992.219938
0.153421, 992.737172
0.153668, 993.039432
0.153920, 992.861407
0.154173, 993.667143
0.154423, 993.980077
0.154677, 993.970605
0.154937, 994.688757
0.155187, 994.769086
0.155440, 995.112469
0.155693, 994.853588
0.155941, 995.102094
0.156199, 995.469909
0.156455, 995.918280
0.156683, 994.655716
0.156973, 997.015149
0.157225, 995.675112
0.157489, 996.890200
0.157735, 996.409390
0.157979, 997.055069
0.158232, 997.018231
0.158475, 997.238545
0.158733, 997.883021
0.158977, 997.412848
0.159237, 998.537233
0.159483, 997.786302
0.159749, 998.861369
0.160017, 998.653084
0.160245, 998.438334
0.160547, 999.938992
0.160797, 999.102545
0.161057, 999.749201
0.161315, 999.712138
0.161566, 999.990302
0.161826, 1000.122693
0.162083, 1000.636018
0.162341, 1001.058678
0.162600, 1001.025862
0.162849, 1000.895049
0.163102, 1000.712213
0.163354, 1000.752171
0.163584, 1001.507612
0.163874, 1002.551329
0.164117, 1001.103823
0.164384, 1002.898245
0.164635, 1002.191595
0.164886, 1002.782167
0.165148, 1003.068263
0.165405, 1003.425666
0.165661, 1003.194752
0.165914, 1003.407022
0.166179, 1004.394843
0.166432, 1004.089501
0.166686, 1004.077961
0.166948, 1004.425967
0.167220, 1005.226967
0.167480, 1004.684697
0.167743, 1005.124986
0.168015, 1005.599030
0.168255, 1004.102846
0.168534, 1007.045672
0.168798, 1005.596173
0.169040, 1006.036086
0.169295, 1005.842273
0.169545, 1006.670789
0.169807, 1006.388415
0.170065, 1006.957411
0.170331, 1006.932451
0.170584, 1007.051911
0.170851, 1007.727850
0.171106, 1007.140661
0.171358, 1007.796715
0.171608, 1007.874375
0.171864, 1008.291170
0.172132, 1008.751081
0.172384, 1008.795625
0.172656, 1008.849002
0.172897, 1007.761192
0.173171, 1009.813066
0.173440, 1008.981168
0.173687, 1009.177198
0.173947, 1009.864602
0.174194, 1010.158102
0.174452, 1010.055783
0.174714, 1010.308913
0.174976, 1010.501034
0.175238, 1010.936924
0.175503, 1010.837236
0.175769, 1011.209751
0.176030, 1011.255422
0.176286, 1011.066346
0.176548, 1011.560839
0.176808, 1011.836071
0.177058, 1011.825734
0.177330, 1012.332143
0.177571, 1011.633162
0.177830, 1013.252603
0.178122, 1012.866932
0.178375, 1012.955231
0.178648, 1012.968312
0.178905, 1013.255460
0.179174, 1013.681126
0.179432, 1013.763711
0.179694, 1013.750742
0.179962, 1013.975304
0.180226, 1014.345938
0.180478, 1014.143931
0.180747, 1014.598391
0.181006, 1014.702665
0.181253, 1014.813818
0.181521, 1014.860655
0.181788, 1015.515393
0.182047, 1015.384205
0.182319, 1015.509003
0.182547, 1014.646055
0.182843, 1016.973386
0.183112, 1015.899147
0.183380, 1016.298914
0.183652, 1016.699094
0.183910, 1016.548359
0.184181, 1017.043341
0.184440, 1016.890576
0.184701, 1017.370146
0.184968, 1017.286359
0.185225, 1017.419990
0.185489, 1018.094613
0.185750, 1017.801827
0.186015, 1018.091005
0.186281, 1018.465887
0.186547, 1018.625794
0.186816, 1018.430778
0.187087, 1018.792091
0.187349, 1019.074653
0.187629, 1019.672781
0.187884, 1018.720483
0.188123, 1018.479044
0.188417, 1020.117130
0.188679, 1019.259896
0.188952, 1020.175356
0.189215, 1020.331128
0.189476, 1020.129083
0.189737, 1020.161335
0.190002, 1020.598316
0.190256, 1020.045033
0.190530, 1020.791302
0.190800, 1021.354734
0.191034, 1020.557494
0.191328, 1022.339774
0.191593, 1021.111040
0.191855, 1022.110251
0.192111, 1021.225200
0.192384, 1022.347254
0.192653, 1022.094689
0.192912, 1022.283314
0.193188, 1022.694508
0.193455, 1022.803631
0.193725, 1022.671390
0.193998, 1022.824681
0.194269, 1023.202195
0.194536, 1023.715446
0.194798, 1023.243694
0.195073, 1024.106642
0.195334, 1023.744766
0.195598, 1024.050596
0.195875, 1024.126377
0.196113, 1023.297260
0.196418, 1025.174116
0.196684, 1024.110664
0.196954, 1025.147615
0.197224, 1024.502500
0.197488, 1024.841108
0.197758, 1024.934030
0.198025, 1025.171109
0.198301, 1025.759914
0.198574, 1025.692215
0.198852, 1026.350186
0.199131, 1026.380371
0.199391, 1025.565350
0.199674, 1026.788633
0.199899, 1025.111341
0.200206, 1027.512386
0.200476, 1025.958426
0.200743, 1026.763974
0.201015, 1026.585723
0.201289, 1027.336691
0.201555, 1027.209262
0.201822, 1027.559824
0.202085, 1027.268804
0.202352, 1027.525843
0.202623, 1028.269857
0.202891, 1028.060068
0.203168, 1028.160020
0.203432, 1028.433485
0.203705, 1028.401045
0.203978, 1028.574597
0.204245, 1028.352592
0.204518, 1029.071721
0.204796, 1028.686689
0.205045, 1029.374056
0.205355, 1030.375672
0.205614, 1029.160696
0.205900, 1030.158516
0.206170, 1029.573131
0.206449, 1030.085291
0.206720, 1029.831072
0.206993, 1029.901966
0.207263, 1030.409089
0.207535, 1030.385370
0.207795, 1030.143292
0.208067, 1030.562944
0.208341, 1030.849152
0.208614, 1030.890915
0.208883, 1031.023418
0.209160, 1031.267977
0.209438, 1031.606661
0.209723, 1032.017366
0.209967, 1030.564222
0.210271, 1032.619968
0.210542, 1031.535729
0.210816, 1032.256776
0.211090, 1031.525166
0.211370, 1032.745142
0.211644, 1032.132541
0.211915, 1032.543172
0.212193, 1032.802428
0.212457, 1032.551554
0.212732, 1033.205240
0.213005, 1033.089163
0.213286, 1033.369357
0.213564, 1033.517122
0.213835, 1033.025523
0.214109, 1033.805962
0.214395, 1033.915649
0.214630, 1032.114574
0.214934, 1034.500545
0.215207, 1033.650002
0.215480, 1034.275758
0.215757, 1034.137428
0.216030, 1034.723603
0.216315, 1034.688794
0.216582, 1034.780664
0.216869, 1034.937977
0.217143, 1035.299778
0.217418, 1035.070631
0.217701, 1035.422960
0.217988, 1035.870015
0.218273, 1035.852009
0.218527, 1034.063414
0.218825, 1036.377927
0.219124, 1036.065744
0.219389, 1035.633387
0.219681, 1036.167500
0.219946, 1035.995113
0.220229, 1036.510055
0.220503, 1036.279668
0.220793, 1037.149231
0.221069, 1036.607638
0.221348, 1036.787355
0.221633, 1037.405330
0.221908, 1037.003721
0.222181, 1037.206856
0.222464, 1037.299365
0.222739, 1036.984363
0.223023, 1037.970417
0.223303, 1037.080442
0.223586, 1038.108973
0.223886, 1038.604819
0.224136, 1037.267301
0.224451, 1039.323723
0.224728, 1037.303913
0.224995, 1038.869338
0.225300, 1038.681389
0.225559, 1038.355261
0.225848, 1038.932263
0.226117, 1038.416494
0.226400, 1039.031575
0.226683, 1039.289667
0.226965, 1039.085629
0.227255, 1039.436642
0.227538, 1039.701613
0.227825, 1039.501522
0.228106, 1040.062812
0.228396, 1039.757471
0.228674, 1039.862158
0.228967, 1039.074465
0.229218, 1040.172875
0.229535, 1040.729955
0.229825, 1040.581137
0.230122, 1040.255761
0.230394, 1040.477540
0.230685, 1040.410743
0.230969, 1040.519829
0.231249, 1040.842424
0.231526, 1040.678720
0.231805, 1041.081908
0.232087, 1041.140811
0.232375, 1041.268616
0.232660, 1041.096831
0.232953, 1041.400030
0.233241, 1041.521031
0.233530, 1041.513025
0.233816, 1041.792768
0.234108, 1042.329361
0.234386, 1041.598917
0.234668, 1041.650603
0.234965, 1042.560200
0.235218, 1041.130812
0.235545, 1043.667970
0.235831, 1042.083036
0.236125, 1042.675149
0.236406, 1042.378115
0.236699, 1043.197609
0.236987, 1042.661580
0.237262, 1042.943728
0.237559, 1042.881254
0.237848, 1043.249784
0.238137, 1043.585460
0.238422, 1043.149795
0.238723, 1043.859302
0.239020, 1043.595873
0.239283, 1042.260196
0.239587, 1044.465211
0.239899, 1043.934631
0.240172, 1043.889411
0.240466, 1043.672969
0.240759, 1044.299064
0.241044, 1043.885351
0.241323, 1043.833327
0.241617, 1044.569898
0.241896, 1044.068113
0.242190, 1044.760929
0.242484, 1044.441341
0.242767, 1044.554186
0.243067, 1044.980040
0.243326, 1043.756757
0.243638, 1045.960568
0.243944, 1045.334624
0.244234, 1045.202684
0.244535, 1045.190881
0.244824, 1045.196895
0.245120, 1045.263918
0.245418, 1045.619178
0.245715, 1045.670300
0.246010, 1045.441078
0.246314, 1045.840995
0.246617, 1045.838214
0.246915, 1046.228207
0.247207, 1046.100741
0.247502, 1046.079803
0.247802, 1046.566778
0.248098, 1046.035485
0.248360, 1045.528286
0.248710, 1047.346653
0.249003, 1046.621622
0.249305, 1046.649964
0.249594, 1046.457317
0.249882, 1046.738902
0.250175, 1046.650190
0.250473, 1047.176897
0.250755, 1047.182686
0.251061, 1047.307371
0.251352, 1046.952599
0.251649, 1047.581701
0.251940, 1047.306093
0.252239, 1047.409052
0.252528, 1047.345600
0.252818, 1047.803669
0.253125, 1047.844191
0.253420, 1047.690448
0.253734, 1048.140849
0.254010, 1046.899222
0.254341, 1048.942638
0.254649, 1047.846183
0.254939, 1048.391084
0.255242, 1047.659399
0.255546, 1048.650979
0.255842, 1048.382927
0.256135, 1048.256362
0.256444, 1048.649137
0.256732, 1048.152389
0.257037, 1048.840958
0.257343, 1048.653836
0.257645, 1048.723941
0.257947, 1049.189565
0.258258, 1049.338909
0.258557, 1048.988986
0.258831, 1048.775251
0.259173, 1049.775589
0.259464, 1048.714017
0.259775, 1049.745104
0.260065, 1048.855956
0.260382, 1049.790625
0.260685, 1049.729091
0.260982, 1049.524715
0.261298, 1049.793933
0.261608, 1049.853099
0.261912, 1049.793407
0.262226, 1050.038417
0.262537, 1050.008608
0.262824, 1049.690862
0.263134, 1050.162839
0.263426, 1049.475736
0.263711, 1049.527121
0.264070, 1051.277976
0.264364, 1049.825508
0.264693, 1051.011916
0.264987, 1050.047589
0.265293, 1050.496598
0.265600, 1050.243168
0.265902, 1050.856595
0.266221, 1050.875390
0.266529, 1050.780213
0.266836, 1050.855167
0.267152, 1051.186220
0.267460, 1050.587340
0.267742, 1049.879901
0.268074, 1051.960907
0.268392, 1050.579371
0.268681, 1051.604631
0.269025, 1051.619892
0.269319, 1050.822088
0.269638, 1051.223283
0.269938, 1051.302071
0.270249, 1051.592790
0.270549, 1051.108409
0.270859, 1051.509980
0.271173, 1051.910649
0.271490, 1051.806150
0.271803, 1051.526520
0.272127, 1052.017103
0.272439, 1051.666429
0.272753, 1051.647446
0.273056, 1051.950269
0.273381, 1052.199977
0.273690, 1051.643837
0.274007, 1052.459572
0.274340, 1052.355524
0.274621, 1051.597564
0.274981, 1053.020111
0.275279, 1051.721573
0.275593, 1052.345111
0.275901, 1051.553396
0.276232, 1052.858174
0.276542, 1052.652370
0.276863, 1052.488291
0.277187, 1052.808969
0.277503, 1052.431154
0.277828, 1052.608164
0.278152, 1052.904710
0.278473, 1052.794798
0.278779, 1052.581814
0.279098, 1052.726610
0.279415, 1053.197872
0.279741, 1052.718302
0.280033, 1052.787392
0.280395, 1053.312672
0.280699, 1052.571251
0.281041, 1053.736233
0.281354, 1053.113634
0.281683, 1053.448070
0.282004, 1053.233169
0.282316, 1052.811375
0.282645, 1053.540202
0.282964, 1053.390219
0.283292, 1053.421569
0.283626, 1053.884750
0.283941, 1053.478330
0.284269, 1053.376349
0.284604, 1053.702665
0.284923, 1053.649889
0.285253, 1053.846634
0.285570, 1053.415179
0.285859, 1052.963726
0.286225, 1055.017818
0.286554, 1053.626320
0.286883, 1054.169304
0.287213, 1053.737999
0.287525, 1053.791227
0.287856, 1053.760102
0.288175, 1054.148630
0.288506, 1053.965305
0.288832, 1054.010224
0.289153, 1054.077999
0.289476, 1053.855618
0.289804, 1053.883209
0.290135, 1054.331579
0.290467, 1054.254708
0.290782, 1053.852460
0.291130, 1055.693756
0.291476, 1054.350825
0.291779, 1053.486825
0.292145, 1055.566741
0.292487, 1054.102507
0.292819, 1054.531030
0.293144, 1053.994286
0.293480, 1054.921024
0.293809, 1054.635530
0.294136, 1054.218509
0.294473, 1054.338984
0.294796, 1054.333684
0.295125, 1054.726986
0.295468, 1054.629290
0.295799, 1054.720896
0.296144, 1054.960982
0.296469, 1054.171372
0.296803, 1054.938015
0.297148, 1054.778446
0.297443, 1053.553133
0.297810, 1055.626132
0.298147, 1054.432432
0.298482, 1055.225501
0.298819, 1054.702778
0.299161, 1055.546329
0.299506, 1055.074992
0.299830, 1054.610645
0.300177, 1054.957599
0.300525, 1055.448709
0.300869, 1054.847348
0.301224, 1055.241514
0.301573, 1054.991730
0.301910, 1054.763109
0.302259, 1055.175732
0.302598, 1054.713566
0.302909, 1054.192084
0.303294, 1056.008420
0.303641, 1054.612675
0.303991, 1055.744803
0.304329, 1055.014134
0.304681, 1055.208247
0.305025, 1055.250912
0.305367, 1055.216855
0.305715, 1054.696162
0.306050, 1055.077435
0.306399, 1055.210691
0.306740, 1054.737774
0.307089, 1055.643311
0.307449, 1055.423787
0.307755, 1054.328647
0.308158, 1055.870391
0.308495, 1054.888358
0.308844, 1055.203022
0.309186, 1055.018231
0.309533, 1055.670714
0.309891, 1055.526971
0.310246, 1055.263542
0.310595, 1055.127204
0.310946, 1055.234748
0.311295, 1055.207608
0.311653, 1055.173439
0.312005, 1055.432921
0.312300, 1017.325715
0.312381, 1027.514904
0.312462, 1036.689358
0.312548, 1044.585611
0.312654, 1051.171447
0.312784, 1056.821599
0.312947, 1060.493290
0.313122, 1061.236252
0.313379, 1063.900011
0.313659, 1062.660038
0.313931, 1062.422546
0.314251, 1061.788595
0.314558, 1061.239184
0.314858, 1060.337481
0.315181, 1059.394354
0.315499, 1059.211856
0.315823, 1058.825471
0.316148, 1058.812765
0.316460, 1057.789084
0.316781, 1057.679848
0.317113, 1057.919783
0.317430, 1057.038041
0.317775, 1057.662820
0.318110, 1057.053077
0.318443, 1057.267301
0.318792, 1056.805736
0.319093, 1056.098147
0.319459, 1057.228846
0.319777, 1055.130850
0.320114, 1057.142879
0.320465, 1056.015186
0.320787, 1055.816825
0.321130, 1056.047100
0.321453, 1055.841183
0.321783, 1056.110401
0.322115, 1056.047852
0.322441, 1055.613239
0.322779, 1056.012405
0.323121, 1055.595610
0.323456, 1055.360974
0.323782, 1055.490471
0.324114, 1055.500320
0.324453, 1055.708867
0.324778, 1055.147615
0.325124, 1055.766380
0.325461, 1054.473405
0.325785, 1056.083900
0.326163, 1055.703530
0.326492, 1055.037402
0.326839, 1055.264481
0.327169, 1054.924482
0.327508, 1055.265647
0.327842, 1054.830132
0.328185, 1055.037778
0.328519, 1054.935007
0.328858, 1054.565463
0.329187, 1054.918468
0.329537, 1055.152163
0.329871, 1054.296997
0.330214, 1054.996880
0.330547, 1054.434500
0.330894, 1055.007593
0.331247, 1054.615758
0.331550, 1053.836898
0.331929, 1055.444010
0.332282, 1054.163440
0.332627, 1054.263091
0.332967, 1053.796790
0.333309, 1054.064842
0.333647, 1053.723152
0.333979, 1053.866632
0.334317, 1053.909258
0.334664, 1054.091193
0.335014, 1054.457467
0.335365, 1053.998196
0.335710, 1053.317821
0.336031, 1053.624854
0.336407, 1054.607977
0.336746, 1053.050671
0.337091, 1053.859715
0.337441, 1053.170695
0.337788, 1053.607525
0.338144, 1053.441304
0.338485, 1053.396685
0.338857, 1053.509228
0.339199, 1053.050671
0.339563, 1053.675676
0.339913, 1052.996993
0.340264, 1053.058866
0.340633, 1053.203436
0.340967, 1051.920911
0.341315, 1053.666466
0.341712, 1052.882532
0.342079, 1052.933767
0.342438, 1052.543548
0.342805, 1052.514566
0.343164, 1052.674774
0.343520, 1052.205992
0.343889, 1052.393790
0.344250, 1052.332181
0.344614, 1052.031914
0.344974, 1051.781416
0.345339, 1052.205541
0.345701, 1051.799985
0.346072, 1051.524753
0.346440, 1051.554937
0.346813, 1052.010563
0.347174, 1051.383641
0.347545, 1051.643010
0.347929, 1051.688832
0.348300, 1051.448972
0.348673, 1051.217419
0.349049, 1050.775589
0.349390, 1051.401910
0.349810, 1051.290456
0.350191, 1050.519077
0.350580, 1050.759313
0.350959, 1050.613803
0.351342, 1050.399128
0.351719, 1050.518551
0.352090, 1050.072097
0.352467, 1050.329963
0.352859, 1049.942300
0.353242, 1050.359320
0.353639, 1050.273127
0.353988, 1048.756456
0.354393, 1050.848664
0.354796, 1049.303424
0.355172, 1049.157050
0.355576, 1049.039920
0.355958, 1048.678269
0.356349, 1048.632523
0.356724, 1048.640191
0.357100, 1048.802579
0.357484, 1048.174567
0.357865, 1048.317596
0.358271, 1048.493177
0.358646, 1047.714731
0.359024, 1048.503252
0.359463, 1048.144307
0.359848, 1047.464459
0.360251, 1047.597076
0.360635, 1046.877871
0.361039, 1047.354058
0.361423, 1046.654437
0.361826, 1046.620005
0.362230, 1046.459986
0.362594, 1045.458858
0.363032, 1047.353832
0.363441, 1045.560613
0.363834, 1046.273428
0.364239, 1045.422659
0.364635, 1045.503327
0.365035, 1045.186032
0.365438, 1045.293726
0.365850, 1045.145134
0.366253, 1044.292486
0.366658, 1044.478066
0.367071, 1044.530354
0.367482, 1043.826185
0.367892, 1043.905349
0.368302, 1043.600421
0.368704, 1043.423486
0.369118, 1043.546931
0.369510, 1042.282976
0.369894, 1043.137842
0.370354, 1043.023757
0.370721, 1041.242191
0.371172, 1042.709958
0.371591, 1041.647897
0.371993, 1041.374770
0.372411, 1040.825471
0.372829, 1040.881066
0.373247, 1040.553622
0.373671, 1040.359659
0.374094, 1039.795061
0.374518, 1039.783107
0.374947, 1039.224599
0.375365, 1038.441153
0.375788, 1038.529489
0.376205, 1037.671240
0.376621, 1037.187723
0.377039, 1037.166635
0.377459, 1036.780175
0.377864, 1035.330827
0.378292, 1036.572680
0.378775, 1035.045521
0.379196, 1034.338383
0.379642, 1033.650678
0.380076, 1033.435477
0.380526, 1032.504342
0.380964, 1031.441604
0.381402, 1030.604067
0.381835, 1029.629252
0.382287, 1029.005488
0.382748, 1028.058264
0.383199, 1027.044506
0.383650, 1025.603240
0.384104, 1024.124159
0.384593, 1022.634252
0.385137, 1019.373604
0.385970, 1009.415630
0.386589, 998.238920