File: Original_Data/Stress_Strain/SR/18-322_RT_SRonly.csv
Eng_Strain, Eng_Stress (MPa)
0.000018, 3.714536
0.000094, 18.548473
0.000177, 34.854715
0.000244, 47.863990
0.000306, 60.070905
0.000372, 73.052027
0.000438, 85.804797
0.000499, 97.742654
0.000571, 112.512500
0.000637, 124.859309
0.000706, 138.650375
0.000763, 150.647395
0.000836, 164.714951
0.000902, 177.330060
0.000970, 190.886937
0.001035, 203.250589
0.001104, 217.013851
0.001169, 229.911809
0.001236, 242.814144
0.001295, 254.227995
0.001363, 268.029621
0.001423, 279.618803
0.001481, 291.591903
0.001542, 304.106216
0.001602, 315.167143
0.001676, 329.741276
0.001729, 339.541836
0.001790, 352.278720
0.001848, 363.467290
0.001909, 375.693994
0.001969, 386.969257
0.002031, 398.833784
0.002082, 409.234872
0.002143, 420.628228
0.002198, 431.156494
0.002264, 444.569182
0.002315, 454.308821
0.002383, 467.042342
0.002433, 477.450450
0.002496, 489.669707
0.002550, 499.831869
0.002620, 513.198123
0.002677, 524.562838
0.002731, 534.994294
0.002790, 546.334459
0.002841, 555.851464
0.002906, 567.435661
0.002961, 577.745608
0.003035, 589.958296
0.003093, 598.640578
0.003198, 612.449174
0.003281, 619.945646
0.003403, 628.864152
0.003540, 636.592192
0.003697, 642.853416
0.003867, 649.496997
0.004059, 655.681944
0.004274, 660.554129
0.004471, 664.227177
0.004791, 670.149812
0.005023, 672.227140
0.005345, 675.820045
0.005615, 677.725488
0.005939, 680.409347
0.006242, 681.360548
0.006581, 683.862387
0.006903, 685.404354
0.007256, 687.353866
0.007586, 687.372935
0.007933, 691.117155
0.008275, 689.829617
0.008605, 692.836036
0.008933, 692.517868
0.009269, 694.936974
0.009606, 695.321584
0.009933, 697.399512
0.010280, 697.634760
0.010596, 698.797710
0.010954, 699.832470
0.011243, 701.111899
0.011651, 702.136111
0.011944, 703.567605
0.012302, 704.407207
0.012609, 705.664940
0.012956, 706.480668
0.013268, 707.906194
0.013605, 708.438776
0.013878, 707.539602
0.014260, 711.489715
0.014550, 711.163889
0.014878, 712.606832
0.015193, 713.341216
0.015486, 713.863363
0.015770, 714.728003
0.016093, 716.244369
0.016382, 715.810923
0.016718, 719.124362
0.017031, 718.371622
0.017330, 720.484872
0.017648, 720.800413
0.017948, 722.125000
0.018259, 722.894294
0.018549, 723.587275
0.018875, 725.471847
0.019143, 725.179467
0.019501, 727.022785
0.019785, 727.072785
0.020108, 728.985511
0.020389, 729.404505
0.020704, 730.565691
0.020984, 731.102553
0.021290, 732.561824
0.021580, 732.567267
0.021890, 734.792830
0.022186, 734.066929
0.022478, 738.165428
0.022786, 736.252740
0.023093, 738.559272
0.023386, 738.411524
0.023682, 740.437387
0.023973, 740.745308
0.024263, 742.091517
0.024561, 742.678416
0.024816, 743.082095
0.025150, 744.875038
0.025407, 744.730518
0.025713, 746.663701
0.025988, 746.912988
0.026279, 747.987650
0.026568, 749.036937
0.026858, 750.040616
0.027139, 750.389827
0.027403, 752.643619
0.027728, 752.469257
0.027997, 754.102590
0.028288, 754.546059
0.028566, 755.513851
0.028860, 756.657995
0.029136, 757.168881
0.029431, 758.711336
0.029707, 758.175713
0.029995, 761.929317
0.030291, 760.327740
0.030549, 762.017080
0.030844, 762.606982
0.031109, 763.630368
0.031397, 764.347260
0.031659, 765.514527
0.031955, 766.010511
0.032184, 766.806269
0.032517, 767.936862
0.032773, 768.922523
0.033055, 769.585360
0.033319, 770.434122
0.033606, 771.132958
0.033869, 772.465053
0.034162, 773.159497
0.034395, 772.420683
0.034710, 775.931344
0.034972, 775.278754
0.035255, 777.017868
0.035504, 776.872260
0.035785, 778.469294
0.036041, 778.235398
0.036318, 780.671096
0.036588, 780.435398
0.036839, 782.690803
0.037157, 782.259197
0.037416, 783.578416
0.037701, 783.917868
0.037957, 784.777853
0.038234, 785.954730
0.038491, 786.685961
0.038775, 787.838288
0.039024, 786.849324
0.039319, 790.467080
0.039595, 789.652928
0.039865, 791.136824
0.040127, 791.042905
0.040395, 792.812087
0.040660, 793.183784
0.040918, 794.470308
0.041195, 794.812575
0.041422, 794.106006
0.041747, 797.281832
0.042006, 797.123911
0.042286, 798.771434
0.042548, 799.060811
0.042810, 799.980443
0.043070, 800.438851
0.043334, 801.562950
0.043595, 802.337725
0.043825, 801.527327
0.044143, 805.037200
0.044389, 803.983221
0.044672, 806.004692
0.044931, 805.649399
0.045191, 807.282658
0.045455, 807.899962
0.045712, 808.192342
0.045995, 809.603604
0.046235, 808.369782
0.046547, 812.435323
0.046798, 810.774587
0.047076, 812.685548
0.047328, 812.654167
0.047582, 814.101577
0.047837, 814.279880
0.048098, 815.392080
0.048346, 815.212763
0.048615, 818.785210
0.048896, 817.289039
0.049152, 818.359234
0.049418, 818.716929
0.049679, 820.374024
0.049943, 820.444745
0.050189, 821.044182
0.050453, 822.465766
0.050716, 822.853979
0.050950, 822.057545
0.051271, 825.363701
0.051516, 824.227928
0.051798, 826.712275
0.052049, 826.402365
0.052323, 827.684685
0.052571, 827.385398
0.052838, 829.328604
0.053099, 829.226652
0.053350, 831.591066
0.053634, 830.222035
0.053886, 831.571359
0.054157, 832.124737
0.054414, 833.330631
0.054686, 833.500338
0.054937, 834.629467
0.055208, 835.133071
0.055438, 836.199174
0.055750, 836.429805
0.056006, 837.644369
0.056277, 837.869895
0.056531, 838.929805
0.056804, 839.586937
0.057051, 839.716854
0.057317, 840.846622
0.057561, 840.810135
0.057831, 843.827140
0.058111, 842.247898
0.058371, 843.813476
0.058640, 844.133896
0.058899, 845.197035
0.059174, 845.616029
0.059444, 846.641779
0.059692, 846.674324
0.059960, 847.724887
0.060218, 847.931607
0.060462, 849.885998
0.060760, 849.274775
0.061011, 850.278153
0.061297, 850.627590
0.061549, 851.676051
0.061825, 852.021659
0.062081, 853.044557
0.062345, 853.173236
0.062571, 853.459535
0.062885, 855.683934
0.063128, 855.181794
0.063415, 856.755893
0.063664, 856.602778
0.063929, 857.144144
0.064185, 857.716817
0.064455, 858.799850
0.064694, 857.700038
0.064980, 861.134947
0.065248, 860.270683
0.065524, 861.890015
0.065787, 861.415803
0.066055, 862.710135
0.066317, 862.957845
0.066572, 863.689339
0.066842, 864.674700
0.067088, 864.303866
0.067358, 867.110435
0.067638, 865.671547
0.067894, 866.647447
0.068161, 867.048949
0.068421, 868.435398
0.068681, 868.291104
0.068940, 869.405968
0.069219, 869.120458
0.069460, 871.208559
0.069756, 870.029880
0.070010, 871.805405
0.070289, 871.778228
0.070541, 872.622147
0.070819, 873.311336
0.071073, 873.785173
0.071353, 874.729842
0.071585, 873.872110
0.071893, 877.212387
0.072138, 875.392380
0.072417, 877.054505
0.072675, 876.982808
0.072955, 878.768619
0.073212, 877.927252
0.073473, 879.367267
0.073741, 879.124362
0.073986, 881.171547
0.074284, 880.533033
0.074536, 881.141479
0.074813, 881.979842
0.075074, 882.321509
0.075344, 882.697110
0.075616, 883.899850
0.075885, 884.157695
0.076155, 884.595758
0.076430, 885.397598
0.076689, 885.556044
0.076921, 886.836862
0.077235, 887.324925
0.077489, 887.678604
0.077778, 888.166892
0.078039, 888.638814
0.078314, 889.183483
0.078575, 889.665803
0.078857, 890.626464
0.079101, 889.145420
0.079407, 892.743806
0.079668, 891.834272
0.079937, 892.432958
0.080194, 892.400263
0.080469, 893.579092
0.080728, 894.282583
0.080995, 894.730593
0.081258, 894.357207
0.081524, 897.031757
0.081810, 895.544895
0.082063, 896.458634
0.082341, 897.032320
0.082598, 897.355668
0.082847, 897.849137
0.083100, 897.975826
0.083367, 899.410998
0.083634, 899.432545
0.083888, 901.366592
0.084192, 900.108859
0.084462, 901.359572
0.084733, 901.188589
0.085001, 902.147635
0.085273, 902.322485
0.085537, 903.317830
0.085806, 903.432470
0.086073, 903.710511
0.086345, 904.237988
0.086616, 905.540803
0.086882, 904.566291
0.087150, 906.983896
0.087441, 906.217305
0.087712, 907.633333
0.087981, 906.976351
0.088256, 908.116329
0.088533, 908.028116
0.088801, 909.479692
0.089073, 909.380443
0.089310, 908.933408
0.089627, 911.191479
0.089887, 910.626426
0.090168, 911.136111
0.090433, 911.701464
0.090722, 912.504167
0.090982, 912.317005
0.091258, 913.574212
0.091510, 912.405631
0.091779, 915.437237
0.092063, 913.781119
0.092331, 915.265390
0.092600, 915.356006
0.092867, 916.444069
0.093144, 916.575113
0.093412, 917.201577
0.093693, 917.342492
0.093931, 916.999662
0.094244, 919.013701
0.094500, 918.402553
0.094791, 919.550375
0.095048, 919.295083
0.095337, 920.397635
0.095604, 919.851426
0.095895, 921.736224
0.096157, 920.986862
0.096415, 922.789452
0.096716, 922.455293
0.096981, 923.242267
0.097267, 923.051652
0.097536, 923.644745
0.097818, 923.863889
0.098082, 925.081231
0.098360, 925.359685
0.098598, 923.716967
0.098898, 927.731869
0.099167, 925.342080
0.099455, 927.437650
0.099726, 927.011937
0.100010, 927.886862
0.100282, 927.986524
0.100559, 928.549287
0.100837, 928.614902
0.101068, 928.837913
0.101382, 929.842192
0.101632, 929.955180
0.101921, 930.514077
0.102181, 930.899024
0.102467, 931.432545
0.102726, 931.470008
0.103000, 932.556982
0.103275, 932.559422
0.103534, 934.533596
0.103843, 933.127628
0.104109, 934.318544
0.104398, 934.196922
0.104674, 934.865390
0.104963, 935.416892
0.105241, 935.511599
0.105519, 935.728904
0.105797, 936.323423
0.106077, 937.014790
0.106346, 937.219782
0.106624, 937.602065
0.106896, 937.971134
0.107179, 938.405818
0.107447, 938.565353
0.107710, 939.189264
0.108002, 939.536637
0.108263, 941.290278
0.108570, 939.705030
0.108831, 941.045908
0.109110, 940.442455
0.109379, 942.256644
0.109651, 941.642755
0.109919, 942.369332
0.110207, 942.649700
0.110480, 943.348536
0.110764, 943.774550
0.111035, 943.515541
0.111317, 944.640653
0.111593, 944.219294
0.111852, 946.244782
0.112157, 944.984122
0.112425, 946.234797
0.112711, 945.704354
0.112973, 946.397860
0.113260, 946.658784
0.113532, 947.589302
0.113814, 947.498461
0.114054, 946.995683
0.114389, 949.199700
0.114655, 948.743881
0.114957, 949.773911
0.115211, 948.930255
0.115502, 950.734835
0.115759, 950.011524
0.116051, 951.198574
0.116295, 949.419707
0.116597, 952.826839
0.116866, 951.060360
0.117152, 952.410773
0.117427, 952.209497
0.117705, 953.333146
0.117991, 953.013251
0.118261, 953.901502
0.118552, 954.031607
0.118803, 954.829017
0.119128, 954.926502
0.119397, 955.272110
0.119694, 955.358483
0.119968, 955.857995
0.120257, 955.977477
0.120522, 956.444069
0.120813, 957.153679
0.121060, 955.653228
0.121374, 959.066704
0.121654, 957.075601
0.121951, 958.639640
0.122221, 958.187500
0.122498, 958.778641
0.122797, 959.737988
0.123067, 959.482057
0.123349, 960.032845
0.123631, 960.167117
0.123917, 960.548799
0.124201, 961.035360
0.124477, 961.417417
0.124759, 961.690390
0.125048, 962.200375
0.125323, 962.342005
0.125581, 963.334835
0.125900, 962.828303
0.126168, 963.653266
0.126458, 963.396997
0.126731, 964.270796
0.127013, 964.208709
0.127287, 965.206644
0.127582, 965.028491
0.127828, 965.684159
0.128154, 965.715390
0.128433, 966.571584
0.128721, 966.071434
0.128997, 966.563889
0.129281, 967.014414
0.129549, 966.823799
0.129839, 968.051464
0.130110, 967.288326
0.130389, 969.894745
0.130695, 968.499324
0.130973, 969.364677
0.131264, 969.009084
0.131552, 969.564977
0.131838, 969.878491
0.132111, 969.938814
0.132412, 970.790428
0.132652, 970.346209
0.132999, 972.087012
0.133261, 971.452327
0.133559, 971.965991
0.133831, 972.187162
0.134123, 972.925676
0.134388, 972.501464
0.134679, 973.223649
0.134955, 973.290503
0.135215, 974.535023
0.135536, 973.655105
0.135807, 974.320008
0.136099, 974.453941
0.136371, 974.883221
0.136668, 975.102628
0.136941, 975.501614
0.137244, 975.985285
0.137487, 974.422335
0.137820, 977.240803
0.138089, 976.281194
0.138383, 977.349775
0.138663, 977.165953
0.138959, 978.122785
0.139233, 977.800450
0.139538, 978.785285
0.139804, 976.968018
0.140116, 980.847860
0.140400, 978.878829
0.140694, 980.023799
0.140977, 979.228341
0.141263, 980.182020
0.141549, 980.371096
0.141828, 980.482470
0.142124, 980.810623
0.142366, 980.682620
0.142708, 982.124887
0.142969, 981.477928
0.143279, 982.362650
0.143559, 982.013964
0.143860, 983.132245
0.144126, 982.127065
0.144428, 983.565653
0.144706, 983.406419
0.145003, 984.312913
0.145254, 982.486674
0.145572, 985.270683
0.145858, 984.763138
0.146159, 985.163814
0.146445, 985.036074
0.146739, 985.610886
0.147030, 985.755368
0.147320, 986.127027
0.147603, 986.154655
0.147892, 986.783258
0.148176, 986.465015
0.148419, 985.482958
0.148774, 988.471734
0.149045, 987.565015
0.149353, 988.349212
0.149632, 988.420533
0.149933, 988.495420
0.150211, 988.664677
0.150508, 989.471734
0.150769, 988.006982
0.151090, 991.570195
0.151370, 988.980030
0.151670, 990.794144
0.151940, 989.982545
0.152237, 990.944069
0.152521, 990.792530
0.152813, 991.759272
0.153097, 991.283221
0.153374, 991.481456
0.153670, 992.193056
0.153912, 990.865240
0.154262, 993.386074
0.154535, 992.474249
0.154847, 993.610998
0.155123, 993.462763
0.155440, 994.274137
0.155709, 993.560698
0.156010, 994.265541
0.156268, 992.762162
0.156587, 995.770120
0.156864, 994.312050
0.157161, 995.599099
0.157449, 995.114677
0.157743, 995.894482
0.158033, 995.770345
0.158333, 996.632470
0.158624, 995.376051
0.158923, 998.423348
0.159220, 996.169857
0.159509, 997.261824
0.159801, 997.060135
0.160091, 998.051577
0.160379, 997.855743
0.160658, 998.018956
0.160951, 998.315203
0.161239, 998.643431
0.161525, 998.689640
0.161828, 999.737012
0.162089, 998.229054
0.162426, 1000.988363
0.162707, 999.548236
0.163009, 999.946697
0.163296, 1000.450225
0.163588, 1000.556607
0.163890, 1001.184047
0.164175, 1000.648273
0.164468, 1001.251577
0.164757, 1001.656644
0.165051, 1001.729017
0.165346, 1002.281494
0.165652, 1002.875000
0.165918, 1001.466441
0.166242, 1004.619332
0.166524, 1002.769782
0.166827, 1003.645683
0.167108, 1003.089752
0.167415, 1003.881306
0.167700, 1003.736149
0.167995, 1004.222973
0.168299, 1004.332207
0.168592, 1004.590653
0.168902, 1004.949249
0.169155, 1004.276989
0.169494, 1005.623311
0.169768, 1005.271471
0.170078, 1006.030556
0.170355, 1005.495233
0.170660, 1006.681231
0.170937, 1005.963476
0.171250, 1007.712125
0.171503, 1005.114189
0.171837, 1008.288101
0.172117, 1006.852890
0.172435, 1008.081494
0.172712, 1007.256194
0.173031, 1008.160398
0.173313, 1008.092568
0.173625, 1008.845571
0.173912, 1008.439940
0.174196, 1010.152440
0.174534, 1009.399850
0.174816, 1009.468619
0.175120, 1009.136299
0.175404, 1009.834910
0.175712, 1009.956231
0.176002, 1010.043769
0.176305, 1010.258296
0.176560, 1009.390165
0.176917, 1011.775938
0.177195, 1010.274287
0.177515, 1011.706869
0.177802, 1011.520083
0.178107, 1012.011712
0.178396, 1011.690803
0.178697, 1012.655931
0.178990, 1011.931081
0.179261, 1013.294144
0.179587, 1011.943919
0.179882, 1013.407883
0.180184, 1012.942905
0.180481, 1013.762050
0.180782, 1013.450450
0.181068, 1013.321284
0.181376, 1014.085661
0.181638, 1013.056456
0.181995, 1015.485698
0.182283, 1014.242042
0.182603, 1015.141479
0.182894, 1015.017080
0.183206, 1015.296922
0.183496, 1015.084384
0.183796, 1015.324174
0.184103, 1015.820083
0.184409, 1016.145233
0.184718, 1016.758821
0.185012, 1015.420608
0.185314, 1018.008934
0.185623, 1016.323461
0.185929, 1017.412725
0.186226, 1016.896734
0.186536, 1018.018881
0.186830, 1017.025413
0.187140, 1018.324474
0.187447, 1017.482583
0.187723, 1018.816554
0.188065, 1018.442455
0.188349, 1018.741779
0.188657, 1018.777928
0.188948, 1018.922673
0.189251, 1019.452365
0.189550, 1019.282583
0.189857, 1019.545983
0.190173, 1019.595383
0.190437, 1019.328754
0.190786, 1020.601014
0.191066, 1019.829129
0.191377, 1020.261486
0.191680, 1020.658784
0.191988, 1021.260098
0.192296, 1020.776089
0.192595, 1021.110698
0.192894, 1021.373724
0.193198, 1021.812237
0.193495, 1021.780068
0.193800, 1021.916441
0.194098, 1021.890916
0.194401, 1021.936524
0.194716, 1022.739602
0.195000, 1021.378078
0.195338, 1024.598536
0.195629, 1022.107995
0.195961, 1023.615953
0.196253, 1022.952890
0.196577, 1023.968506
0.196869, 1023.123123
0.197189, 1024.431794
0.197480, 1023.402102
0.197793, 1024.440953
0.198084, 1023.431794
0.198411, 1025.881381
0.198711, 1024.475263
0.199022, 1025.155518
0.199320, 1024.108709
0.199629, 1025.214452
0.199929, 1025.104542
0.200242, 1026.140578
0.200538, 1024.849399
0.200843, 1027.191704
0.201173, 1025.949587
0.201486, 1026.815428
0.201795, 1026.263739
0.202104, 1026.989414
0.202416, 1026.441817
0.202736, 1027.496471
0.203046, 1026.785886
0.203322, 1026.809047
0.203694, 1028.481682
0.203991, 1027.463776
0.204316, 1028.067080
0.204619, 1028.148086
0.204935, 1028.092755
0.205230, 1028.099324
0.205550, 1028.845120
0.205845, 1027.432545
0.206171, 1030.416854
0.206487, 1028.401389
0.206801, 1029.537050
0.207104, 1028.846134
0.207419, 1029.855330
0.207734, 1029.354054
0.208037, 1030.104880
0.208356, 1030.059272
0.208624, 1028.635661
0.208994, 1031.158221
0.209288, 1029.988964
0.209613, 1030.363701
0.209918, 1030.453716
0.210240, 1031.350751
0.210543, 1030.820158
0.210851, 1031.206832
0.211160, 1031.120158
0.211435, 1030.308709
0.211797, 1032.806044
0.212085, 1031.160773
0.212430, 1032.815878
0.212725, 1031.810135
0.213054, 1032.753491
0.213367, 1032.332432
0.213699, 1032.787350
0.213995, 1031.767380
0.214339, 1034.289865
0.214656, 1032.447185
0.214985, 1034.016066
0.215288, 1032.768956
0.215605, 1033.584872
0.215914, 1033.107658
0.216232, 1033.830556
0.216551, 1033.563851
0.216859, 1034.379317
0.217181, 1033.818318
0.217475, 1035.557808
0.217817, 1033.997710
0.218131, 1035.089827
0.218453, 1034.294707
0.218770, 1035.392905
0.219089, 1034.731381
0.219412, 1035.386974
0.219740, 1035.720045
0.220041, 1034.882770
0.220367, 1036.328266
0.220674, 1034.084009
0.221027, 1037.437763
0.221339, 1035.361036
0.221689, 1037.016104
0.222000, 1035.828566
0.222326, 1037.010023
0.222636, 1036.211261
0.222955, 1037.013551
0.223269, 1036.409084
0.223579, 1038.170908
0.223930, 1037.027553
0.224246, 1037.195871
0.224578, 1037.510623
0.224898, 1037.568694
0.225224, 1037.832395
0.225531, 1037.404692
0.225859, 1038.177440
0.226136, 1036.433709
0.226514, 1039.531419
0.226826, 1038.282508
0.227161, 1038.818431
0.227474, 1038.397072
0.227803, 1038.840953
0.228111, 1038.399737
0.228427, 1038.809722
0.228748, 1038.677740
0.229061, 1038.949512
0.229402, 1039.924399
0.229686, 1038.159835
0.230067, 1040.736149
0.230384, 1039.329805
0.230722, 1040.180931
0.231047, 1039.714940
0.231372, 1040.191929
0.231702, 1040.317230
0.232014, 1039.967868
0.232351, 1040.763063
0.232650, 1039.205255
0.233013, 1042.197110
0.233344, 1040.785698
0.233685, 1041.576126
0.234005, 1040.791592
0.234336, 1041.281757
0.234672, 1041.528266
0.234989, 1040.931306
0.235334, 1041.694970
0.235641, 1040.515465
0.235975, 1042.987087
0.236312, 1041.403604
0.236646, 1042.674249
0.236966, 1041.676201
0.237308, 1042.796697
0.237627, 1042.130968
0.237971, 1042.891629
0.238286, 1041.961486
0.238617, 1043.860698
0.238971, 1042.210511
0.239303, 1043.479392
0.239632, 1042.696096
0.239957, 1043.385248
0.240296, 1043.017267
0.240615, 1043.057620
0.240948, 1043.554017
0.241260, 1042.264039
0.241620, 1045.589114
0.241968, 1043.444407
0.242312, 1044.629054
0.242645, 1043.631907
0.242983, 1044.361674
0.243315, 1043.692155
0.243647, 1044.585060
0.243981, 1043.807620
0.244305, 1044.897260
0.244641, 1044.136449
0.244951, 1045.849962
0.245326, 1044.649362
0.245662, 1045.303566
0.245779, 1018.688138
0.245858, 1027.746171
0.245962, 1036.864790
0.246087, 1043.795533
0.246244, 1048.394032
0.246455, 1051.277815
0.246644, 1050.277703
0.246929, 1052.495646
0.247148, 1050.385285
0.247422, 1051.127515
0.247685, 1050.773986
0.247959, 1050.346847
0.248236, 1049.837237
0.248523, 1049.995608
0.248798, 1048.834122
0.249083, 1050.821997
0.249377, 1048.650713
0.249663, 1049.255405
0.249949, 1048.558108
0.250239, 1048.795571
0.250534, 1048.844182
0.250813, 1048.019444
0.251119, 1048.592943
0.251374, 1046.892605
0.251706, 1050.191929
0.251989, 1048.065578
0.252302, 1049.034009
0.252590, 1048.090803
0.252893, 1048.825338
0.253190, 1048.266254
0.253484, 1049.016104
0.253767, 1048.120571
0.254058, 1049.427177
0.254372, 1048.749887
0.254668, 1049.294107
0.254956, 1048.392042
0.255245, 1049.012725
0.255542, 1048.841479
0.255825, 1048.831569
0.256120, 1049.015878
0.256404, 1049.021809
0.256665, 1048.230968
0.257001, 1049.987012
0.257278, 1048.927327
0.257595, 1050.043243
0.257874, 1048.846659
0.258173, 1050.143994
0.258454, 1048.766254
0.258754, 1049.859610
0.259017, 1048.150901
0.259341, 1051.282357
0.259630, 1049.507920
0.259944, 1050.589752
0.260228, 1049.708483
0.260519, 1050.064527
0.260803, 1049.577853
0.261095, 1050.136937
0.261375, 1049.898161
0.261631, 1049.232320
0.261970, 1051.443056
0.262250, 1050.301839
0.262563, 1050.823048
0.262842, 1050.101539
0.263147, 1050.933821
0.263423, 1050.311449
0.263727, 1050.838964
0.263995, 1049.693468
0.264308, 1052.520721
0.264605, 1050.730218
0.264909, 1051.292980
0.265192, 1050.462988
0.265484, 1051.247110
0.265776, 1050.831757
0.266064, 1051.217980
0.266360, 1051.426126
0.266623, 1050.119520
0.266962, 1052.840991
0.267249, 1051.090878
0.267558, 1052.083934
0.267845, 1050.965353
0.268136, 1051.927102
0.268421, 1051.001652
0.268719, 1052.158333
0.269019, 1051.736036
0.269286, 1051.473423
0.269618, 1052.036111
0.269913, 1051.959047
0.270221, 1052.082583
0.270514, 1052.125413
0.270821, 1052.129730
0.271117, 1052.159159
0.271422, 1052.218956
0.271687, 1050.910435
0.272032, 1053.378829
0.272321, 1051.620796
0.272631, 1052.789227
0.272921, 1052.038776
0.273224, 1052.770008
0.273525, 1052.739227
0.273828, 1052.801314
0.274136, 1052.986637
0.274430, 1052.979392
0.274748, 1053.477778
0.275000, 1051.293581
0.275350, 1053.911449
0.275642, 1052.556231
0.275960, 1053.444857
0.276267, 1052.863101
0.276582, 1053.635661
0.276878, 1052.859685
0.277205, 1053.716216
0.277463, 1051.098198
0.277808, 1054.129730
0.278099, 1052.976014
0.278409, 1053.521697
0.278706, 1053.283671
0.279021, 1053.501126
0.279330, 1053.761299
0.279648, 1053.982995
0.279967, 1053.603303
0.280280, 1053.786749
0.280594, 1053.770458
0.280908, 1053.729617
0.281216, 1053.697598
0.281533, 1053.969970
0.281856, 1053.880218
0.282143, 1054.032808
0.282492, 1053.910511
0.282800, 1054.369294
0.283120, 1053.870120
0.283430, 1053.706832
0.283740, 1053.727065
0.284046, 1053.823386
0.284364, 1054.243656
0.284678, 1053.358146
0.284968, 1053.478904
0.285342, 1054.832095
0.285658, 1054.663589
0.285986, 1054.176802
0.286298, 1054.036599
0.286623, 1054.592117
0.286930, 1054.508258
0.287267, 1054.944032
0.287562, 1053.537763
0.287906, 1056.267830
0.288232, 1053.527778
0.288561, 1055.106419
0.288883, 1054.046284
0.289202, 1054.487575
0.289522, 1054.281644
0.289847, 1054.714339
0.290179, 1054.913889
0.290473, 1054.353979
0.290851, 1055.419107
0.291168, 1054.426652
0.291514, 1055.021021
0.291834, 1054.546734
0.292167, 1054.750263
0.292484, 1054.323874
0.292823, 1055.390541
0.293107, 1052.856869
0.293482, 1055.710173
0.293806, 1054.590653
0.294145, 1055.185661
0.294473, 1054.819670
0.294820, 1055.117643
0.295137, 1054.870345
0.295475, 1055.044557
0.295802, 1054.476201
0.296106, 1054.647260
0.296494, 1055.390541
0.296824, 1054.918431
0.297173, 1055.041779
0.297514, 1055.082320
0.297862, 1055.280931
0.298203, 1054.978791
0.298542, 1054.854017
0.298880, 1054.984122
0.299219, 1054.761562
0.299565, 1055.140503
0.299913, 1055.164565
0.300243, 1055.498574
0.300624, 1055.168956
0.300964, 1055.088551
0.301315, 1055.116629
0.301645, 1054.698874
0.301995, 1054.860961
0.302320, 1054.459047
0.302683, 1055.521246
0.302989, 1053.490315
0.303388, 1056.346547
0.303720, 1054.643656
0.304096, 1055.756306
0.304429, 1054.964489
0.304786, 1055.196471
0.305121, 1054.844182
0.305491, 1055.343468
0.305816, 1054.271734
0.306203, 1056.663288
0.306557, 1054.246059
0.306921, 1055.390465
0.307264, 1054.246209
0.307622, 1054.998574
0.307975, 1054.711637
0.308327, 1054.952665
0.308697, 1055.164264
0.309027, 1053.957057
0.309398, 1055.849399
0.309773, 1054.847973
0.310149, 1055.482958
0.310512, 1054.703416
0.310881, 1055.013814
0.311244, 1054.425826
0.311601, 1054.809722
0.311967, 1054.449737
0.312297, 1054.635098
0.312707, 1055.402027
0.313066, 1054.661749
0.313446, 1054.385210
0.313809, 1054.998273
0.314194, 1055.066329
0.314554, 1054.577177
0.314937, 1054.597898
0.315298, 1054.867042
0.315641, 1054.818956
0.316059, 1054.827252
0.316420, 1054.947410
0.316809, 1054.675113
0.317176, 1054.456119
0.317569, 1054.522673
0.317940, 1054.368956
0.318313, 1054.505818
0.318692, 1054.354805
0.319075, 1054.606794
0.319463, 1054.490803
0.319798, 1052.813701
0.320245, 1055.334272
0.320613, 1053.232470
0.321014, 1054.219970
0.321375, 1053.578829
0.321771, 1054.306982
0.322140, 1053.557057
0.322532, 1054.137913
0.322906, 1053.461899
0.323264, 1054.292605
0.323701, 1054.098498
0.324087, 1054.113589
0.324483, 1053.433821
0.324871, 1053.683221
0.325272, 1053.662312
0.325654, 1053.321134
0.326050, 1053.594895
0.326434, 1053.228003
0.326805, 1054.063664
0.327246, 1053.443694
0.327643, 1053.428604
0.328049, 1053.181456
0.328444, 1053.453679
0.328845, 1052.761862
0.329226, 1053.108784
0.329631, 1053.072523
0.330034, 1053.339827
0.330435, 1052.958784
0.330840, 1052.785323
0.331248, 1053.237613
0.331662, 1052.787012
0.332079, 1052.570871
0.332458, 1052.748611
0.332901, 1052.605781
0.333312, 1052.615390
0.333722, 1052.092793
0.334132, 1052.386937
0.334555, 1052.476539
0.334960, 1052.334422
0.335390, 1052.258934
0.335756, 1050.592230
0.336230, 1052.972635
0.336638, 1051.713514
0.337074, 1052.021734
0.337479, 1051.428566
0.337912, 1051.847260
0.338329, 1051.321209
0.338766, 1052.038701
0.339158, 1049.924775
0.339607, 1053.217305
0.340037, 1050.508971
0.340473, 1051.201351
0.340883, 1050.842267
0.341306, 1051.053116
0.341729, 1050.789827
0.342147, 1050.651989
0.342572, 1050.588363
0.342999, 1050.265390
0.343431, 1050.445458
0.343859, 1050.545533
0.344288, 1050.130631
0.344711, 1049.592793
0.345147, 1050.432282
0.345563, 1048.932958
0.346013, 1051.635098
0.346470, 1049.005330
0.346921, 1050.169069
0.347351, 1048.871547
0.347794, 1049.415766
0.348231, 1048.933258
0.348663, 1049.039940
0.349105, 1048.879655
0.349490, 1047.630518
0.350007, 1049.715691
0.350438, 1048.285811
0.350897, 1048.689790
0.351323, 1047.964189
0.351775, 1048.203829
0.352215, 1047.795270
0.352674, 1048.022823
0.353118, 1047.539152
0.353560, 1047.487988
0.354013, 1047.708596
0.354458, 1046.765315
0.354853, 1046.277327
0.355363, 1047.834685
0.355809, 1047.144932
0.356279, 1046.776239
0.356712, 1046.127778
0.357173, 1046.569632
0.357618, 1046.180480
0.358091, 1046.293844
0.358509, 1044.615991
0.359022, 1047.557658
0.359484, 1044.839339
0.359956, 1045.872635
0.360417, 1044.550450
0.360875, 1045.596434
0.361339, 1044.819820
0.361793, 1044.404842
0.362250, 1044.842680
0.362728, 1044.392305
0.363179, 1043.908071
0.363643, 1043.734835
0.364119, 1043.985698
0.364536, 1042.615090
0.365066, 1044.126051
0.365524, 1042.665428
0.366001, 1043.142943
0.366452, 1042.519970
0.366931, 1042.882883
0.367374, 1041.693881
0.367853, 1042.432245
0.368260, 1040.401614
0.368779, 1043.207770
0.369257, 1041.154129
0.369747, 1041.549887
0.370200, 1040.416854
0.370670, 1041.018468
0.371136, 1040.216779
0.371604, 1040.557320
0.372083, 1040.046697
0.372496, 1038.188739
0.373046, 1040.813363
0.373505, 1038.946884
0.373995, 1039.152665
0.374448, 1038.734835
0.374927, 1038.204917
0.375383, 1038.328453
0.375870, 1038.200826
0.376309, 1036.384497
0.376821, 1039.582095
0.377298, 1036.544932
0.377796, 1037.380405
0.378265, 1036.358483
0.378741, 1036.923799
0.379210, 1035.958671
0.379674, 1036.243731
0.380151, 1035.362200
0.380570, 1035.218206
0.381118, 1035.632207
0.381602, 1034.795233
0.382101, 1034.273311
0.382580, 1034.398761
0.383072, 1033.923761
0.383537, 1033.628716
0.384029, 1033.365390
0.384472, 1033.050638
0.384992, 1032.429429
0.385469, 1032.288438
0.385944, 1031.566441
0.386417, 1031.925901
0.386908, 1031.096471
0.387381, 1030.950638
0.387883, 1030.700413
0.388305, 1029.015503
0.388846, 1031.109009
0.389316, 1029.536261
0.389821, 1029.578566
0.390290, 1028.924212
0.390790, 1028.989227
0.391280, 1027.834760
0.391776, 1028.300075
0.392265, 1027.123874
0.392722, 1026.009272
0.393223, 1028.110548
0.393738, 1026.126351
0.394239, 1026.032583
0.394714, 1024.802477
0.395203, 1024.911937
0.395699, 1024.759459
0.396188, 1023.837575
0.396691, 1023.821171
0.397134, 1022.150601
0.397665, 1024.637688
0.398176, 1021.900676
0.398686, 1022.312688
0.399166, 1021.112875
0.399658, 1020.963176
0.400153, 1020.695571
0.400637, 1019.898911
0.401116, 1019.906569
0.401604, 1019.028679
0.402040, 1017.447110
0.402577, 1020.254279
0.403090, 1017.113026
0.403590, 1017.699474
0.404078, 1015.665015
0.404570, 1016.745683
0.405061, 1014.690653
0.405560, 1015.169782
0.406058, 1014.176952
0.406534, 1014.053866
0.407084, 1012.984535
0.407593, 1012.040465
0.408130, 1010.363739
0.408639, 1009.595683
0.409214, 1007.614339
0.410007, 1004.075038